rm: das Entfernen von 'family_1/Generation_*' ist nicht möglich: Datei oder Verzeichnis nicht gefunden
rm: das Entfernen von 'family_1/vars_*.txt' ist nicht möglich: Datei oder Verzeichnis nicht gefunden
rm: das Entfernen von 'Gridsearch/Run*' ist nicht möglich: Datei oder Verzeichnis nicht gefunden
multiprocessing.pool.RemoteTraceback: 
"""
Traceback (most recent call last):
  File "/home/gahan/anaconda3/envs/ligninsims/lib/python3.10/multiprocessing/pool.py", line 125, in worker
    result = (True, func(*args, **kwds))
  File "/home/gahan/anaconda3/envs/ligninsims/lib/python3.10/multiprocessing/pool.py", line 51, in starmapstar
    return list(itertools.starmap(args[0], args[1]))
  File "/home/gahan/june24/040624_allparametersopen_limitSG/silphium/family_1/Generation_20/Run_2/Code/function_library.py", line 185, in generate_analysis_parallel
    nrings = np.sum([partial_dict_B[smiles_dictionary_id + k]["rings"] for k in range(partial_dict_A[bond_dictionary_id]['Bonds']["b1"]+1)])
  File "/home/gahan/june24/040624_allparametersopen_limitSG/silphium/family_1/Generation_20/Run_2/Code/function_library.py", line 185, in <listcomp>
    nrings = np.sum([partial_dict_B[smiles_dictionary_id + k]["rings"] for k in range(partial_dict_A[bond_dictionary_id]['Bonds']["b1"]+1)])
KeyError: 75
"""

The above exception was the direct cause of the following exception:

Traceback (most recent call last):
  File "/home/gahan/june24/040624_allparametersopen_limitSG/silphium/family_1/Generation_20/Run_2/Code/simulation_main.py", line 80, in <module>
    simulation_run_analysis(SG_ratio, simulation_time, monomer_addition_rate, minimum_num_monomers, maximum_num_monomers, rxn_rates, number_of_runs, filewriting, filepath)
  File "/home/gahan/june24/040624_allparametersopen_limitSG/silphium/family_1/Generation_20/Run_2/Code/simulation_main.py", line 22, in simulation_run_analysis
    data_dictionary = generate_analysis(result, number_of_runs, num_cores=int(sys.argv[2]), file_writing=False, savefile_path=filepath)
  File "/home/gahan/june24/040624_allparametersopen_limitSG/silphium/family_1/Generation_20/Run_2/Code/function_library.py", line 342, in generate_analysis
    lignin_libraries = pool.starmap(generate_analysis_parallel, [(cur_adjs[i], monolist[i], file_writing, savefile_path) for i, result in enumerate(results)])
  File "/home/gahan/anaconda3/envs/ligninsims/lib/python3.10/multiprocessing/pool.py", line 375, in starmap
    return self._map_async(func, iterable, starmapstar, chunksize).get()
  File "/home/gahan/anaconda3/envs/ligninsims/lib/python3.10/multiprocessing/pool.py", line 774, in get
    raise self._value
KeyError: 75
multiprocessing.pool.RemoteTraceback: 
"""
Traceback (most recent call last):
  File "/home/gahan/anaconda3/envs/ligninsims/lib/python3.10/multiprocessing/pool.py", line 125, in worker
    result = (True, func(*args, **kwds))
  File "/home/gahan/anaconda3/envs/ligninsims/lib/python3.10/multiprocessing/pool.py", line 51, in starmapstar
    return list(itertools.starmap(args[0], args[1]))
  File "/home/gahan/june24/040624_allparametersopen_limitSG/silphium/family_1/Generation_29/Run_2/Code/function_library.py", line 201, in generate_analysis_parallel
    smiles = partial_dict_B[smiles_dictionary_id]["smilestring"]
KeyError: 62
"""

The above exception was the direct cause of the following exception:

Traceback (most recent call last):
  File "/home/gahan/june24/040624_allparametersopen_limitSG/silphium/family_1/Generation_29/Run_2/Code/simulation_main.py", line 80, in <module>
    simulation_run_analysis(SG_ratio, simulation_time, monomer_addition_rate, minimum_num_monomers, maximum_num_monomers, rxn_rates, number_of_runs, filewriting, filepath)
  File "/home/gahan/june24/040624_allparametersopen_limitSG/silphium/family_1/Generation_29/Run_2/Code/simulation_main.py", line 22, in simulation_run_analysis
    data_dictionary = generate_analysis(result, number_of_runs, num_cores=int(sys.argv[2]), file_writing=False, savefile_path=filepath)
  File "/home/gahan/june24/040624_allparametersopen_limitSG/silphium/family_1/Generation_29/Run_2/Code/function_library.py", line 342, in generate_analysis
    lignin_libraries = pool.starmap(generate_analysis_parallel, [(cur_adjs[i], monolist[i], file_writing, savefile_path) for i, result in enumerate(results)])
  File "/home/gahan/anaconda3/envs/ligninsims/lib/python3.10/multiprocessing/pool.py", line 375, in starmap
    return self._map_async(func, iterable, starmapstar, chunksize).get()
  File "/home/gahan/anaconda3/envs/ligninsims/lib/python3.10/multiprocessing/pool.py", line 774, in get
    raise self._value
KeyError: 62
multiprocessing.pool.RemoteTraceback: 
"""
Traceback (most recent call last):
  File "/home/gahan/anaconda3/envs/ligninsims/lib/python3.10/multiprocessing/pool.py", line 125, in worker
    result = (True, func(*args, **kwds))
  File "/home/gahan/anaconda3/envs/ligninsims/lib/python3.10/multiprocessing/pool.py", line 51, in starmapstar
    return list(itertools.starmap(args[0], args[1]))
  File "/home/gahan/june24/040624_allparametersopen_limitSG/silphium/family_1/Generation_29/Run_3/Code/function_library.py", line 201, in generate_analysis_parallel
    smiles = partial_dict_B[smiles_dictionary_id]["smilestring"]
KeyError: 60
"""

The above exception was the direct cause of the following exception:

Traceback (most recent call last):
  File "/home/gahan/june24/040624_allparametersopen_limitSG/silphium/family_1/Generation_29/Run_3/Code/simulation_main.py", line 80, in <module>
    simulation_run_analysis(SG_ratio, simulation_time, monomer_addition_rate, minimum_num_monomers, maximum_num_monomers, rxn_rates, number_of_runs, filewriting, filepath)
  File "/home/gahan/june24/040624_allparametersopen_limitSG/silphium/family_1/Generation_29/Run_3/Code/simulation_main.py", line 22, in simulation_run_analysis
    data_dictionary = generate_analysis(result, number_of_runs, num_cores=int(sys.argv[2]), file_writing=False, savefile_path=filepath)
  File "/home/gahan/june24/040624_allparametersopen_limitSG/silphium/family_1/Generation_29/Run_3/Code/function_library.py", line 342, in generate_analysis
    lignin_libraries = pool.starmap(generate_analysis_parallel, [(cur_adjs[i], monolist[i], file_writing, savefile_path) for i, result in enumerate(results)])
  File "/home/gahan/anaconda3/envs/ligninsims/lib/python3.10/multiprocessing/pool.py", line 375, in starmap
    return self._map_async(func, iterable, starmapstar, chunksize).get()
  File "/home/gahan/anaconda3/envs/ligninsims/lib/python3.10/multiprocessing/pool.py", line 774, in get
    raise self._value
KeyError: 60
multiprocessing.pool.RemoteTraceback: 
"""
Traceback (most recent call last):
  File "/home/gahan/anaconda3/envs/ligninsims/lib/python3.10/multiprocessing/pool.py", line 125, in worker
    result = (True, func(*args, **kwds))
  File "/home/gahan/anaconda3/envs/ligninsims/lib/python3.10/multiprocessing/pool.py", line 51, in starmapstar
    return list(itertools.starmap(args[0], args[1]))
  File "/home/gahan/june24/040624_allparametersopen_limitSG/silphium/family_1/Generation_30/Run_3/Code/function_library.py", line 201, in generate_analysis_parallel
    smiles = partial_dict_B[smiles_dictionary_id]["smilestring"]
KeyError: 52
"""

The above exception was the direct cause of the following exception:

Traceback (most recent call last):
  File "/home/gahan/june24/040624_allparametersopen_limitSG/silphium/family_1/Generation_30/Run_3/Code/simulation_main.py", line 80, in <module>
    simulation_run_analysis(SG_ratio, simulation_time, monomer_addition_rate, minimum_num_monomers, maximum_num_monomers, rxn_rates, number_of_runs, filewriting, filepath)
  File "/home/gahan/june24/040624_allparametersopen_limitSG/silphium/family_1/Generation_30/Run_3/Code/simulation_main.py", line 22, in simulation_run_analysis
    data_dictionary = generate_analysis(result, number_of_runs, num_cores=int(sys.argv[2]), file_writing=False, savefile_path=filepath)
  File "/home/gahan/june24/040624_allparametersopen_limitSG/silphium/family_1/Generation_30/Run_3/Code/function_library.py", line 342, in generate_analysis
    lignin_libraries = pool.starmap(generate_analysis_parallel, [(cur_adjs[i], monolist[i], file_writing, savefile_path) for i, result in enumerate(results)])
  File "/home/gahan/anaconda3/envs/ligninsims/lib/python3.10/multiprocessing/pool.py", line 375, in starmap
    return self._map_async(func, iterable, starmapstar, chunksize).get()
  File "/home/gahan/anaconda3/envs/ligninsims/lib/python3.10/multiprocessing/pool.py", line 774, in get
    raise self._value
KeyError: 52
multiprocessing.pool.RemoteTraceback: 
"""
Traceback (most recent call last):
  File "/home/gahan/anaconda3/envs/ligninsims/lib/python3.10/multiprocessing/pool.py", line 125, in worker
    result = (True, func(*args, **kwds))
  File "/home/gahan/anaconda3/envs/ligninsims/lib/python3.10/multiprocessing/pool.py", line 51, in starmapstar
    return list(itertools.starmap(args[0], args[1]))
  File "/home/gahan/june24/040624_allparametersopen_limitSG/silphium/family_1/Generation_32/Run_3/Code/function_library.py", line 185, in generate_analysis_parallel
    nrings = np.sum([partial_dict_B[smiles_dictionary_id + k]["rings"] for k in range(partial_dict_A[bond_dictionary_id]['Bonds']["b1"]+1)])
  File "/home/gahan/june24/040624_allparametersopen_limitSG/silphium/family_1/Generation_32/Run_3/Code/function_library.py", line 185, in <listcomp>
    nrings = np.sum([partial_dict_B[smiles_dictionary_id + k]["rings"] for k in range(partial_dict_A[bond_dictionary_id]['Bonds']["b1"]+1)])
KeyError: 54
"""

The above exception was the direct cause of the following exception:

Traceback (most recent call last):
  File "/home/gahan/june24/040624_allparametersopen_limitSG/silphium/family_1/Generation_32/Run_3/Code/simulation_main.py", line 80, in <module>
    simulation_run_analysis(SG_ratio, simulation_time, monomer_addition_rate, minimum_num_monomers, maximum_num_monomers, rxn_rates, number_of_runs, filewriting, filepath)
  File "/home/gahan/june24/040624_allparametersopen_limitSG/silphium/family_1/Generation_32/Run_3/Code/simulation_main.py", line 22, in simulation_run_analysis
    data_dictionary = generate_analysis(result, number_of_runs, num_cores=int(sys.argv[2]), file_writing=False, savefile_path=filepath)
  File "/home/gahan/june24/040624_allparametersopen_limitSG/silphium/family_1/Generation_32/Run_3/Code/function_library.py", line 342, in generate_analysis
    lignin_libraries = pool.starmap(generate_analysis_parallel, [(cur_adjs[i], monolist[i], file_writing, savefile_path) for i, result in enumerate(results)])
  File "/home/gahan/anaconda3/envs/ligninsims/lib/python3.10/multiprocessing/pool.py", line 375, in starmap
    return self._map_async(func, iterable, starmapstar, chunksize).get()
  File "/home/gahan/anaconda3/envs/ligninsims/lib/python3.10/multiprocessing/pool.py", line 774, in get
    raise self._value
KeyError: 54
multiprocessing.pool.RemoteTraceback: 
"""
Traceback (most recent call last):
  File "/home/gahan/anaconda3/envs/ligninsims/lib/python3.10/multiprocessing/pool.py", line 125, in worker
    result = (True, func(*args, **kwds))
  File "/home/gahan/anaconda3/envs/ligninsims/lib/python3.10/multiprocessing/pool.py", line 51, in starmapstar
    return list(itertools.starmap(args[0], args[1]))
  File "/home/gahan/june24/040624_allparametersopen_limitSG/silphium/family_1/Generation_33/Run_1/Code/function_library.py", line 201, in generate_analysis_parallel
    smiles = partial_dict_B[smiles_dictionary_id]["smilestring"]
KeyError: 105
"""

The above exception was the direct cause of the following exception:

Traceback (most recent call last):
  File "/home/gahan/june24/040624_allparametersopen_limitSG/silphium/family_1/Generation_33/Run_1/Code/simulation_main.py", line 80, in <module>
    simulation_run_analysis(SG_ratio, simulation_time, monomer_addition_rate, minimum_num_monomers, maximum_num_monomers, rxn_rates, number_of_runs, filewriting, filepath)
  File "/home/gahan/june24/040624_allparametersopen_limitSG/silphium/family_1/Generation_33/Run_1/Code/simulation_main.py", line 22, in simulation_run_analysis
    data_dictionary = generate_analysis(result, number_of_runs, num_cores=int(sys.argv[2]), file_writing=False, savefile_path=filepath)
  File "/home/gahan/june24/040624_allparametersopen_limitSG/silphium/family_1/Generation_33/Run_1/Code/function_library.py", line 342, in generate_analysis
    lignin_libraries = pool.starmap(generate_analysis_parallel, [(cur_adjs[i], monolist[i], file_writing, savefile_path) for i, result in enumerate(results)])
  File "/home/gahan/anaconda3/envs/ligninsims/lib/python3.10/multiprocessing/pool.py", line 375, in starmap
    return self._map_async(func, iterable, starmapstar, chunksize).get()
  File "/home/gahan/anaconda3/envs/ligninsims/lib/python3.10/multiprocessing/pool.py", line 774, in get
    raise self._value
KeyError: 105
multiprocessing.pool.RemoteTraceback: 
"""
Traceback (most recent call last):
  File "/home/gahan/anaconda3/envs/ligninsims/lib/python3.10/multiprocessing/pool.py", line 125, in worker
    result = (True, func(*args, **kwds))
  File "/home/gahan/anaconda3/envs/ligninsims/lib/python3.10/multiprocessing/pool.py", line 51, in starmapstar
    return list(itertools.starmap(args[0], args[1]))
  File "/home/gahan/june24/040624_allparametersopen_limitSG/silphium/family_1/Generation_34/Run_1/Code/function_library.py", line 201, in generate_analysis_parallel
    smiles = partial_dict_B[smiles_dictionary_id]["smilestring"]
KeyError: 52
"""

The above exception was the direct cause of the following exception:

Traceback (most recent call last):
  File "/home/gahan/june24/040624_allparametersopen_limitSG/silphium/family_1/Generation_34/Run_1/Code/simulation_main.py", line 80, in <module>
    simulation_run_analysis(SG_ratio, simulation_time, monomer_addition_rate, minimum_num_monomers, maximum_num_monomers, rxn_rates, number_of_runs, filewriting, filepath)
  File "/home/gahan/june24/040624_allparametersopen_limitSG/silphium/family_1/Generation_34/Run_1/Code/simulation_main.py", line 22, in simulation_run_analysis
    data_dictionary = generate_analysis(result, number_of_runs, num_cores=int(sys.argv[2]), file_writing=False, savefile_path=filepath)
  File "/home/gahan/june24/040624_allparametersopen_limitSG/silphium/family_1/Generation_34/Run_1/Code/function_library.py", line 342, in generate_analysis
    lignin_libraries = pool.starmap(generate_analysis_parallel, [(cur_adjs[i], monolist[i], file_writing, savefile_path) for i, result in enumerate(results)])
  File "/home/gahan/anaconda3/envs/ligninsims/lib/python3.10/multiprocessing/pool.py", line 375, in starmap
    return self._map_async(func, iterable, starmapstar, chunksize).get()
  File "/home/gahan/anaconda3/envs/ligninsims/lib/python3.10/multiprocessing/pool.py", line 774, in get
    raise self._value
KeyError: 52
multiprocessing.pool.RemoteTraceback: 
"""
Traceback (most recent call last):
  File "/home/gahan/anaconda3/envs/ligninsims/lib/python3.10/multiprocessing/pool.py", line 125, in worker
    result = (True, func(*args, **kwds))
  File "/home/gahan/anaconda3/envs/ligninsims/lib/python3.10/multiprocessing/pool.py", line 51, in starmapstar
    return list(itertools.starmap(args[0], args[1]))
  File "/home/gahan/june24/040624_allparametersopen_limitSG/silphium/family_1/Generation_34/Run_3/Code/function_library.py", line 185, in generate_analysis_parallel
    nrings = np.sum([partial_dict_B[smiles_dictionary_id + k]["rings"] for k in range(partial_dict_A[bond_dictionary_id]['Bonds']["b1"]+1)])
  File "/home/gahan/june24/040624_allparametersopen_limitSG/silphium/family_1/Generation_34/Run_3/Code/function_library.py", line 185, in <listcomp>
    nrings = np.sum([partial_dict_B[smiles_dictionary_id + k]["rings"] for k in range(partial_dict_A[bond_dictionary_id]['Bonds']["b1"]+1)])
KeyError: 56
"""

The above exception was the direct cause of the following exception:

Traceback (most recent call last):
  File "/home/gahan/june24/040624_allparametersopen_limitSG/silphium/family_1/Generation_34/Run_3/Code/simulation_main.py", line 80, in <module>
    simulation_run_analysis(SG_ratio, simulation_time, monomer_addition_rate, minimum_num_monomers, maximum_num_monomers, rxn_rates, number_of_runs, filewriting, filepath)
  File "/home/gahan/june24/040624_allparametersopen_limitSG/silphium/family_1/Generation_34/Run_3/Code/simulation_main.py", line 22, in simulation_run_analysis
    data_dictionary = generate_analysis(result, number_of_runs, num_cores=int(sys.argv[2]), file_writing=False, savefile_path=filepath)
  File "/home/gahan/june24/040624_allparametersopen_limitSG/silphium/family_1/Generation_34/Run_3/Code/function_library.py", line 342, in generate_analysis
    lignin_libraries = pool.starmap(generate_analysis_parallel, [(cur_adjs[i], monolist[i], file_writing, savefile_path) for i, result in enumerate(results)])
  File "/home/gahan/anaconda3/envs/ligninsims/lib/python3.10/multiprocessing/pool.py", line 375, in starmap
    return self._map_async(func, iterable, starmapstar, chunksize).get()
  File "/home/gahan/anaconda3/envs/ligninsims/lib/python3.10/multiprocessing/pool.py", line 774, in get
    raise self._value
KeyError: 56
multiprocessing.pool.RemoteTraceback: 
"""
Traceback (most recent call last):
  File "/home/gahan/anaconda3/envs/ligninsims/lib/python3.10/multiprocessing/pool.py", line 125, in worker
    result = (True, func(*args, **kwds))
  File "/home/gahan/anaconda3/envs/ligninsims/lib/python3.10/multiprocessing/pool.py", line 51, in starmapstar
    return list(itertools.starmap(args[0], args[1]))
  File "/home/gahan/june24/040624_allparametersopen_limitSG/silphium/family_1/Generation_35/Run_1/Code/function_library.py", line 185, in generate_analysis_parallel
    nrings = np.sum([partial_dict_B[smiles_dictionary_id + k]["rings"] for k in range(partial_dict_A[bond_dictionary_id]['Bonds']["b1"]+1)])
  File "/home/gahan/june24/040624_allparametersopen_limitSG/silphium/family_1/Generation_35/Run_1/Code/function_library.py", line 185, in <listcomp>
    nrings = np.sum([partial_dict_B[smiles_dictionary_id + k]["rings"] for k in range(partial_dict_A[bond_dictionary_id]['Bonds']["b1"]+1)])
KeyError: 51
"""

The above exception was the direct cause of the following exception:

Traceback (most recent call last):
  File "/home/gahan/june24/040624_allparametersopen_limitSG/silphium/family_1/Generation_35/Run_1/Code/simulation_main.py", line 80, in <module>
    simulation_run_analysis(SG_ratio, simulation_time, monomer_addition_rate, minimum_num_monomers, maximum_num_monomers, rxn_rates, number_of_runs, filewriting, filepath)
  File "/home/gahan/june24/040624_allparametersopen_limitSG/silphium/family_1/Generation_35/Run_1/Code/simulation_main.py", line 22, in simulation_run_analysis
    data_dictionary = generate_analysis(result, number_of_runs, num_cores=int(sys.argv[2]), file_writing=False, savefile_path=filepath)
  File "/home/gahan/june24/040624_allparametersopen_limitSG/silphium/family_1/Generation_35/Run_1/Code/function_library.py", line 342, in generate_analysis
    lignin_libraries = pool.starmap(generate_analysis_parallel, [(cur_adjs[i], monolist[i], file_writing, savefile_path) for i, result in enumerate(results)])
  File "/home/gahan/anaconda3/envs/ligninsims/lib/python3.10/multiprocessing/pool.py", line 375, in starmap
    return self._map_async(func, iterable, starmapstar, chunksize).get()
  File "/home/gahan/anaconda3/envs/ligninsims/lib/python3.10/multiprocessing/pool.py", line 774, in get
    raise self._value
KeyError: 51
multiprocessing.pool.RemoteTraceback: 
"""
Traceback (most recent call last):
  File "/home/gahan/anaconda3/envs/ligninsims/lib/python3.10/multiprocessing/pool.py", line 125, in worker
    result = (True, func(*args, **kwds))
  File "/home/gahan/anaconda3/envs/ligninsims/lib/python3.10/multiprocessing/pool.py", line 51, in starmapstar
    return list(itertools.starmap(args[0], args[1]))
  File "/home/gahan/june24/040624_allparametersopen_limitSG/silphium/family_1/Generation_36/Run_3/Code/function_library.py", line 201, in generate_analysis_parallel
    smiles = partial_dict_B[smiles_dictionary_id]["smilestring"]
KeyError: 41
"""

The above exception was the direct cause of the following exception:

Traceback (most recent call last):
  File "/home/gahan/june24/040624_allparametersopen_limitSG/silphium/family_1/Generation_36/Run_3/Code/simulation_main.py", line 80, in <module>
    simulation_run_analysis(SG_ratio, simulation_time, monomer_addition_rate, minimum_num_monomers, maximum_num_monomers, rxn_rates, number_of_runs, filewriting, filepath)
  File "/home/gahan/june24/040624_allparametersopen_limitSG/silphium/family_1/Generation_36/Run_3/Code/simulation_main.py", line 22, in simulation_run_analysis
    data_dictionary = generate_analysis(result, number_of_runs, num_cores=int(sys.argv[2]), file_writing=False, savefile_path=filepath)
  File "/home/gahan/june24/040624_allparametersopen_limitSG/silphium/family_1/Generation_36/Run_3/Code/function_library.py", line 342, in generate_analysis
    lignin_libraries = pool.starmap(generate_analysis_parallel, [(cur_adjs[i], monolist[i], file_writing, savefile_path) for i, result in enumerate(results)])
  File "/home/gahan/anaconda3/envs/ligninsims/lib/python3.10/multiprocessing/pool.py", line 375, in starmap
    return self._map_async(func, iterable, starmapstar, chunksize).get()
  File "/home/gahan/anaconda3/envs/ligninsims/lib/python3.10/multiprocessing/pool.py", line 774, in get
    raise self._value
KeyError: 41
multiprocessing.pool.RemoteTraceback: 
"""
Traceback (most recent call last):
  File "/home/gahan/anaconda3/envs/ligninsims/lib/python3.10/multiprocessing/pool.py", line 125, in worker
    result = (True, func(*args, **kwds))
  File "/home/gahan/anaconda3/envs/ligninsims/lib/python3.10/multiprocessing/pool.py", line 51, in starmapstar
    return list(itertools.starmap(args[0], args[1]))
  File "/home/gahan/june24/040624_allparametersopen_limitSG/silphium/family_1/Generation_39/Run_2/Code/function_library.py", line 201, in generate_analysis_parallel
    smiles = partial_dict_B[smiles_dictionary_id]["smilestring"]
KeyError: 57
"""

The above exception was the direct cause of the following exception:

Traceback (most recent call last):
  File "/home/gahan/june24/040624_allparametersopen_limitSG/silphium/family_1/Generation_39/Run_2/Code/simulation_main.py", line 80, in <module>
    simulation_run_analysis(SG_ratio, simulation_time, monomer_addition_rate, minimum_num_monomers, maximum_num_monomers, rxn_rates, number_of_runs, filewriting, filepath)
  File "/home/gahan/june24/040624_allparametersopen_limitSG/silphium/family_1/Generation_39/Run_2/Code/simulation_main.py", line 22, in simulation_run_analysis
    data_dictionary = generate_analysis(result, number_of_runs, num_cores=int(sys.argv[2]), file_writing=False, savefile_path=filepath)
  File "/home/gahan/june24/040624_allparametersopen_limitSG/silphium/family_1/Generation_39/Run_2/Code/function_library.py", line 342, in generate_analysis
    lignin_libraries = pool.starmap(generate_analysis_parallel, [(cur_adjs[i], monolist[i], file_writing, savefile_path) for i, result in enumerate(results)])
  File "/home/gahan/anaconda3/envs/ligninsims/lib/python3.10/multiprocessing/pool.py", line 375, in starmap
    return self._map_async(func, iterable, starmapstar, chunksize).get()
  File "/home/gahan/anaconda3/envs/ligninsims/lib/python3.10/multiprocessing/pool.py", line 774, in get
    raise self._value
KeyError: 57
multiprocessing.pool.RemoteTraceback: 
"""
Traceback (most recent call last):
  File "/home/gahan/anaconda3/envs/ligninsims/lib/python3.10/multiprocessing/pool.py", line 125, in worker
    result = (True, func(*args, **kwds))
  File "/home/gahan/anaconda3/envs/ligninsims/lib/python3.10/multiprocessing/pool.py", line 51, in starmapstar
    return list(itertools.starmap(args[0], args[1]))
  File "/home/gahan/june24/040624_allparametersopen_limitSG/silphium/family_1/Generation_39/Run_3/Code/function_library.py", line 201, in generate_analysis_parallel
    smiles = partial_dict_B[smiles_dictionary_id]["smilestring"]
KeyError: 107
"""

The above exception was the direct cause of the following exception:

Traceback (most recent call last):
  File "/home/gahan/june24/040624_allparametersopen_limitSG/silphium/family_1/Generation_39/Run_3/Code/simulation_main.py", line 80, in <module>
    simulation_run_analysis(SG_ratio, simulation_time, monomer_addition_rate, minimum_num_monomers, maximum_num_monomers, rxn_rates, number_of_runs, filewriting, filepath)
  File "/home/gahan/june24/040624_allparametersopen_limitSG/silphium/family_1/Generation_39/Run_3/Code/simulation_main.py", line 22, in simulation_run_analysis
    data_dictionary = generate_analysis(result, number_of_runs, num_cores=int(sys.argv[2]), file_writing=False, savefile_path=filepath)
  File "/home/gahan/june24/040624_allparametersopen_limitSG/silphium/family_1/Generation_39/Run_3/Code/function_library.py", line 342, in generate_analysis
    lignin_libraries = pool.starmap(generate_analysis_parallel, [(cur_adjs[i], monolist[i], file_writing, savefile_path) for i, result in enumerate(results)])
  File "/home/gahan/anaconda3/envs/ligninsims/lib/python3.10/multiprocessing/pool.py", line 375, in starmap
    return self._map_async(func, iterable, starmapstar, chunksize).get()
  File "/home/gahan/anaconda3/envs/ligninsims/lib/python3.10/multiprocessing/pool.py", line 774, in get
    raise self._value
KeyError: 107
multiprocessing.pool.RemoteTraceback: 
"""
Traceback (most recent call last):
  File "/home/gahan/anaconda3/envs/ligninsims/lib/python3.10/multiprocessing/pool.py", line 125, in worker
    result = (True, func(*args, **kwds))
  File "/home/gahan/anaconda3/envs/ligninsims/lib/python3.10/multiprocessing/pool.py", line 51, in starmapstar
    return list(itertools.starmap(args[0], args[1]))
  File "/home/gahan/june24/040624_allparametersopen_limitSG/silphium/family_1/Generation_40/Run_3/Code/function_library.py", line 201, in generate_analysis_parallel
    smiles = partial_dict_B[smiles_dictionary_id]["smilestring"]
KeyError: 56
"""

The above exception was the direct cause of the following exception:

Traceback (most recent call last):
  File "/home/gahan/june24/040624_allparametersopen_limitSG/silphium/family_1/Generation_40/Run_3/Code/simulation_main.py", line 80, in <module>
    simulation_run_analysis(SG_ratio, simulation_time, monomer_addition_rate, minimum_num_monomers, maximum_num_monomers, rxn_rates, number_of_runs, filewriting, filepath)
  File "/home/gahan/june24/040624_allparametersopen_limitSG/silphium/family_1/Generation_40/Run_3/Code/simulation_main.py", line 22, in simulation_run_analysis
    data_dictionary = generate_analysis(result, number_of_runs, num_cores=int(sys.argv[2]), file_writing=False, savefile_path=filepath)
  File "/home/gahan/june24/040624_allparametersopen_limitSG/silphium/family_1/Generation_40/Run_3/Code/function_library.py", line 342, in generate_analysis
    lignin_libraries = pool.starmap(generate_analysis_parallel, [(cur_adjs[i], monolist[i], file_writing, savefile_path) for i, result in enumerate(results)])
  File "/home/gahan/anaconda3/envs/ligninsims/lib/python3.10/multiprocessing/pool.py", line 375, in starmap
    return self._map_async(func, iterable, starmapstar, chunksize).get()
  File "/home/gahan/anaconda3/envs/ligninsims/lib/python3.10/multiprocessing/pool.py", line 774, in get
    raise self._value
KeyError: 56
multiprocessing.pool.RemoteTraceback: 
"""
Traceback (most recent call last):
  File "/home/gahan/anaconda3/envs/ligninsims/lib/python3.10/multiprocessing/pool.py", line 125, in worker
    result = (True, func(*args, **kwds))
  File "/home/gahan/anaconda3/envs/ligninsims/lib/python3.10/multiprocessing/pool.py", line 51, in starmapstar
    return list(itertools.starmap(args[0], args[1]))
  File "/home/gahan/june24/040624_allparametersopen_limitSG/silphium/family_1/Generation_41/Run_1/Code/function_library.py", line 185, in generate_analysis_parallel
    nrings = np.sum([partial_dict_B[smiles_dictionary_id + k]["rings"] for k in range(partial_dict_A[bond_dictionary_id]['Bonds']["b1"]+1)])
  File "/home/gahan/june24/040624_allparametersopen_limitSG/silphium/family_1/Generation_41/Run_1/Code/function_library.py", line 185, in <listcomp>
    nrings = np.sum([partial_dict_B[smiles_dictionary_id + k]["rings"] for k in range(partial_dict_A[bond_dictionary_id]['Bonds']["b1"]+1)])
KeyError: 59
"""

The above exception was the direct cause of the following exception:

Traceback (most recent call last):
  File "/home/gahan/june24/040624_allparametersopen_limitSG/silphium/family_1/Generation_41/Run_1/Code/simulation_main.py", line 80, in <module>
    simulation_run_analysis(SG_ratio, simulation_time, monomer_addition_rate, minimum_num_monomers, maximum_num_monomers, rxn_rates, number_of_runs, filewriting, filepath)
  File "/home/gahan/june24/040624_allparametersopen_limitSG/silphium/family_1/Generation_41/Run_1/Code/simulation_main.py", line 22, in simulation_run_analysis
    data_dictionary = generate_analysis(result, number_of_runs, num_cores=int(sys.argv[2]), file_writing=False, savefile_path=filepath)
  File "/home/gahan/june24/040624_allparametersopen_limitSG/silphium/family_1/Generation_41/Run_1/Code/function_library.py", line 342, in generate_analysis
    lignin_libraries = pool.starmap(generate_analysis_parallel, [(cur_adjs[i], monolist[i], file_writing, savefile_path) for i, result in enumerate(results)])
  File "/home/gahan/anaconda3/envs/ligninsims/lib/python3.10/multiprocessing/pool.py", line 375, in starmap
    return self._map_async(func, iterable, starmapstar, chunksize).get()
  File "/home/gahan/anaconda3/envs/ligninsims/lib/python3.10/multiprocessing/pool.py", line 774, in get
    raise self._value
KeyError: 59
multiprocessing.pool.RemoteTraceback: 
"""
Traceback (most recent call last):
  File "/home/gahan/anaconda3/envs/ligninsims/lib/python3.10/multiprocessing/pool.py", line 125, in worker
    result = (True, func(*args, **kwds))
  File "/home/gahan/anaconda3/envs/ligninsims/lib/python3.10/multiprocessing/pool.py", line 51, in starmapstar
    return list(itertools.starmap(args[0], args[1]))
  File "/home/gahan/june24/040624_allparametersopen_limitSG/silphium/family_1/Generation_41/Run_2/Code/function_library.py", line 201, in generate_analysis_parallel
    smiles = partial_dict_B[smiles_dictionary_id]["smilestring"]
KeyError: 104
"""

The above exception was the direct cause of the following exception:

Traceback (most recent call last):
  File "/home/gahan/june24/040624_allparametersopen_limitSG/silphium/family_1/Generation_41/Run_2/Code/simulation_main.py", line 80, in <module>
    simulation_run_analysis(SG_ratio, simulation_time, monomer_addition_rate, minimum_num_monomers, maximum_num_monomers, rxn_rates, number_of_runs, filewriting, filepath)
  File "/home/gahan/june24/040624_allparametersopen_limitSG/silphium/family_1/Generation_41/Run_2/Code/simulation_main.py", line 22, in simulation_run_analysis
    data_dictionary = generate_analysis(result, number_of_runs, num_cores=int(sys.argv[2]), file_writing=False, savefile_path=filepath)
  File "/home/gahan/june24/040624_allparametersopen_limitSG/silphium/family_1/Generation_41/Run_2/Code/function_library.py", line 342, in generate_analysis
    lignin_libraries = pool.starmap(generate_analysis_parallel, [(cur_adjs[i], monolist[i], file_writing, savefile_path) for i, result in enumerate(results)])
  File "/home/gahan/anaconda3/envs/ligninsims/lib/python3.10/multiprocessing/pool.py", line 375, in starmap
    return self._map_async(func, iterable, starmapstar, chunksize).get()
  File "/home/gahan/anaconda3/envs/ligninsims/lib/python3.10/multiprocessing/pool.py", line 774, in get
    raise self._value
KeyError: 104
multiprocessing.pool.RemoteTraceback: 
"""
Traceback (most recent call last):
  File "/home/gahan/anaconda3/envs/ligninsims/lib/python3.10/multiprocessing/pool.py", line 125, in worker
    result = (True, func(*args, **kwds))
  File "/home/gahan/anaconda3/envs/ligninsims/lib/python3.10/multiprocessing/pool.py", line 51, in starmapstar
    return list(itertools.starmap(args[0], args[1]))
  File "/home/gahan/june24/040624_allparametersopen_limitSG/silphium/family_1/Generation_41/Run_3/Code/function_library.py", line 201, in generate_analysis_parallel
    smiles = partial_dict_B[smiles_dictionary_id]["smilestring"]
KeyError: 118
"""

The above exception was the direct cause of the following exception:

Traceback (most recent call last):
  File "/home/gahan/june24/040624_allparametersopen_limitSG/silphium/family_1/Generation_41/Run_3/Code/simulation_main.py", line 80, in <module>
    simulation_run_analysis(SG_ratio, simulation_time, monomer_addition_rate, minimum_num_monomers, maximum_num_monomers, rxn_rates, number_of_runs, filewriting, filepath)
  File "/home/gahan/june24/040624_allparametersopen_limitSG/silphium/family_1/Generation_41/Run_3/Code/simulation_main.py", line 22, in simulation_run_analysis
    data_dictionary = generate_analysis(result, number_of_runs, num_cores=int(sys.argv[2]), file_writing=False, savefile_path=filepath)
  File "/home/gahan/june24/040624_allparametersopen_limitSG/silphium/family_1/Generation_41/Run_3/Code/function_library.py", line 342, in generate_analysis
    lignin_libraries = pool.starmap(generate_analysis_parallel, [(cur_adjs[i], monolist[i], file_writing, savefile_path) for i, result in enumerate(results)])
  File "/home/gahan/anaconda3/envs/ligninsims/lib/python3.10/multiprocessing/pool.py", line 375, in starmap
    return self._map_async(func, iterable, starmapstar, chunksize).get()
  File "/home/gahan/anaconda3/envs/ligninsims/lib/python3.10/multiprocessing/pool.py", line 774, in get
    raise self._value
KeyError: 118
multiprocessing.pool.RemoteTraceback: 
"""
Traceback (most recent call last):
  File "/home/gahan/anaconda3/envs/ligninsims/lib/python3.10/multiprocessing/pool.py", line 125, in worker
    result = (True, func(*args, **kwds))
  File "/home/gahan/anaconda3/envs/ligninsims/lib/python3.10/multiprocessing/pool.py", line 51, in starmapstar
    return list(itertools.starmap(args[0], args[1]))
  File "/home/gahan/june24/040624_allparametersopen_limitSG/silphium/family_1/Generation_41/Run_4/Code/function_library.py", line 201, in generate_analysis_parallel
    smiles = partial_dict_B[smiles_dictionary_id]["smilestring"]
KeyError: 50
"""

The above exception was the direct cause of the following exception:

Traceback (most recent call last):
  File "/home/gahan/june24/040624_allparametersopen_limitSG/silphium/family_1/Generation_41/Run_4/Code/simulation_main.py", line 80, in <module>
    simulation_run_analysis(SG_ratio, simulation_time, monomer_addition_rate, minimum_num_monomers, maximum_num_monomers, rxn_rates, number_of_runs, filewriting, filepath)
  File "/home/gahan/june24/040624_allparametersopen_limitSG/silphium/family_1/Generation_41/Run_4/Code/simulation_main.py", line 22, in simulation_run_analysis
    data_dictionary = generate_analysis(result, number_of_runs, num_cores=int(sys.argv[2]), file_writing=False, savefile_path=filepath)
  File "/home/gahan/june24/040624_allparametersopen_limitSG/silphium/family_1/Generation_41/Run_4/Code/function_library.py", line 342, in generate_analysis
    lignin_libraries = pool.starmap(generate_analysis_parallel, [(cur_adjs[i], monolist[i], file_writing, savefile_path) for i, result in enumerate(results)])
  File "/home/gahan/anaconda3/envs/ligninsims/lib/python3.10/multiprocessing/pool.py", line 375, in starmap
    return self._map_async(func, iterable, starmapstar, chunksize).get()
  File "/home/gahan/anaconda3/envs/ligninsims/lib/python3.10/multiprocessing/pool.py", line 774, in get
    raise self._value
KeyError: 50
multiprocessing.pool.RemoteTraceback: 
"""
Traceback (most recent call last):
  File "/home/gahan/anaconda3/envs/ligninsims/lib/python3.10/multiprocessing/pool.py", line 125, in worker
    result = (True, func(*args, **kwds))
  File "/home/gahan/anaconda3/envs/ligninsims/lib/python3.10/multiprocessing/pool.py", line 51, in starmapstar
    return list(itertools.starmap(args[0], args[1]))
  File "/home/gahan/june24/040624_allparametersopen_limitSG/silphium/family_1/Generation_42/Run_1/Code/function_library.py", line 201, in generate_analysis_parallel
    smiles = partial_dict_B[smiles_dictionary_id]["smilestring"]
KeyError: 40
"""

The above exception was the direct cause of the following exception:

Traceback (most recent call last):
  File "/home/gahan/june24/040624_allparametersopen_limitSG/silphium/family_1/Generation_42/Run_1/Code/simulation_main.py", line 80, in <module>
    simulation_run_analysis(SG_ratio, simulation_time, monomer_addition_rate, minimum_num_monomers, maximum_num_monomers, rxn_rates, number_of_runs, filewriting, filepath)
  File "/home/gahan/june24/040624_allparametersopen_limitSG/silphium/family_1/Generation_42/Run_1/Code/simulation_main.py", line 22, in simulation_run_analysis
    data_dictionary = generate_analysis(result, number_of_runs, num_cores=int(sys.argv[2]), file_writing=False, savefile_path=filepath)
  File "/home/gahan/june24/040624_allparametersopen_limitSG/silphium/family_1/Generation_42/Run_1/Code/function_library.py", line 342, in generate_analysis
    lignin_libraries = pool.starmap(generate_analysis_parallel, [(cur_adjs[i], monolist[i], file_writing, savefile_path) for i, result in enumerate(results)])
  File "/home/gahan/anaconda3/envs/ligninsims/lib/python3.10/multiprocessing/pool.py", line 375, in starmap
    return self._map_async(func, iterable, starmapstar, chunksize).get()
  File "/home/gahan/anaconda3/envs/ligninsims/lib/python3.10/multiprocessing/pool.py", line 774, in get
    raise self._value
KeyError: 40
multiprocessing.pool.RemoteTraceback: 
"""
Traceback (most recent call last):
  File "/home/gahan/anaconda3/envs/ligninsims/lib/python3.10/multiprocessing/pool.py", line 125, in worker
    result = (True, func(*args, **kwds))
  File "/home/gahan/anaconda3/envs/ligninsims/lib/python3.10/multiprocessing/pool.py", line 51, in starmapstar
    return list(itertools.starmap(args[0], args[1]))
  File "/home/gahan/june24/040624_allparametersopen_limitSG/silphium/family_1/Generation_42/Run_2/Code/function_library.py", line 201, in generate_analysis_parallel
    smiles = partial_dict_B[smiles_dictionary_id]["smilestring"]
KeyError: 38
"""

The above exception was the direct cause of the following exception:

Traceback (most recent call last):
  File "/home/gahan/june24/040624_allparametersopen_limitSG/silphium/family_1/Generation_42/Run_2/Code/simulation_main.py", line 80, in <module>
    simulation_run_analysis(SG_ratio, simulation_time, monomer_addition_rate, minimum_num_monomers, maximum_num_monomers, rxn_rates, number_of_runs, filewriting, filepath)
  File "/home/gahan/june24/040624_allparametersopen_limitSG/silphium/family_1/Generation_42/Run_2/Code/simulation_main.py", line 22, in simulation_run_analysis
    data_dictionary = generate_analysis(result, number_of_runs, num_cores=int(sys.argv[2]), file_writing=False, savefile_path=filepath)
  File "/home/gahan/june24/040624_allparametersopen_limitSG/silphium/family_1/Generation_42/Run_2/Code/function_library.py", line 342, in generate_analysis
    lignin_libraries = pool.starmap(generate_analysis_parallel, [(cur_adjs[i], monolist[i], file_writing, savefile_path) for i, result in enumerate(results)])
  File "/home/gahan/anaconda3/envs/ligninsims/lib/python3.10/multiprocessing/pool.py", line 375, in starmap
    return self._map_async(func, iterable, starmapstar, chunksize).get()
  File "/home/gahan/anaconda3/envs/ligninsims/lib/python3.10/multiprocessing/pool.py", line 774, in get
    raise self._value
KeyError: 38
multiprocessing.pool.RemoteTraceback: 
"""
Traceback (most recent call last):
  File "/home/gahan/anaconda3/envs/ligninsims/lib/python3.10/multiprocessing/pool.py", line 125, in worker
    result = (True, func(*args, **kwds))
  File "/home/gahan/anaconda3/envs/ligninsims/lib/python3.10/multiprocessing/pool.py", line 51, in starmapstar
    return list(itertools.starmap(args[0], args[1]))
  File "/home/gahan/june24/040624_allparametersopen_limitSG/silphium/family_1/Generation_43/Run_1/Code/function_library.py", line 201, in generate_analysis_parallel
    smiles = partial_dict_B[smiles_dictionary_id]["smilestring"]
KeyError: 115
"""

The above exception was the direct cause of the following exception:

Traceback (most recent call last):
  File "/home/gahan/june24/040624_allparametersopen_limitSG/silphium/family_1/Generation_43/Run_1/Code/simulation_main.py", line 80, in <module>
    simulation_run_analysis(SG_ratio, simulation_time, monomer_addition_rate, minimum_num_monomers, maximum_num_monomers, rxn_rates, number_of_runs, filewriting, filepath)
  File "/home/gahan/june24/040624_allparametersopen_limitSG/silphium/family_1/Generation_43/Run_1/Code/simulation_main.py", line 22, in simulation_run_analysis
    data_dictionary = generate_analysis(result, number_of_runs, num_cores=int(sys.argv[2]), file_writing=False, savefile_path=filepath)
  File "/home/gahan/june24/040624_allparametersopen_limitSG/silphium/family_1/Generation_43/Run_1/Code/function_library.py", line 342, in generate_analysis
    lignin_libraries = pool.starmap(generate_analysis_parallel, [(cur_adjs[i], monolist[i], file_writing, savefile_path) for i, result in enumerate(results)])
  File "/home/gahan/anaconda3/envs/ligninsims/lib/python3.10/multiprocessing/pool.py", line 375, in starmap
    return self._map_async(func, iterable, starmapstar, chunksize).get()
  File "/home/gahan/anaconda3/envs/ligninsims/lib/python3.10/multiprocessing/pool.py", line 774, in get
    raise self._value
KeyError: 115
multiprocessing.pool.RemoteTraceback: 
"""
Traceback (most recent call last):
  File "/home/gahan/anaconda3/envs/ligninsims/lib/python3.10/multiprocessing/pool.py", line 125, in worker
    result = (True, func(*args, **kwds))
  File "/home/gahan/anaconda3/envs/ligninsims/lib/python3.10/multiprocessing/pool.py", line 51, in starmapstar
    return list(itertools.starmap(args[0], args[1]))
  File "/home/gahan/june24/040624_allparametersopen_limitSG/silphium/family_1/Generation_45/Run_1/Code/function_library.py", line 201, in generate_analysis_parallel
    smiles = partial_dict_B[smiles_dictionary_id]["smilestring"]
KeyError: 83
"""

The above exception was the direct cause of the following exception:

Traceback (most recent call last):
  File "/home/gahan/june24/040624_allparametersopen_limitSG/silphium/family_1/Generation_45/Run_1/Code/simulation_main.py", line 80, in <module>
    simulation_run_analysis(SG_ratio, simulation_time, monomer_addition_rate, minimum_num_monomers, maximum_num_monomers, rxn_rates, number_of_runs, filewriting, filepath)
  File "/home/gahan/june24/040624_allparametersopen_limitSG/silphium/family_1/Generation_45/Run_1/Code/simulation_main.py", line 22, in simulation_run_analysis
    data_dictionary = generate_analysis(result, number_of_runs, num_cores=int(sys.argv[2]), file_writing=False, savefile_path=filepath)
  File "/home/gahan/june24/040624_allparametersopen_limitSG/silphium/family_1/Generation_45/Run_1/Code/function_library.py", line 342, in generate_analysis
    lignin_libraries = pool.starmap(generate_analysis_parallel, [(cur_adjs[i], monolist[i], file_writing, savefile_path) for i, result in enumerate(results)])
  File "/home/gahan/anaconda3/envs/ligninsims/lib/python3.10/multiprocessing/pool.py", line 375, in starmap
    return self._map_async(func, iterable, starmapstar, chunksize).get()
  File "/home/gahan/anaconda3/envs/ligninsims/lib/python3.10/multiprocessing/pool.py", line 774, in get
    raise self._value
KeyError: 83
multiprocessing.pool.RemoteTraceback: 
"""
Traceback (most recent call last):
  File "/home/gahan/anaconda3/envs/ligninsims/lib/python3.10/multiprocessing/pool.py", line 125, in worker
    result = (True, func(*args, **kwds))
  File "/home/gahan/anaconda3/envs/ligninsims/lib/python3.10/multiprocessing/pool.py", line 51, in starmapstar
    return list(itertools.starmap(args[0], args[1]))
  File "/home/gahan/june24/040624_allparametersopen_limitSG/silphium/family_1/Generation_45/Run_3/Code/function_library.py", line 185, in generate_analysis_parallel
    nrings = np.sum([partial_dict_B[smiles_dictionary_id + k]["rings"] for k in range(partial_dict_A[bond_dictionary_id]['Bonds']["b1"]+1)])
  File "/home/gahan/june24/040624_allparametersopen_limitSG/silphium/family_1/Generation_45/Run_3/Code/function_library.py", line 185, in <listcomp>
    nrings = np.sum([partial_dict_B[smiles_dictionary_id + k]["rings"] for k in range(partial_dict_A[bond_dictionary_id]['Bonds']["b1"]+1)])
KeyError: 54
"""

The above exception was the direct cause of the following exception:

Traceback (most recent call last):
  File "/home/gahan/june24/040624_allparametersopen_limitSG/silphium/family_1/Generation_45/Run_3/Code/simulation_main.py", line 80, in <module>
    simulation_run_analysis(SG_ratio, simulation_time, monomer_addition_rate, minimum_num_monomers, maximum_num_monomers, rxn_rates, number_of_runs, filewriting, filepath)
  File "/home/gahan/june24/040624_allparametersopen_limitSG/silphium/family_1/Generation_45/Run_3/Code/simulation_main.py", line 22, in simulation_run_analysis
    data_dictionary = generate_analysis(result, number_of_runs, num_cores=int(sys.argv[2]), file_writing=False, savefile_path=filepath)
  File "/home/gahan/june24/040624_allparametersopen_limitSG/silphium/family_1/Generation_45/Run_3/Code/function_library.py", line 342, in generate_analysis
    lignin_libraries = pool.starmap(generate_analysis_parallel, [(cur_adjs[i], monolist[i], file_writing, savefile_path) for i, result in enumerate(results)])
  File "/home/gahan/anaconda3/envs/ligninsims/lib/python3.10/multiprocessing/pool.py", line 375, in starmap
    return self._map_async(func, iterable, starmapstar, chunksize).get()
  File "/home/gahan/anaconda3/envs/ligninsims/lib/python3.10/multiprocessing/pool.py", line 774, in get
    raise self._value
KeyError: 54
multiprocessing.pool.RemoteTraceback: 
"""
Traceback (most recent call last):
  File "/home/gahan/anaconda3/envs/ligninsims/lib/python3.10/multiprocessing/pool.py", line 125, in worker
    result = (True, func(*args, **kwds))
  File "/home/gahan/anaconda3/envs/ligninsims/lib/python3.10/multiprocessing/pool.py", line 51, in starmapstar
    return list(itertools.starmap(args[0], args[1]))
  File "/home/gahan/june24/040624_allparametersopen_limitSG/silphium/family_1/Generation_45/Run_4/Code/function_library.py", line 185, in generate_analysis_parallel
    nrings = np.sum([partial_dict_B[smiles_dictionary_id + k]["rings"] for k in range(partial_dict_A[bond_dictionary_id]['Bonds']["b1"]+1)])
  File "/home/gahan/june24/040624_allparametersopen_limitSG/silphium/family_1/Generation_45/Run_4/Code/function_library.py", line 185, in <listcomp>
    nrings = np.sum([partial_dict_B[smiles_dictionary_id + k]["rings"] for k in range(partial_dict_A[bond_dictionary_id]['Bonds']["b1"]+1)])
KeyError: 71
"""

The above exception was the direct cause of the following exception:

Traceback (most recent call last):
  File "/home/gahan/june24/040624_allparametersopen_limitSG/silphium/family_1/Generation_45/Run_4/Code/simulation_main.py", line 80, in <module>
    simulation_run_analysis(SG_ratio, simulation_time, monomer_addition_rate, minimum_num_monomers, maximum_num_monomers, rxn_rates, number_of_runs, filewriting, filepath)
  File "/home/gahan/june24/040624_allparametersopen_limitSG/silphium/family_1/Generation_45/Run_4/Code/simulation_main.py", line 22, in simulation_run_analysis
    data_dictionary = generate_analysis(result, number_of_runs, num_cores=int(sys.argv[2]), file_writing=False, savefile_path=filepath)
  File "/home/gahan/june24/040624_allparametersopen_limitSG/silphium/family_1/Generation_45/Run_4/Code/function_library.py", line 342, in generate_analysis
    lignin_libraries = pool.starmap(generate_analysis_parallel, [(cur_adjs[i], monolist[i], file_writing, savefile_path) for i, result in enumerate(results)])
  File "/home/gahan/anaconda3/envs/ligninsims/lib/python3.10/multiprocessing/pool.py", line 375, in starmap
    return self._map_async(func, iterable, starmapstar, chunksize).get()
  File "/home/gahan/anaconda3/envs/ligninsims/lib/python3.10/multiprocessing/pool.py", line 774, in get
    raise self._value
KeyError: 71
multiprocessing.pool.RemoteTraceback: 
"""
Traceback (most recent call last):
  File "/home/gahan/anaconda3/envs/ligninsims/lib/python3.10/multiprocessing/pool.py", line 125, in worker
    result = (True, func(*args, **kwds))
  File "/home/gahan/anaconda3/envs/ligninsims/lib/python3.10/multiprocessing/pool.py", line 51, in starmapstar
    return list(itertools.starmap(args[0], args[1]))
  File "/home/gahan/june24/040624_allparametersopen_limitSG/silphium/family_1/Generation_46/Run_4/Code/function_library.py", line 185, in generate_analysis_parallel
    nrings = np.sum([partial_dict_B[smiles_dictionary_id + k]["rings"] for k in range(partial_dict_A[bond_dictionary_id]['Bonds']["b1"]+1)])
  File "/home/gahan/june24/040624_allparametersopen_limitSG/silphium/family_1/Generation_46/Run_4/Code/function_library.py", line 185, in <listcomp>
    nrings = np.sum([partial_dict_B[smiles_dictionary_id + k]["rings"] for k in range(partial_dict_A[bond_dictionary_id]['Bonds']["b1"]+1)])
KeyError: 41
"""

The above exception was the direct cause of the following exception:

Traceback (most recent call last):
  File "/home/gahan/june24/040624_allparametersopen_limitSG/silphium/family_1/Generation_46/Run_4/Code/simulation_main.py", line 80, in <module>
    simulation_run_analysis(SG_ratio, simulation_time, monomer_addition_rate, minimum_num_monomers, maximum_num_monomers, rxn_rates, number_of_runs, filewriting, filepath)
  File "/home/gahan/june24/040624_allparametersopen_limitSG/silphium/family_1/Generation_46/Run_4/Code/simulation_main.py", line 22, in simulation_run_analysis
    data_dictionary = generate_analysis(result, number_of_runs, num_cores=int(sys.argv[2]), file_writing=False, savefile_path=filepath)
  File "/home/gahan/june24/040624_allparametersopen_limitSG/silphium/family_1/Generation_46/Run_4/Code/function_library.py", line 342, in generate_analysis
    lignin_libraries = pool.starmap(generate_analysis_parallel, [(cur_adjs[i], monolist[i], file_writing, savefile_path) for i, result in enumerate(results)])
  File "/home/gahan/anaconda3/envs/ligninsims/lib/python3.10/multiprocessing/pool.py", line 375, in starmap
    return self._map_async(func, iterable, starmapstar, chunksize).get()
  File "/home/gahan/anaconda3/envs/ligninsims/lib/python3.10/multiprocessing/pool.py", line 774, in get
    raise self._value
KeyError: 41
multiprocessing.pool.RemoteTraceback: 
"""
Traceback (most recent call last):
  File "/home/gahan/anaconda3/envs/ligninsims/lib/python3.10/multiprocessing/pool.py", line 125, in worker
    result = (True, func(*args, **kwds))
  File "/home/gahan/anaconda3/envs/ligninsims/lib/python3.10/multiprocessing/pool.py", line 51, in starmapstar
    return list(itertools.starmap(args[0], args[1]))
  File "/home/gahan/june24/040624_allparametersopen_limitSG/silphium/family_1/Generation_47/Run_2/Code/function_library.py", line 185, in generate_analysis_parallel
    nrings = np.sum([partial_dict_B[smiles_dictionary_id + k]["rings"] for k in range(partial_dict_A[bond_dictionary_id]['Bonds']["b1"]+1)])
  File "/home/gahan/june24/040624_allparametersopen_limitSG/silphium/family_1/Generation_47/Run_2/Code/function_library.py", line 185, in <listcomp>
    nrings = np.sum([partial_dict_B[smiles_dictionary_id + k]["rings"] for k in range(partial_dict_A[bond_dictionary_id]['Bonds']["b1"]+1)])
KeyError: 55
"""

The above exception was the direct cause of the following exception:

Traceback (most recent call last):
  File "/home/gahan/june24/040624_allparametersopen_limitSG/silphium/family_1/Generation_47/Run_2/Code/simulation_main.py", line 80, in <module>
    simulation_run_analysis(SG_ratio, simulation_time, monomer_addition_rate, minimum_num_monomers, maximum_num_monomers, rxn_rates, number_of_runs, filewriting, filepath)
  File "/home/gahan/june24/040624_allparametersopen_limitSG/silphium/family_1/Generation_47/Run_2/Code/simulation_main.py", line 22, in simulation_run_analysis
    data_dictionary = generate_analysis(result, number_of_runs, num_cores=int(sys.argv[2]), file_writing=False, savefile_path=filepath)
  File "/home/gahan/june24/040624_allparametersopen_limitSG/silphium/family_1/Generation_47/Run_2/Code/function_library.py", line 342, in generate_analysis
    lignin_libraries = pool.starmap(generate_analysis_parallel, [(cur_adjs[i], monolist[i], file_writing, savefile_path) for i, result in enumerate(results)])
  File "/home/gahan/anaconda3/envs/ligninsims/lib/python3.10/multiprocessing/pool.py", line 375, in starmap
    return self._map_async(func, iterable, starmapstar, chunksize).get()
  File "/home/gahan/anaconda3/envs/ligninsims/lib/python3.10/multiprocessing/pool.py", line 774, in get
    raise self._value
KeyError: 55
multiprocessing.pool.RemoteTraceback: 
"""
Traceback (most recent call last):
  File "/home/gahan/anaconda3/envs/ligninsims/lib/python3.10/multiprocessing/pool.py", line 125, in worker
    result = (True, func(*args, **kwds))
  File "/home/gahan/anaconda3/envs/ligninsims/lib/python3.10/multiprocessing/pool.py", line 51, in starmapstar
    return list(itertools.starmap(args[0], args[1]))
  File "/home/gahan/june24/040624_allparametersopen_limitSG/silphium/family_1/Generation_47/Run_4/Code/function_library.py", line 201, in generate_analysis_parallel
    smiles = partial_dict_B[smiles_dictionary_id]["smilestring"]
KeyError: 33
"""

The above exception was the direct cause of the following exception:

Traceback (most recent call last):
  File "/home/gahan/june24/040624_allparametersopen_limitSG/silphium/family_1/Generation_47/Run_4/Code/simulation_main.py", line 80, in <module>
    simulation_run_analysis(SG_ratio, simulation_time, monomer_addition_rate, minimum_num_monomers, maximum_num_monomers, rxn_rates, number_of_runs, filewriting, filepath)
  File "/home/gahan/june24/040624_allparametersopen_limitSG/silphium/family_1/Generation_47/Run_4/Code/simulation_main.py", line 22, in simulation_run_analysis
    data_dictionary = generate_analysis(result, number_of_runs, num_cores=int(sys.argv[2]), file_writing=False, savefile_path=filepath)
  File "/home/gahan/june24/040624_allparametersopen_limitSG/silphium/family_1/Generation_47/Run_4/Code/function_library.py", line 342, in generate_analysis
    lignin_libraries = pool.starmap(generate_analysis_parallel, [(cur_adjs[i], monolist[i], file_writing, savefile_path) for i, result in enumerate(results)])
  File "/home/gahan/anaconda3/envs/ligninsims/lib/python3.10/multiprocessing/pool.py", line 375, in starmap
    return self._map_async(func, iterable, starmapstar, chunksize).get()
  File "/home/gahan/anaconda3/envs/ligninsims/lib/python3.10/multiprocessing/pool.py", line 774, in get
    raise self._value
KeyError: 33
multiprocessing.pool.RemoteTraceback: 
"""
Traceback (most recent call last):
  File "/home/gahan/anaconda3/envs/ligninsims/lib/python3.10/multiprocessing/pool.py", line 125, in worker
    result = (True, func(*args, **kwds))
  File "/home/gahan/anaconda3/envs/ligninsims/lib/python3.10/multiprocessing/pool.py", line 51, in starmapstar
    return list(itertools.starmap(args[0], args[1]))
  File "/home/gahan/june24/040624_allparametersopen_limitSG/silphium/family_1/Generation_48/Run_4/Code/function_library.py", line 185, in generate_analysis_parallel
    nrings = np.sum([partial_dict_B[smiles_dictionary_id + k]["rings"] for k in range(partial_dict_A[bond_dictionary_id]['Bonds']["b1"]+1)])
  File "/home/gahan/june24/040624_allparametersopen_limitSG/silphium/family_1/Generation_48/Run_4/Code/function_library.py", line 185, in <listcomp>
    nrings = np.sum([partial_dict_B[smiles_dictionary_id + k]["rings"] for k in range(partial_dict_A[bond_dictionary_id]['Bonds']["b1"]+1)])
KeyError: 61
"""

The above exception was the direct cause of the following exception:

Traceback (most recent call last):
  File "/home/gahan/june24/040624_allparametersopen_limitSG/silphium/family_1/Generation_48/Run_4/Code/simulation_main.py", line 80, in <module>
    simulation_run_analysis(SG_ratio, simulation_time, monomer_addition_rate, minimum_num_monomers, maximum_num_monomers, rxn_rates, number_of_runs, filewriting, filepath)
  File "/home/gahan/june24/040624_allparametersopen_limitSG/silphium/family_1/Generation_48/Run_4/Code/simulation_main.py", line 22, in simulation_run_analysis
    data_dictionary = generate_analysis(result, number_of_runs, num_cores=int(sys.argv[2]), file_writing=False, savefile_path=filepath)
  File "/home/gahan/june24/040624_allparametersopen_limitSG/silphium/family_1/Generation_48/Run_4/Code/function_library.py", line 342, in generate_analysis
    lignin_libraries = pool.starmap(generate_analysis_parallel, [(cur_adjs[i], monolist[i], file_writing, savefile_path) for i, result in enumerate(results)])
  File "/home/gahan/anaconda3/envs/ligninsims/lib/python3.10/multiprocessing/pool.py", line 375, in starmap
    return self._map_async(func, iterable, starmapstar, chunksize).get()
  File "/home/gahan/anaconda3/envs/ligninsims/lib/python3.10/multiprocessing/pool.py", line 774, in get
    raise self._value
KeyError: 61
multiprocessing.pool.RemoteTraceback: 
"""
Traceback (most recent call last):
  File "/home/gahan/anaconda3/envs/ligninsims/lib/python3.10/multiprocessing/pool.py", line 125, in worker
    result = (True, func(*args, **kwds))
  File "/home/gahan/anaconda3/envs/ligninsims/lib/python3.10/multiprocessing/pool.py", line 51, in starmapstar
    return list(itertools.starmap(args[0], args[1]))
  File "/home/gahan/june24/040624_allparametersopen_limitSG/silphium/family_1/Generation_50/Run_4/Code/function_library.py", line 201, in generate_analysis_parallel
    smiles = partial_dict_B[smiles_dictionary_id]["smilestring"]
KeyError: 45
"""

The above exception was the direct cause of the following exception:

Traceback (most recent call last):
  File "/home/gahan/june24/040624_allparametersopen_limitSG/silphium/family_1/Generation_50/Run_4/Code/simulation_main.py", line 80, in <module>
    simulation_run_analysis(SG_ratio, simulation_time, monomer_addition_rate, minimum_num_monomers, maximum_num_monomers, rxn_rates, number_of_runs, filewriting, filepath)
  File "/home/gahan/june24/040624_allparametersopen_limitSG/silphium/family_1/Generation_50/Run_4/Code/simulation_main.py", line 22, in simulation_run_analysis
    data_dictionary = generate_analysis(result, number_of_runs, num_cores=int(sys.argv[2]), file_writing=False, savefile_path=filepath)
  File "/home/gahan/june24/040624_allparametersopen_limitSG/silphium/family_1/Generation_50/Run_4/Code/function_library.py", line 342, in generate_analysis
    lignin_libraries = pool.starmap(generate_analysis_parallel, [(cur_adjs[i], monolist[i], file_writing, savefile_path) for i, result in enumerate(results)])
  File "/home/gahan/anaconda3/envs/ligninsims/lib/python3.10/multiprocessing/pool.py", line 375, in starmap
    return self._map_async(func, iterable, starmapstar, chunksize).get()
  File "/home/gahan/anaconda3/envs/ligninsims/lib/python3.10/multiprocessing/pool.py", line 774, in get
    raise self._value
KeyError: 45
rm: das Entfernen von 'Gridsearch/Run*' ist nicht möglich: Datei oder Verzeichnis nicht gefunden
