multiprocessing.pool.RemoteTraceback: 
"""
Traceback (most recent call last):
  File "/home/gahan/anaconda3/envs/ligninsims/lib/python3.10/multiprocessing/pool.py", line 125, in worker
    result = (True, func(*args, **kwds))
  File "/home/gahan/anaconda3/envs/ligninsims/lib/python3.10/multiprocessing/pool.py", line 51, in starmapstar
    return list(itertools.starmap(args[0], args[1]))
  File "/home/gahan/may24/240524_allparametersopen/spruce_dellon/family_1/Generation_35/Run_2/Code/function_library.py", line 185, in generate_analysis_parallel
    nrings = np.sum([partial_dict_B[smiles_dictionary_id + k]["rings"] for k in range(partial_dict_A[bond_dictionary_id]['Bonds']["b1"]+1)])
  File "/home/gahan/may24/240524_allparametersopen/spruce_dellon/family_1/Generation_35/Run_2/Code/function_library.py", line 185, in <listcomp>
    nrings = np.sum([partial_dict_B[smiles_dictionary_id + k]["rings"] for k in range(partial_dict_A[bond_dictionary_id]['Bonds']["b1"]+1)])
KeyError: 42
"""

The above exception was the direct cause of the following exception:

Traceback (most recent call last):
  File "/home/gahan/may24/240524_allparametersopen/spruce_dellon/family_1/Generation_35/Run_2/Code/simulation_main.py", line 80, in <module>
    simulation_run_analysis(SG_ratio, simulation_time, monomer_addition_rate, minimum_num_monomers, maximum_num_monomers, rxn_rates, number_of_runs, filewriting, filepath)
  File "/home/gahan/may24/240524_allparametersopen/spruce_dellon/family_1/Generation_35/Run_2/Code/simulation_main.py", line 22, in simulation_run_analysis
    data_dictionary = generate_analysis(result, number_of_runs, num_cores=int(sys.argv[2]), file_writing=False, savefile_path=filepath)
  File "/home/gahan/may24/240524_allparametersopen/spruce_dellon/family_1/Generation_35/Run_2/Code/function_library.py", line 342, in generate_analysis
    lignin_libraries = pool.starmap(generate_analysis_parallel, [(cur_adjs[i], monolist[i], file_writing, savefile_path) for i, result in enumerate(results)])
  File "/home/gahan/anaconda3/envs/ligninsims/lib/python3.10/multiprocessing/pool.py", line 375, in starmap
    return self._map_async(func, iterable, starmapstar, chunksize).get()
  File "/home/gahan/anaconda3/envs/ligninsims/lib/python3.10/multiprocessing/pool.py", line 774, in get
    raise self._value
KeyError: 42
multiprocessing.pool.RemoteTraceback: 
"""
Traceback (most recent call last):
  File "/home/gahan/anaconda3/envs/ligninsims/lib/python3.10/multiprocessing/pool.py", line 125, in worker
    result = (True, func(*args, **kwds))
  File "/home/gahan/anaconda3/envs/ligninsims/lib/python3.10/multiprocessing/pool.py", line 51, in starmapstar
    return list(itertools.starmap(args[0], args[1]))
  File "/home/gahan/may24/240524_allparametersopen/spruce_dellon/family_1/Generation_36/Run_3/Code/function_library.py", line 201, in generate_analysis_parallel
    smiles = partial_dict_B[smiles_dictionary_id]["smilestring"]
KeyError: 45
"""

The above exception was the direct cause of the following exception:

Traceback (most recent call last):
  File "/home/gahan/may24/240524_allparametersopen/spruce_dellon/family_1/Generation_36/Run_3/Code/simulation_main.py", line 80, in <module>
    simulation_run_analysis(SG_ratio, simulation_time, monomer_addition_rate, minimum_num_monomers, maximum_num_monomers, rxn_rates, number_of_runs, filewriting, filepath)
  File "/home/gahan/may24/240524_allparametersopen/spruce_dellon/family_1/Generation_36/Run_3/Code/simulation_main.py", line 22, in simulation_run_analysis
    data_dictionary = generate_analysis(result, number_of_runs, num_cores=int(sys.argv[2]), file_writing=False, savefile_path=filepath)
  File "/home/gahan/may24/240524_allparametersopen/spruce_dellon/family_1/Generation_36/Run_3/Code/function_library.py", line 342, in generate_analysis
    lignin_libraries = pool.starmap(generate_analysis_parallel, [(cur_adjs[i], monolist[i], file_writing, savefile_path) for i, result in enumerate(results)])
  File "/home/gahan/anaconda3/envs/ligninsims/lib/python3.10/multiprocessing/pool.py", line 375, in starmap
    return self._map_async(func, iterable, starmapstar, chunksize).get()
  File "/home/gahan/anaconda3/envs/ligninsims/lib/python3.10/multiprocessing/pool.py", line 774, in get
    raise self._value
KeyError: 45
multiprocessing.pool.RemoteTraceback: 
"""
Traceback (most recent call last):
  File "/home/gahan/anaconda3/envs/ligninsims/lib/python3.10/multiprocessing/pool.py", line 125, in worker
    result = (True, func(*args, **kwds))
  File "/home/gahan/anaconda3/envs/ligninsims/lib/python3.10/multiprocessing/pool.py", line 51, in starmapstar
    return list(itertools.starmap(args[0], args[1]))
  File "/home/gahan/may24/240524_allparametersopen/spruce_dellon/family_1/Generation_37/Run_1/Code/function_library.py", line 185, in generate_analysis_parallel
    nrings = np.sum([partial_dict_B[smiles_dictionary_id + k]["rings"] for k in range(partial_dict_A[bond_dictionary_id]['Bonds']["b1"]+1)])
  File "/home/gahan/may24/240524_allparametersopen/spruce_dellon/family_1/Generation_37/Run_1/Code/function_library.py", line 185, in <listcomp>
    nrings = np.sum([partial_dict_B[smiles_dictionary_id + k]["rings"] for k in range(partial_dict_A[bond_dictionary_id]['Bonds']["b1"]+1)])
KeyError: 36
"""

The above exception was the direct cause of the following exception:

Traceback (most recent call last):
  File "/home/gahan/may24/240524_allparametersopen/spruce_dellon/family_1/Generation_37/Run_1/Code/simulation_main.py", line 80, in <module>
    simulation_run_analysis(SG_ratio, simulation_time, monomer_addition_rate, minimum_num_monomers, maximum_num_monomers, rxn_rates, number_of_runs, filewriting, filepath)
  File "/home/gahan/may24/240524_allparametersopen/spruce_dellon/family_1/Generation_37/Run_1/Code/simulation_main.py", line 22, in simulation_run_analysis
    data_dictionary = generate_analysis(result, number_of_runs, num_cores=int(sys.argv[2]), file_writing=False, savefile_path=filepath)
  File "/home/gahan/may24/240524_allparametersopen/spruce_dellon/family_1/Generation_37/Run_1/Code/function_library.py", line 342, in generate_analysis
    lignin_libraries = pool.starmap(generate_analysis_parallel, [(cur_adjs[i], monolist[i], file_writing, savefile_path) for i, result in enumerate(results)])
  File "/home/gahan/anaconda3/envs/ligninsims/lib/python3.10/multiprocessing/pool.py", line 375, in starmap
    return self._map_async(func, iterable, starmapstar, chunksize).get()
  File "/home/gahan/anaconda3/envs/ligninsims/lib/python3.10/multiprocessing/pool.py", line 774, in get
    raise self._value
KeyError: 36
multiprocessing.pool.RemoteTraceback: 
"""
Traceback (most recent call last):
  File "/home/gahan/anaconda3/envs/ligninsims/lib/python3.10/multiprocessing/pool.py", line 125, in worker
    result = (True, func(*args, **kwds))
  File "/home/gahan/anaconda3/envs/ligninsims/lib/python3.10/multiprocessing/pool.py", line 51, in starmapstar
    return list(itertools.starmap(args[0], args[1]))
  File "/home/gahan/may24/240524_allparametersopen/spruce_dellon/family_1/Generation_37/Run_3/Code/function_library.py", line 201, in generate_analysis_parallel
    smiles = partial_dict_B[smiles_dictionary_id]["smilestring"]
KeyError: 40
"""

The above exception was the direct cause of the following exception:

Traceback (most recent call last):
  File "/home/gahan/may24/240524_allparametersopen/spruce_dellon/family_1/Generation_37/Run_3/Code/simulation_main.py", line 80, in <module>
    simulation_run_analysis(SG_ratio, simulation_time, monomer_addition_rate, minimum_num_monomers, maximum_num_monomers, rxn_rates, number_of_runs, filewriting, filepath)
  File "/home/gahan/may24/240524_allparametersopen/spruce_dellon/family_1/Generation_37/Run_3/Code/simulation_main.py", line 22, in simulation_run_analysis
    data_dictionary = generate_analysis(result, number_of_runs, num_cores=int(sys.argv[2]), file_writing=False, savefile_path=filepath)
  File "/home/gahan/may24/240524_allparametersopen/spruce_dellon/family_1/Generation_37/Run_3/Code/function_library.py", line 342, in generate_analysis
    lignin_libraries = pool.starmap(generate_analysis_parallel, [(cur_adjs[i], monolist[i], file_writing, savefile_path) for i, result in enumerate(results)])
  File "/home/gahan/anaconda3/envs/ligninsims/lib/python3.10/multiprocessing/pool.py", line 375, in starmap
    return self._map_async(func, iterable, starmapstar, chunksize).get()
  File "/home/gahan/anaconda3/envs/ligninsims/lib/python3.10/multiprocessing/pool.py", line 774, in get
    raise self._value
KeyError: 40
multiprocessing.pool.RemoteTraceback: 
"""
Traceback (most recent call last):
  File "/home/gahan/anaconda3/envs/ligninsims/lib/python3.10/multiprocessing/pool.py", line 125, in worker
    result = (True, func(*args, **kwds))
  File "/home/gahan/anaconda3/envs/ligninsims/lib/python3.10/multiprocessing/pool.py", line 51, in starmapstar
    return list(itertools.starmap(args[0], args[1]))
  File "/home/gahan/may24/240524_allparametersopen/spruce_dellon/family_1/Generation_41/Run_2/Code/function_library.py", line 185, in generate_analysis_parallel
    nrings = np.sum([partial_dict_B[smiles_dictionary_id + k]["rings"] for k in range(partial_dict_A[bond_dictionary_id]['Bonds']["b1"]+1)])
  File "/home/gahan/may24/240524_allparametersopen/spruce_dellon/family_1/Generation_41/Run_2/Code/function_library.py", line 185, in <listcomp>
    nrings = np.sum([partial_dict_B[smiles_dictionary_id + k]["rings"] for k in range(partial_dict_A[bond_dictionary_id]['Bonds']["b1"]+1)])
KeyError: 46
"""

The above exception was the direct cause of the following exception:

Traceback (most recent call last):
  File "/home/gahan/may24/240524_allparametersopen/spruce_dellon/family_1/Generation_41/Run_2/Code/simulation_main.py", line 80, in <module>
    simulation_run_analysis(SG_ratio, simulation_time, monomer_addition_rate, minimum_num_monomers, maximum_num_monomers, rxn_rates, number_of_runs, filewriting, filepath)
  File "/home/gahan/may24/240524_allparametersopen/spruce_dellon/family_1/Generation_41/Run_2/Code/simulation_main.py", line 22, in simulation_run_analysis
    data_dictionary = generate_analysis(result, number_of_runs, num_cores=int(sys.argv[2]), file_writing=False, savefile_path=filepath)
  File "/home/gahan/may24/240524_allparametersopen/spruce_dellon/family_1/Generation_41/Run_2/Code/function_library.py", line 342, in generate_analysis
    lignin_libraries = pool.starmap(generate_analysis_parallel, [(cur_adjs[i], monolist[i], file_writing, savefile_path) for i, result in enumerate(results)])
  File "/home/gahan/anaconda3/envs/ligninsims/lib/python3.10/multiprocessing/pool.py", line 375, in starmap
    return self._map_async(func, iterable, starmapstar, chunksize).get()
  File "/home/gahan/anaconda3/envs/ligninsims/lib/python3.10/multiprocessing/pool.py", line 774, in get
    raise self._value
KeyError: 46
multiprocessing.pool.RemoteTraceback: 
"""
Traceback (most recent call last):
  File "/home/gahan/anaconda3/envs/ligninsims/lib/python3.10/multiprocessing/pool.py", line 125, in worker
    result = (True, func(*args, **kwds))
  File "/home/gahan/anaconda3/envs/ligninsims/lib/python3.10/multiprocessing/pool.py", line 51, in starmapstar
    return list(itertools.starmap(args[0], args[1]))
  File "/home/gahan/may24/240524_allparametersopen/spruce_dellon/family_1/Generation_44/Run_2/Code/function_library.py", line 201, in generate_analysis_parallel
    smiles = partial_dict_B[smiles_dictionary_id]["smilestring"]
KeyError: 56
"""

The above exception was the direct cause of the following exception:

Traceback (most recent call last):
  File "/home/gahan/may24/240524_allparametersopen/spruce_dellon/family_1/Generation_44/Run_2/Code/simulation_main.py", line 80, in <module>
    simulation_run_analysis(SG_ratio, simulation_time, monomer_addition_rate, minimum_num_monomers, maximum_num_monomers, rxn_rates, number_of_runs, filewriting, filepath)
  File "/home/gahan/may24/240524_allparametersopen/spruce_dellon/family_1/Generation_44/Run_2/Code/simulation_main.py", line 22, in simulation_run_analysis
    data_dictionary = generate_analysis(result, number_of_runs, num_cores=int(sys.argv[2]), file_writing=False, savefile_path=filepath)
  File "/home/gahan/may24/240524_allparametersopen/spruce_dellon/family_1/Generation_44/Run_2/Code/function_library.py", line 342, in generate_analysis
    lignin_libraries = pool.starmap(generate_analysis_parallel, [(cur_adjs[i], monolist[i], file_writing, savefile_path) for i, result in enumerate(results)])
  File "/home/gahan/anaconda3/envs/ligninsims/lib/python3.10/multiprocessing/pool.py", line 375, in starmap
    return self._map_async(func, iterable, starmapstar, chunksize).get()
  File "/home/gahan/anaconda3/envs/ligninsims/lib/python3.10/multiprocessing/pool.py", line 774, in get
    raise self._value
KeyError: 56
multiprocessing.pool.RemoteTraceback: 
"""
Traceback (most recent call last):
  File "/home/gahan/anaconda3/envs/ligninsims/lib/python3.10/multiprocessing/pool.py", line 125, in worker
    result = (True, func(*args, **kwds))
  File "/home/gahan/anaconda3/envs/ligninsims/lib/python3.10/multiprocessing/pool.py", line 51, in starmapstar
    return list(itertools.starmap(args[0], args[1]))
  File "/home/gahan/may24/240524_allparametersopen/spruce_dellon/family_1/Generation_44/Run_4/Code/function_library.py", line 201, in generate_analysis_parallel
    smiles = partial_dict_B[smiles_dictionary_id]["smilestring"]
KeyError: 44
"""

The above exception was the direct cause of the following exception:

Traceback (most recent call last):
  File "/home/gahan/may24/240524_allparametersopen/spruce_dellon/family_1/Generation_44/Run_4/Code/simulation_main.py", line 80, in <module>
    simulation_run_analysis(SG_ratio, simulation_time, monomer_addition_rate, minimum_num_monomers, maximum_num_monomers, rxn_rates, number_of_runs, filewriting, filepath)
  File "/home/gahan/may24/240524_allparametersopen/spruce_dellon/family_1/Generation_44/Run_4/Code/simulation_main.py", line 22, in simulation_run_analysis
    data_dictionary = generate_analysis(result, number_of_runs, num_cores=int(sys.argv[2]), file_writing=False, savefile_path=filepath)
  File "/home/gahan/may24/240524_allparametersopen/spruce_dellon/family_1/Generation_44/Run_4/Code/function_library.py", line 342, in generate_analysis
    lignin_libraries = pool.starmap(generate_analysis_parallel, [(cur_adjs[i], monolist[i], file_writing, savefile_path) for i, result in enumerate(results)])
  File "/home/gahan/anaconda3/envs/ligninsims/lib/python3.10/multiprocessing/pool.py", line 375, in starmap
    return self._map_async(func, iterable, starmapstar, chunksize).get()
  File "/home/gahan/anaconda3/envs/ligninsims/lib/python3.10/multiprocessing/pool.py", line 774, in get
    raise self._value
KeyError: 44
multiprocessing.pool.RemoteTraceback: 
"""
Traceback (most recent call last):
  File "/home/gahan/anaconda3/envs/ligninsims/lib/python3.10/multiprocessing/pool.py", line 125, in worker
    result = (True, func(*args, **kwds))
  File "/home/gahan/anaconda3/envs/ligninsims/lib/python3.10/multiprocessing/pool.py", line 51, in starmapstar
    return list(itertools.starmap(args[0], args[1]))
  File "/home/gahan/may24/240524_allparametersopen/spruce_dellon/family_1/Generation_45/Run_3/Code/function_library.py", line 185, in generate_analysis_parallel
    nrings = np.sum([partial_dict_B[smiles_dictionary_id + k]["rings"] for k in range(partial_dict_A[bond_dictionary_id]['Bonds']["b1"]+1)])
  File "/home/gahan/may24/240524_allparametersopen/spruce_dellon/family_1/Generation_45/Run_3/Code/function_library.py", line 185, in <listcomp>
    nrings = np.sum([partial_dict_B[smiles_dictionary_id + k]["rings"] for k in range(partial_dict_A[bond_dictionary_id]['Bonds']["b1"]+1)])
KeyError: 30
"""

The above exception was the direct cause of the following exception:

Traceback (most recent call last):
  File "/home/gahan/may24/240524_allparametersopen/spruce_dellon/family_1/Generation_45/Run_3/Code/simulation_main.py", line 80, in <module>
    simulation_run_analysis(SG_ratio, simulation_time, monomer_addition_rate, minimum_num_monomers, maximum_num_monomers, rxn_rates, number_of_runs, filewriting, filepath)
  File "/home/gahan/may24/240524_allparametersopen/spruce_dellon/family_1/Generation_45/Run_3/Code/simulation_main.py", line 22, in simulation_run_analysis
    data_dictionary = generate_analysis(result, number_of_runs, num_cores=int(sys.argv[2]), file_writing=False, savefile_path=filepath)
  File "/home/gahan/may24/240524_allparametersopen/spruce_dellon/family_1/Generation_45/Run_3/Code/function_library.py", line 342, in generate_analysis
    lignin_libraries = pool.starmap(generate_analysis_parallel, [(cur_adjs[i], monolist[i], file_writing, savefile_path) for i, result in enumerate(results)])
  File "/home/gahan/anaconda3/envs/ligninsims/lib/python3.10/multiprocessing/pool.py", line 375, in starmap
    return self._map_async(func, iterable, starmapstar, chunksize).get()
  File "/home/gahan/anaconda3/envs/ligninsims/lib/python3.10/multiprocessing/pool.py", line 774, in get
    raise self._value
KeyError: 30
multiprocessing.pool.RemoteTraceback: 
"""
Traceback (most recent call last):
  File "/home/gahan/anaconda3/envs/ligninsims/lib/python3.10/multiprocessing/pool.py", line 125, in worker
    result = (True, func(*args, **kwds))
  File "/home/gahan/anaconda3/envs/ligninsims/lib/python3.10/multiprocessing/pool.py", line 51, in starmapstar
    return list(itertools.starmap(args[0], args[1]))
  File "/home/gahan/may24/240524_allparametersopen/spruce_dellon/family_1/Generation_46/Run_1/Code/function_library.py", line 201, in generate_analysis_parallel
    smiles = partial_dict_B[smiles_dictionary_id]["smilestring"]
KeyError: 49
"""

The above exception was the direct cause of the following exception:

Traceback (most recent call last):
  File "/home/gahan/may24/240524_allparametersopen/spruce_dellon/family_1/Generation_46/Run_1/Code/simulation_main.py", line 80, in <module>
    simulation_run_analysis(SG_ratio, simulation_time, monomer_addition_rate, minimum_num_monomers, maximum_num_monomers, rxn_rates, number_of_runs, filewriting, filepath)
  File "/home/gahan/may24/240524_allparametersopen/spruce_dellon/family_1/Generation_46/Run_1/Code/simulation_main.py", line 22, in simulation_run_analysis
    data_dictionary = generate_analysis(result, number_of_runs, num_cores=int(sys.argv[2]), file_writing=False, savefile_path=filepath)
  File "/home/gahan/may24/240524_allparametersopen/spruce_dellon/family_1/Generation_46/Run_1/Code/function_library.py", line 342, in generate_analysis
    lignin_libraries = pool.starmap(generate_analysis_parallel, [(cur_adjs[i], monolist[i], file_writing, savefile_path) for i, result in enumerate(results)])
  File "/home/gahan/anaconda3/envs/ligninsims/lib/python3.10/multiprocessing/pool.py", line 375, in starmap
    return self._map_async(func, iterable, starmapstar, chunksize).get()
  File "/home/gahan/anaconda3/envs/ligninsims/lib/python3.10/multiprocessing/pool.py", line 774, in get
    raise self._value
KeyError: 49
multiprocessing.pool.RemoteTraceback: 
"""
Traceback (most recent call last):
  File "/home/gahan/anaconda3/envs/ligninsims/lib/python3.10/multiprocessing/pool.py", line 125, in worker
    result = (True, func(*args, **kwds))
  File "/home/gahan/anaconda3/envs/ligninsims/lib/python3.10/multiprocessing/pool.py", line 51, in starmapstar
    return list(itertools.starmap(args[0], args[1]))
  File "/home/gahan/may24/240524_allparametersopen/spruce_dellon/family_1/Generation_46/Run_3/Code/function_library.py", line 201, in generate_analysis_parallel
    smiles = partial_dict_B[smiles_dictionary_id]["smilestring"]
KeyError: 34
"""

The above exception was the direct cause of the following exception:

Traceback (most recent call last):
  File "/home/gahan/may24/240524_allparametersopen/spruce_dellon/family_1/Generation_46/Run_3/Code/simulation_main.py", line 80, in <module>
    simulation_run_analysis(SG_ratio, simulation_time, monomer_addition_rate, minimum_num_monomers, maximum_num_monomers, rxn_rates, number_of_runs, filewriting, filepath)
  File "/home/gahan/may24/240524_allparametersopen/spruce_dellon/family_1/Generation_46/Run_3/Code/simulation_main.py", line 22, in simulation_run_analysis
    data_dictionary = generate_analysis(result, number_of_runs, num_cores=int(sys.argv[2]), file_writing=False, savefile_path=filepath)
  File "/home/gahan/may24/240524_allparametersopen/spruce_dellon/family_1/Generation_46/Run_3/Code/function_library.py", line 342, in generate_analysis
    lignin_libraries = pool.starmap(generate_analysis_parallel, [(cur_adjs[i], monolist[i], file_writing, savefile_path) for i, result in enumerate(results)])
  File "/home/gahan/anaconda3/envs/ligninsims/lib/python3.10/multiprocessing/pool.py", line 375, in starmap
    return self._map_async(func, iterable, starmapstar, chunksize).get()
  File "/home/gahan/anaconda3/envs/ligninsims/lib/python3.10/multiprocessing/pool.py", line 774, in get
    raise self._value
KeyError: 34
multiprocessing.pool.RemoteTraceback: 
"""
Traceback (most recent call last):
  File "/home/gahan/anaconda3/envs/ligninsims/lib/python3.10/multiprocessing/pool.py", line 125, in worker
    result = (True, func(*args, **kwds))
  File "/home/gahan/anaconda3/envs/ligninsims/lib/python3.10/multiprocessing/pool.py", line 51, in starmapstar
    return list(itertools.starmap(args[0], args[1]))
  File "/home/gahan/may24/240524_allparametersopen/spruce_dellon/family_1/Generation_47/Run_3/Code/function_library.py", line 201, in generate_analysis_parallel
    smiles = partial_dict_B[smiles_dictionary_id]["smilestring"]
KeyError: 47
"""

The above exception was the direct cause of the following exception:

Traceback (most recent call last):
  File "/home/gahan/may24/240524_allparametersopen/spruce_dellon/family_1/Generation_47/Run_3/Code/simulation_main.py", line 80, in <module>
    simulation_run_analysis(SG_ratio, simulation_time, monomer_addition_rate, minimum_num_monomers, maximum_num_monomers, rxn_rates, number_of_runs, filewriting, filepath)
  File "/home/gahan/may24/240524_allparametersopen/spruce_dellon/family_1/Generation_47/Run_3/Code/simulation_main.py", line 22, in simulation_run_analysis
    data_dictionary = generate_analysis(result, number_of_runs, num_cores=int(sys.argv[2]), file_writing=False, savefile_path=filepath)
  File "/home/gahan/may24/240524_allparametersopen/spruce_dellon/family_1/Generation_47/Run_3/Code/function_library.py", line 342, in generate_analysis
    lignin_libraries = pool.starmap(generate_analysis_parallel, [(cur_adjs[i], monolist[i], file_writing, savefile_path) for i, result in enumerate(results)])
  File "/home/gahan/anaconda3/envs/ligninsims/lib/python3.10/multiprocessing/pool.py", line 375, in starmap
    return self._map_async(func, iterable, starmapstar, chunksize).get()
  File "/home/gahan/anaconda3/envs/ligninsims/lib/python3.10/multiprocessing/pool.py", line 774, in get
    raise self._value
KeyError: 47
multiprocessing.pool.RemoteTraceback: 
"""
Traceback (most recent call last):
  File "/home/gahan/anaconda3/envs/ligninsims/lib/python3.10/multiprocessing/pool.py", line 125, in worker
    result = (True, func(*args, **kwds))
  File "/home/gahan/anaconda3/envs/ligninsims/lib/python3.10/multiprocessing/pool.py", line 51, in starmapstar
    return list(itertools.starmap(args[0], args[1]))
  File "/home/gahan/may24/240524_allparametersopen/spruce_dellon/family_1/Generation_48/Run_4/Code/function_library.py", line 185, in generate_analysis_parallel
    nrings = np.sum([partial_dict_B[smiles_dictionary_id + k]["rings"] for k in range(partial_dict_A[bond_dictionary_id]['Bonds']["b1"]+1)])
  File "/home/gahan/may24/240524_allparametersopen/spruce_dellon/family_1/Generation_48/Run_4/Code/function_library.py", line 185, in <listcomp>
    nrings = np.sum([partial_dict_B[smiles_dictionary_id + k]["rings"] for k in range(partial_dict_A[bond_dictionary_id]['Bonds']["b1"]+1)])
KeyError: 34
"""

The above exception was the direct cause of the following exception:

Traceback (most recent call last):
  File "/home/gahan/may24/240524_allparametersopen/spruce_dellon/family_1/Generation_48/Run_4/Code/simulation_main.py", line 80, in <module>
    simulation_run_analysis(SG_ratio, simulation_time, monomer_addition_rate, minimum_num_monomers, maximum_num_monomers, rxn_rates, number_of_runs, filewriting, filepath)
  File "/home/gahan/may24/240524_allparametersopen/spruce_dellon/family_1/Generation_48/Run_4/Code/simulation_main.py", line 22, in simulation_run_analysis
    data_dictionary = generate_analysis(result, number_of_runs, num_cores=int(sys.argv[2]), file_writing=False, savefile_path=filepath)
  File "/home/gahan/may24/240524_allparametersopen/spruce_dellon/family_1/Generation_48/Run_4/Code/function_library.py", line 342, in generate_analysis
    lignin_libraries = pool.starmap(generate_analysis_parallel, [(cur_adjs[i], monolist[i], file_writing, savefile_path) for i, result in enumerate(results)])
  File "/home/gahan/anaconda3/envs/ligninsims/lib/python3.10/multiprocessing/pool.py", line 375, in starmap
    return self._map_async(func, iterable, starmapstar, chunksize).get()
  File "/home/gahan/anaconda3/envs/ligninsims/lib/python3.10/multiprocessing/pool.py", line 774, in get
    raise self._value
KeyError: 34
multiprocessing.pool.RemoteTraceback: 
"""
Traceback (most recent call last):
  File "/home/gahan/anaconda3/envs/ligninsims/lib/python3.10/multiprocessing/pool.py", line 125, in worker
    result = (True, func(*args, **kwds))
  File "/home/gahan/anaconda3/envs/ligninsims/lib/python3.10/multiprocessing/pool.py", line 51, in starmapstar
    return list(itertools.starmap(args[0], args[1]))
  File "/home/gahan/may24/240524_allparametersopen/spruce_dellon/family_1/Generation_49/Run_1/Code/function_library.py", line 201, in generate_analysis_parallel
    smiles = partial_dict_B[smiles_dictionary_id]["smilestring"]
KeyError: 42
"""

The above exception was the direct cause of the following exception:

Traceback (most recent call last):
  File "/home/gahan/may24/240524_allparametersopen/spruce_dellon/family_1/Generation_49/Run_1/Code/simulation_main.py", line 80, in <module>
    simulation_run_analysis(SG_ratio, simulation_time, monomer_addition_rate, minimum_num_monomers, maximum_num_monomers, rxn_rates, number_of_runs, filewriting, filepath)
  File "/home/gahan/may24/240524_allparametersopen/spruce_dellon/family_1/Generation_49/Run_1/Code/simulation_main.py", line 22, in simulation_run_analysis
    data_dictionary = generate_analysis(result, number_of_runs, num_cores=int(sys.argv[2]), file_writing=False, savefile_path=filepath)
  File "/home/gahan/may24/240524_allparametersopen/spruce_dellon/family_1/Generation_49/Run_1/Code/function_library.py", line 342, in generate_analysis
    lignin_libraries = pool.starmap(generate_analysis_parallel, [(cur_adjs[i], monolist[i], file_writing, savefile_path) for i, result in enumerate(results)])
  File "/home/gahan/anaconda3/envs/ligninsims/lib/python3.10/multiprocessing/pool.py", line 375, in starmap
    return self._map_async(func, iterable, starmapstar, chunksize).get()
  File "/home/gahan/anaconda3/envs/ligninsims/lib/python3.10/multiprocessing/pool.py", line 774, in get
    raise self._value
KeyError: 42
multiprocessing.pool.RemoteTraceback: 
"""
Traceback (most recent call last):
  File "/home/gahan/anaconda3/envs/ligninsims/lib/python3.10/multiprocessing/pool.py", line 125, in worker
    result = (True, func(*args, **kwds))
  File "/home/gahan/anaconda3/envs/ligninsims/lib/python3.10/multiprocessing/pool.py", line 51, in starmapstar
    return list(itertools.starmap(args[0], args[1]))
  File "/home/gahan/may24/240524_allparametersopen/spruce_dellon/family_1/Generation_49/Run_4/Code/function_library.py", line 201, in generate_analysis_parallel
    smiles = partial_dict_B[smiles_dictionary_id]["smilestring"]
KeyError: 55
"""

The above exception was the direct cause of the following exception:

Traceback (most recent call last):
  File "/home/gahan/may24/240524_allparametersopen/spruce_dellon/family_1/Generation_49/Run_4/Code/simulation_main.py", line 80, in <module>
    simulation_run_analysis(SG_ratio, simulation_time, monomer_addition_rate, minimum_num_monomers, maximum_num_monomers, rxn_rates, number_of_runs, filewriting, filepath)
  File "/home/gahan/may24/240524_allparametersopen/spruce_dellon/family_1/Generation_49/Run_4/Code/simulation_main.py", line 22, in simulation_run_analysis
    data_dictionary = generate_analysis(result, number_of_runs, num_cores=int(sys.argv[2]), file_writing=False, savefile_path=filepath)
  File "/home/gahan/may24/240524_allparametersopen/spruce_dellon/family_1/Generation_49/Run_4/Code/function_library.py", line 342, in generate_analysis
    lignin_libraries = pool.starmap(generate_analysis_parallel, [(cur_adjs[i], monolist[i], file_writing, savefile_path) for i, result in enumerate(results)])
  File "/home/gahan/anaconda3/envs/ligninsims/lib/python3.10/multiprocessing/pool.py", line 375, in starmap
    return self._map_async(func, iterable, starmapstar, chunksize).get()
  File "/home/gahan/anaconda3/envs/ligninsims/lib/python3.10/multiprocessing/pool.py", line 774, in get
    raise self._value
KeyError: 55
rm: das Entfernen von 'Gridsearch/Run*' ist nicht möglich: Datei oder Verzeichnis nicht gefunden
multiprocessing.pool.RemoteTraceback: 
"""
Traceback (most recent call last):
  File "/home/gahan/anaconda3/envs/ligninsims/lib/python3.10/multiprocessing/pool.py", line 125, in worker
    result = (True, func(*args, **kwds))
  File "/home/gahan/anaconda3/envs/ligninsims/lib/python3.10/multiprocessing/pool.py", line 51, in starmapstar
    return list(itertools.starmap(args[0], args[1]))
  File "/home/gahan/may24/240524_allparametersopen/spruce_dellon/BEST_FIT/best_Run/Code/function_library.py", line 185, in generate_analysis_parallel
    nrings = np.sum([partial_dict_B[smiles_dictionary_id + k]["rings"] for k in range(partial_dict_A[bond_dictionary_id]['Bonds']["b1"]+1)])
  File "/home/gahan/may24/240524_allparametersopen/spruce_dellon/BEST_FIT/best_Run/Code/function_library.py", line 185, in <listcomp>
    nrings = np.sum([partial_dict_B[smiles_dictionary_id + k]["rings"] for k in range(partial_dict_A[bond_dictionary_id]['Bonds']["b1"]+1)])
KeyError: 37
"""

The above exception was the direct cause of the following exception:

Traceback (most recent call last):
  File "/home/gahan/may24/240524_allparametersopen/spruce_dellon/BEST_FIT/best_Run/Code/simulation_main.py", line 80, in <module>
    simulation_run_analysis(SG_ratio, simulation_time, monomer_addition_rate, minimum_num_monomers, maximum_num_monomers, rxn_rates, number_of_runs, filewriting, filepath)
  File "/home/gahan/may24/240524_allparametersopen/spruce_dellon/BEST_FIT/best_Run/Code/simulation_main.py", line 22, in simulation_run_analysis
    data_dictionary = generate_analysis(result, number_of_runs, num_cores=int(sys.argv[2]), file_writing=False, savefile_path=filepath)
  File "/home/gahan/may24/240524_allparametersopen/spruce_dellon/BEST_FIT/best_Run/Code/function_library.py", line 342, in generate_analysis
    lignin_libraries = pool.starmap(generate_analysis_parallel, [(cur_adjs[i], monolist[i], file_writing, savefile_path) for i, result in enumerate(results)])
  File "/home/gahan/anaconda3/envs/ligninsims/lib/python3.10/multiprocessing/pool.py", line 375, in starmap
    return self._map_async(func, iterable, starmapstar, chunksize).get()
  File "/home/gahan/anaconda3/envs/ligninsims/lib/python3.10/multiprocessing/pool.py", line 774, in get
    raise self._value
KeyError: 37
