multiprocessing.pool.RemoteTraceback: 
"""
Traceback (most recent call last):
  File "/home/gahan/anaconda3/envs/ligninsims/lib/python3.10/multiprocessing/pool.py", line 125, in worker
    result = (True, func(*args, **kwds))
  File "/home/gahan/anaconda3/envs/ligninsims/lib/python3.10/multiprocessing/pool.py", line 51, in starmapstar
    return list(itertools.starmap(args[0], args[1]))
  File "/home/gahan/may24/240524_allparametersopen/birch_dellon/family_1/Generation_32/Run_3/Code/function_library.py", line 201, in generate_analysis_parallel
    smiles = partial_dict_B[smiles_dictionary_id]["smilestring"]
KeyError: 57
"""

The above exception was the direct cause of the following exception:

Traceback (most recent call last):
  File "/home/gahan/may24/240524_allparametersopen/birch_dellon/family_1/Generation_32/Run_3/Code/simulation_main.py", line 80, in <module>
    simulation_run_analysis(SG_ratio, simulation_time, monomer_addition_rate, minimum_num_monomers, maximum_num_monomers, rxn_rates, number_of_runs, filewriting, filepath)
  File "/home/gahan/may24/240524_allparametersopen/birch_dellon/family_1/Generation_32/Run_3/Code/simulation_main.py", line 22, in simulation_run_analysis
    data_dictionary = generate_analysis(result, number_of_runs, num_cores=int(sys.argv[2]), file_writing=False, savefile_path=filepath)
  File "/home/gahan/may24/240524_allparametersopen/birch_dellon/family_1/Generation_32/Run_3/Code/function_library.py", line 342, in generate_analysis
    lignin_libraries = pool.starmap(generate_analysis_parallel, [(cur_adjs[i], monolist[i], file_writing, savefile_path) for i, result in enumerate(results)])
  File "/home/gahan/anaconda3/envs/ligninsims/lib/python3.10/multiprocessing/pool.py", line 375, in starmap
    return self._map_async(func, iterable, starmapstar, chunksize).get()
  File "/home/gahan/anaconda3/envs/ligninsims/lib/python3.10/multiprocessing/pool.py", line 774, in get
    raise self._value
KeyError: 57
multiprocessing.pool.RemoteTraceback: 
"""
Traceback (most recent call last):
  File "/home/gahan/anaconda3/envs/ligninsims/lib/python3.10/multiprocessing/pool.py", line 125, in worker
    result = (True, func(*args, **kwds))
  File "/home/gahan/anaconda3/envs/ligninsims/lib/python3.10/multiprocessing/pool.py", line 51, in starmapstar
    return list(itertools.starmap(args[0], args[1]))
  File "/home/gahan/may24/240524_allparametersopen/birch_dellon/family_1/Generation_33/Run_2/Code/function_library.py", line 185, in generate_analysis_parallel
    nrings = np.sum([partial_dict_B[smiles_dictionary_id + k]["rings"] for k in range(partial_dict_A[bond_dictionary_id]['Bonds']["b1"]+1)])
  File "/home/gahan/may24/240524_allparametersopen/birch_dellon/family_1/Generation_33/Run_2/Code/function_library.py", line 185, in <listcomp>
    nrings = np.sum([partial_dict_B[smiles_dictionary_id + k]["rings"] for k in range(partial_dict_A[bond_dictionary_id]['Bonds']["b1"]+1)])
KeyError: 52
"""

The above exception was the direct cause of the following exception:

Traceback (most recent call last):
  File "/home/gahan/may24/240524_allparametersopen/birch_dellon/family_1/Generation_33/Run_2/Code/simulation_main.py", line 80, in <module>
    simulation_run_analysis(SG_ratio, simulation_time, monomer_addition_rate, minimum_num_monomers, maximum_num_monomers, rxn_rates, number_of_runs, filewriting, filepath)
  File "/home/gahan/may24/240524_allparametersopen/birch_dellon/family_1/Generation_33/Run_2/Code/simulation_main.py", line 22, in simulation_run_analysis
    data_dictionary = generate_analysis(result, number_of_runs, num_cores=int(sys.argv[2]), file_writing=False, savefile_path=filepath)
  File "/home/gahan/may24/240524_allparametersopen/birch_dellon/family_1/Generation_33/Run_2/Code/function_library.py", line 342, in generate_analysis
    lignin_libraries = pool.starmap(generate_analysis_parallel, [(cur_adjs[i], monolist[i], file_writing, savefile_path) for i, result in enumerate(results)])
  File "/home/gahan/anaconda3/envs/ligninsims/lib/python3.10/multiprocessing/pool.py", line 375, in starmap
    return self._map_async(func, iterable, starmapstar, chunksize).get()
  File "/home/gahan/anaconda3/envs/ligninsims/lib/python3.10/multiprocessing/pool.py", line 774, in get
    raise self._value
KeyError: 52
multiprocessing.pool.RemoteTraceback: 
"""
Traceback (most recent call last):
  File "/home/gahan/anaconda3/envs/ligninsims/lib/python3.10/multiprocessing/pool.py", line 125, in worker
    result = (True, func(*args, **kwds))
  File "/home/gahan/anaconda3/envs/ligninsims/lib/python3.10/multiprocessing/pool.py", line 51, in starmapstar
    return list(itertools.starmap(args[0], args[1]))
  File "/home/gahan/may24/240524_allparametersopen/birch_dellon/family_1/Generation_34/Run_1/Code/function_library.py", line 201, in generate_analysis_parallel
    smiles = partial_dict_B[smiles_dictionary_id]["smilestring"]
KeyError: 20
"""

The above exception was the direct cause of the following exception:

Traceback (most recent call last):
  File "/home/gahan/may24/240524_allparametersopen/birch_dellon/family_1/Generation_34/Run_1/Code/simulation_main.py", line 80, in <module>
    simulation_run_analysis(SG_ratio, simulation_time, monomer_addition_rate, minimum_num_monomers, maximum_num_monomers, rxn_rates, number_of_runs, filewriting, filepath)
  File "/home/gahan/may24/240524_allparametersopen/birch_dellon/family_1/Generation_34/Run_1/Code/simulation_main.py", line 22, in simulation_run_analysis
    data_dictionary = generate_analysis(result, number_of_runs, num_cores=int(sys.argv[2]), file_writing=False, savefile_path=filepath)
  File "/home/gahan/may24/240524_allparametersopen/birch_dellon/family_1/Generation_34/Run_1/Code/function_library.py", line 342, in generate_analysis
    lignin_libraries = pool.starmap(generate_analysis_parallel, [(cur_adjs[i], monolist[i], file_writing, savefile_path) for i, result in enumerate(results)])
  File "/home/gahan/anaconda3/envs/ligninsims/lib/python3.10/multiprocessing/pool.py", line 375, in starmap
    return self._map_async(func, iterable, starmapstar, chunksize).get()
  File "/home/gahan/anaconda3/envs/ligninsims/lib/python3.10/multiprocessing/pool.py", line 774, in get
    raise self._value
KeyError: 20
multiprocessing.pool.RemoteTraceback: 
"""
Traceback (most recent call last):
  File "/home/gahan/anaconda3/envs/ligninsims/lib/python3.10/multiprocessing/pool.py", line 125, in worker
    result = (True, func(*args, **kwds))
  File "/home/gahan/anaconda3/envs/ligninsims/lib/python3.10/multiprocessing/pool.py", line 51, in starmapstar
    return list(itertools.starmap(args[0], args[1]))
  File "/home/gahan/may24/240524_allparametersopen/birch_dellon/family_1/Generation_36/Run_3/Code/function_library.py", line 201, in generate_analysis_parallel
    smiles = partial_dict_B[smiles_dictionary_id]["smilestring"]
KeyError: 24
"""

The above exception was the direct cause of the following exception:

Traceback (most recent call last):
  File "/home/gahan/may24/240524_allparametersopen/birch_dellon/family_1/Generation_36/Run_3/Code/simulation_main.py", line 80, in <module>
    simulation_run_analysis(SG_ratio, simulation_time, monomer_addition_rate, minimum_num_monomers, maximum_num_monomers, rxn_rates, number_of_runs, filewriting, filepath)
  File "/home/gahan/may24/240524_allparametersopen/birch_dellon/family_1/Generation_36/Run_3/Code/simulation_main.py", line 22, in simulation_run_analysis
    data_dictionary = generate_analysis(result, number_of_runs, num_cores=int(sys.argv[2]), file_writing=False, savefile_path=filepath)
  File "/home/gahan/may24/240524_allparametersopen/birch_dellon/family_1/Generation_36/Run_3/Code/function_library.py", line 342, in generate_analysis
    lignin_libraries = pool.starmap(generate_analysis_parallel, [(cur_adjs[i], monolist[i], file_writing, savefile_path) for i, result in enumerate(results)])
  File "/home/gahan/anaconda3/envs/ligninsims/lib/python3.10/multiprocessing/pool.py", line 375, in starmap
    return self._map_async(func, iterable, starmapstar, chunksize).get()
  File "/home/gahan/anaconda3/envs/ligninsims/lib/python3.10/multiprocessing/pool.py", line 774, in get
    raise self._value
KeyError: 24
multiprocessing.pool.RemoteTraceback: 
"""
Traceback (most recent call last):
  File "/home/gahan/anaconda3/envs/ligninsims/lib/python3.10/multiprocessing/pool.py", line 125, in worker
    result = (True, func(*args, **kwds))
  File "/home/gahan/anaconda3/envs/ligninsims/lib/python3.10/multiprocessing/pool.py", line 51, in starmapstar
    return list(itertools.starmap(args[0], args[1]))
  File "/home/gahan/may24/240524_allparametersopen/birch_dellon/family_1/Generation_37/Run_2/Code/function_library.py", line 201, in generate_analysis_parallel
    smiles = partial_dict_B[smiles_dictionary_id]["smilestring"]
KeyError: 39
"""

The above exception was the direct cause of the following exception:

Traceback (most recent call last):
  File "/home/gahan/may24/240524_allparametersopen/birch_dellon/family_1/Generation_37/Run_2/Code/simulation_main.py", line 80, in <module>
    simulation_run_analysis(SG_ratio, simulation_time, monomer_addition_rate, minimum_num_monomers, maximum_num_monomers, rxn_rates, number_of_runs, filewriting, filepath)
  File "/home/gahan/may24/240524_allparametersopen/birch_dellon/family_1/Generation_37/Run_2/Code/simulation_main.py", line 22, in simulation_run_analysis
    data_dictionary = generate_analysis(result, number_of_runs, num_cores=int(sys.argv[2]), file_writing=False, savefile_path=filepath)
  File "/home/gahan/may24/240524_allparametersopen/birch_dellon/family_1/Generation_37/Run_2/Code/function_library.py", line 342, in generate_analysis
    lignin_libraries = pool.starmap(generate_analysis_parallel, [(cur_adjs[i], monolist[i], file_writing, savefile_path) for i, result in enumerate(results)])
  File "/home/gahan/anaconda3/envs/ligninsims/lib/python3.10/multiprocessing/pool.py", line 375, in starmap
    return self._map_async(func, iterable, starmapstar, chunksize).get()
  File "/home/gahan/anaconda3/envs/ligninsims/lib/python3.10/multiprocessing/pool.py", line 774, in get
    raise self._value
KeyError: 39
multiprocessing.pool.RemoteTraceback: 
"""
Traceback (most recent call last):
  File "/home/gahan/anaconda3/envs/ligninsims/lib/python3.10/multiprocessing/pool.py", line 125, in worker
    result = (True, func(*args, **kwds))
  File "/home/gahan/anaconda3/envs/ligninsims/lib/python3.10/multiprocessing/pool.py", line 51, in starmapstar
    return list(itertools.starmap(args[0], args[1]))
  File "/home/gahan/may24/240524_allparametersopen/birch_dellon/family_1/Generation_37/Run_3/Code/function_library.py", line 201, in generate_analysis_parallel
    smiles = partial_dict_B[smiles_dictionary_id]["smilestring"]
KeyError: 33
"""

The above exception was the direct cause of the following exception:

Traceback (most recent call last):
  File "/home/gahan/may24/240524_allparametersopen/birch_dellon/family_1/Generation_37/Run_3/Code/simulation_main.py", line 80, in <module>
    simulation_run_analysis(SG_ratio, simulation_time, monomer_addition_rate, minimum_num_monomers, maximum_num_monomers, rxn_rates, number_of_runs, filewriting, filepath)
  File "/home/gahan/may24/240524_allparametersopen/birch_dellon/family_1/Generation_37/Run_3/Code/simulation_main.py", line 22, in simulation_run_analysis
    data_dictionary = generate_analysis(result, number_of_runs, num_cores=int(sys.argv[2]), file_writing=False, savefile_path=filepath)
  File "/home/gahan/may24/240524_allparametersopen/birch_dellon/family_1/Generation_37/Run_3/Code/function_library.py", line 342, in generate_analysis
    lignin_libraries = pool.starmap(generate_analysis_parallel, [(cur_adjs[i], monolist[i], file_writing, savefile_path) for i, result in enumerate(results)])
  File "/home/gahan/anaconda3/envs/ligninsims/lib/python3.10/multiprocessing/pool.py", line 375, in starmap
    return self._map_async(func, iterable, starmapstar, chunksize).get()
  File "/home/gahan/anaconda3/envs/ligninsims/lib/python3.10/multiprocessing/pool.py", line 774, in get
    raise self._value
KeyError: 33
multiprocessing.pool.RemoteTraceback: 
"""
Traceback (most recent call last):
  File "/home/gahan/anaconda3/envs/ligninsims/lib/python3.10/multiprocessing/pool.py", line 125, in worker
    result = (True, func(*args, **kwds))
  File "/home/gahan/anaconda3/envs/ligninsims/lib/python3.10/multiprocessing/pool.py", line 51, in starmapstar
    return list(itertools.starmap(args[0], args[1]))
  File "/home/gahan/may24/240524_allparametersopen/birch_dellon/family_1/Generation_38/Run_2/Code/function_library.py", line 201, in generate_analysis_parallel
    smiles = partial_dict_B[smiles_dictionary_id]["smilestring"]
KeyError: 47
"""

The above exception was the direct cause of the following exception:

Traceback (most recent call last):
  File "/home/gahan/may24/240524_allparametersopen/birch_dellon/family_1/Generation_38/Run_2/Code/simulation_main.py", line 80, in <module>
    simulation_run_analysis(SG_ratio, simulation_time, monomer_addition_rate, minimum_num_monomers, maximum_num_monomers, rxn_rates, number_of_runs, filewriting, filepath)
  File "/home/gahan/may24/240524_allparametersopen/birch_dellon/family_1/Generation_38/Run_2/Code/simulation_main.py", line 22, in simulation_run_analysis
    data_dictionary = generate_analysis(result, number_of_runs, num_cores=int(sys.argv[2]), file_writing=False, savefile_path=filepath)
  File "/home/gahan/may24/240524_allparametersopen/birch_dellon/family_1/Generation_38/Run_2/Code/function_library.py", line 342, in generate_analysis
    lignin_libraries = pool.starmap(generate_analysis_parallel, [(cur_adjs[i], monolist[i], file_writing, savefile_path) for i, result in enumerate(results)])
  File "/home/gahan/anaconda3/envs/ligninsims/lib/python3.10/multiprocessing/pool.py", line 375, in starmap
    return self._map_async(func, iterable, starmapstar, chunksize).get()
  File "/home/gahan/anaconda3/envs/ligninsims/lib/python3.10/multiprocessing/pool.py", line 774, in get
    raise self._value
KeyError: 47
multiprocessing.pool.RemoteTraceback: 
"""
Traceback (most recent call last):
  File "/home/gahan/anaconda3/envs/ligninsims/lib/python3.10/multiprocessing/pool.py", line 125, in worker
    result = (True, func(*args, **kwds))
  File "/home/gahan/anaconda3/envs/ligninsims/lib/python3.10/multiprocessing/pool.py", line 51, in starmapstar
    return list(itertools.starmap(args[0], args[1]))
  File "/home/gahan/may24/240524_allparametersopen/birch_dellon/family_1/Generation_38/Run_3/Code/function_library.py", line 201, in generate_analysis_parallel
    smiles = partial_dict_B[smiles_dictionary_id]["smilestring"]
KeyError: 42
"""

The above exception was the direct cause of the following exception:

Traceback (most recent call last):
  File "/home/gahan/may24/240524_allparametersopen/birch_dellon/family_1/Generation_38/Run_3/Code/simulation_main.py", line 80, in <module>
    simulation_run_analysis(SG_ratio, simulation_time, monomer_addition_rate, minimum_num_monomers, maximum_num_monomers, rxn_rates, number_of_runs, filewriting, filepath)
  File "/home/gahan/may24/240524_allparametersopen/birch_dellon/family_1/Generation_38/Run_3/Code/simulation_main.py", line 22, in simulation_run_analysis
    data_dictionary = generate_analysis(result, number_of_runs, num_cores=int(sys.argv[2]), file_writing=False, savefile_path=filepath)
  File "/home/gahan/may24/240524_allparametersopen/birch_dellon/family_1/Generation_38/Run_3/Code/function_library.py", line 342, in generate_analysis
    lignin_libraries = pool.starmap(generate_analysis_parallel, [(cur_adjs[i], monolist[i], file_writing, savefile_path) for i, result in enumerate(results)])
  File "/home/gahan/anaconda3/envs/ligninsims/lib/python3.10/multiprocessing/pool.py", line 375, in starmap
    return self._map_async(func, iterable, starmapstar, chunksize).get()
  File "/home/gahan/anaconda3/envs/ligninsims/lib/python3.10/multiprocessing/pool.py", line 774, in get
    raise self._value
KeyError: 42
multiprocessing.pool.RemoteTraceback: 
"""
Traceback (most recent call last):
  File "/home/gahan/anaconda3/envs/ligninsims/lib/python3.10/multiprocessing/pool.py", line 125, in worker
    result = (True, func(*args, **kwds))
  File "/home/gahan/anaconda3/envs/ligninsims/lib/python3.10/multiprocessing/pool.py", line 51, in starmapstar
    return list(itertools.starmap(args[0], args[1]))
  File "/home/gahan/may24/240524_allparametersopen/birch_dellon/family_1/Generation_39/Run_1/Code/function_library.py", line 201, in generate_analysis_parallel
    smiles = partial_dict_B[smiles_dictionary_id]["smilestring"]
KeyError: 37
"""

The above exception was the direct cause of the following exception:

Traceback (most recent call last):
  File "/home/gahan/may24/240524_allparametersopen/birch_dellon/family_1/Generation_39/Run_1/Code/simulation_main.py", line 80, in <module>
    simulation_run_analysis(SG_ratio, simulation_time, monomer_addition_rate, minimum_num_monomers, maximum_num_monomers, rxn_rates, number_of_runs, filewriting, filepath)
  File "/home/gahan/may24/240524_allparametersopen/birch_dellon/family_1/Generation_39/Run_1/Code/simulation_main.py", line 22, in simulation_run_analysis
    data_dictionary = generate_analysis(result, number_of_runs, num_cores=int(sys.argv[2]), file_writing=False, savefile_path=filepath)
  File "/home/gahan/may24/240524_allparametersopen/birch_dellon/family_1/Generation_39/Run_1/Code/function_library.py", line 342, in generate_analysis
    lignin_libraries = pool.starmap(generate_analysis_parallel, [(cur_adjs[i], monolist[i], file_writing, savefile_path) for i, result in enumerate(results)])
  File "/home/gahan/anaconda3/envs/ligninsims/lib/python3.10/multiprocessing/pool.py", line 375, in starmap
    return self._map_async(func, iterable, starmapstar, chunksize).get()
  File "/home/gahan/anaconda3/envs/ligninsims/lib/python3.10/multiprocessing/pool.py", line 774, in get
    raise self._value
KeyError: 37
multiprocessing.pool.RemoteTraceback: 
"""
Traceback (most recent call last):
  File "/home/gahan/anaconda3/envs/ligninsims/lib/python3.10/multiprocessing/pool.py", line 125, in worker
    result = (True, func(*args, **kwds))
  File "/home/gahan/anaconda3/envs/ligninsims/lib/python3.10/multiprocessing/pool.py", line 51, in starmapstar
    return list(itertools.starmap(args[0], args[1]))
  File "/home/gahan/may24/240524_allparametersopen/birch_dellon/family_1/Generation_39/Run_4/Code/function_library.py", line 201, in generate_analysis_parallel
    smiles = partial_dict_B[smiles_dictionary_id]["smilestring"]
KeyError: 23
"""

The above exception was the direct cause of the following exception:

Traceback (most recent call last):
  File "/home/gahan/may24/240524_allparametersopen/birch_dellon/family_1/Generation_39/Run_4/Code/simulation_main.py", line 80, in <module>
    simulation_run_analysis(SG_ratio, simulation_time, monomer_addition_rate, minimum_num_monomers, maximum_num_monomers, rxn_rates, number_of_runs, filewriting, filepath)
  File "/home/gahan/may24/240524_allparametersopen/birch_dellon/family_1/Generation_39/Run_4/Code/simulation_main.py", line 22, in simulation_run_analysis
    data_dictionary = generate_analysis(result, number_of_runs, num_cores=int(sys.argv[2]), file_writing=False, savefile_path=filepath)
  File "/home/gahan/may24/240524_allparametersopen/birch_dellon/family_1/Generation_39/Run_4/Code/function_library.py", line 342, in generate_analysis
    lignin_libraries = pool.starmap(generate_analysis_parallel, [(cur_adjs[i], monolist[i], file_writing, savefile_path) for i, result in enumerate(results)])
  File "/home/gahan/anaconda3/envs/ligninsims/lib/python3.10/multiprocessing/pool.py", line 375, in starmap
    return self._map_async(func, iterable, starmapstar, chunksize).get()
  File "/home/gahan/anaconda3/envs/ligninsims/lib/python3.10/multiprocessing/pool.py", line 774, in get
    raise self._value
KeyError: 23
multiprocessing.pool.RemoteTraceback: 
"""
Traceback (most recent call last):
  File "/home/gahan/anaconda3/envs/ligninsims/lib/python3.10/multiprocessing/pool.py", line 125, in worker
    result = (True, func(*args, **kwds))
  File "/home/gahan/anaconda3/envs/ligninsims/lib/python3.10/multiprocessing/pool.py", line 51, in starmapstar
    return list(itertools.starmap(args[0], args[1]))
  File "/home/gahan/may24/240524_allparametersopen/birch_dellon/family_1/Generation_40/Run_1/Code/function_library.py", line 201, in generate_analysis_parallel
    smiles = partial_dict_B[smiles_dictionary_id]["smilestring"]
KeyError: 32
"""

The above exception was the direct cause of the following exception:

Traceback (most recent call last):
  File "/home/gahan/may24/240524_allparametersopen/birch_dellon/family_1/Generation_40/Run_1/Code/simulation_main.py", line 80, in <module>
    simulation_run_analysis(SG_ratio, simulation_time, monomer_addition_rate, minimum_num_monomers, maximum_num_monomers, rxn_rates, number_of_runs, filewriting, filepath)
  File "/home/gahan/may24/240524_allparametersopen/birch_dellon/family_1/Generation_40/Run_1/Code/simulation_main.py", line 22, in simulation_run_analysis
    data_dictionary = generate_analysis(result, number_of_runs, num_cores=int(sys.argv[2]), file_writing=False, savefile_path=filepath)
  File "/home/gahan/may24/240524_allparametersopen/birch_dellon/family_1/Generation_40/Run_1/Code/function_library.py", line 342, in generate_analysis
    lignin_libraries = pool.starmap(generate_analysis_parallel, [(cur_adjs[i], monolist[i], file_writing, savefile_path) for i, result in enumerate(results)])
  File "/home/gahan/anaconda3/envs/ligninsims/lib/python3.10/multiprocessing/pool.py", line 375, in starmap
    return self._map_async(func, iterable, starmapstar, chunksize).get()
  File "/home/gahan/anaconda3/envs/ligninsims/lib/python3.10/multiprocessing/pool.py", line 774, in get
    raise self._value
KeyError: 32
multiprocessing.pool.RemoteTraceback: 
"""
Traceback (most recent call last):
  File "/home/gahan/anaconda3/envs/ligninsims/lib/python3.10/multiprocessing/pool.py", line 125, in worker
    result = (True, func(*args, **kwds))
  File "/home/gahan/anaconda3/envs/ligninsims/lib/python3.10/multiprocessing/pool.py", line 51, in starmapstar
    return list(itertools.starmap(args[0], args[1]))
  File "/home/gahan/may24/240524_allparametersopen/birch_dellon/family_1/Generation_40/Run_2/Code/function_library.py", line 201, in generate_analysis_parallel
    smiles = partial_dict_B[smiles_dictionary_id]["smilestring"]
KeyError: 15
"""

The above exception was the direct cause of the following exception:

Traceback (most recent call last):
  File "/home/gahan/may24/240524_allparametersopen/birch_dellon/family_1/Generation_40/Run_2/Code/simulation_main.py", line 80, in <module>
    simulation_run_analysis(SG_ratio, simulation_time, monomer_addition_rate, minimum_num_monomers, maximum_num_monomers, rxn_rates, number_of_runs, filewriting, filepath)
  File "/home/gahan/may24/240524_allparametersopen/birch_dellon/family_1/Generation_40/Run_2/Code/simulation_main.py", line 22, in simulation_run_analysis
    data_dictionary = generate_analysis(result, number_of_runs, num_cores=int(sys.argv[2]), file_writing=False, savefile_path=filepath)
  File "/home/gahan/may24/240524_allparametersopen/birch_dellon/family_1/Generation_40/Run_2/Code/function_library.py", line 342, in generate_analysis
    lignin_libraries = pool.starmap(generate_analysis_parallel, [(cur_adjs[i], monolist[i], file_writing, savefile_path) for i, result in enumerate(results)])
  File "/home/gahan/anaconda3/envs/ligninsims/lib/python3.10/multiprocessing/pool.py", line 375, in starmap
    return self._map_async(func, iterable, starmapstar, chunksize).get()
  File "/home/gahan/anaconda3/envs/ligninsims/lib/python3.10/multiprocessing/pool.py", line 774, in get
    raise self._value
KeyError: 15
multiprocessing.pool.RemoteTraceback: 
"""
Traceback (most recent call last):
  File "/home/gahan/anaconda3/envs/ligninsims/lib/python3.10/multiprocessing/pool.py", line 125, in worker
    result = (True, func(*args, **kwds))
  File "/home/gahan/anaconda3/envs/ligninsims/lib/python3.10/multiprocessing/pool.py", line 51, in starmapstar
    return list(itertools.starmap(args[0], args[1]))
  File "/home/gahan/may24/240524_allparametersopen/birch_dellon/family_1/Generation_41/Run_3/Code/function_library.py", line 201, in generate_analysis_parallel
    smiles = partial_dict_B[smiles_dictionary_id]["smilestring"]
KeyError: 19
"""

The above exception was the direct cause of the following exception:

Traceback (most recent call last):
  File "/home/gahan/may24/240524_allparametersopen/birch_dellon/family_1/Generation_41/Run_3/Code/simulation_main.py", line 80, in <module>
    simulation_run_analysis(SG_ratio, simulation_time, monomer_addition_rate, minimum_num_monomers, maximum_num_monomers, rxn_rates, number_of_runs, filewriting, filepath)
  File "/home/gahan/may24/240524_allparametersopen/birch_dellon/family_1/Generation_41/Run_3/Code/simulation_main.py", line 22, in simulation_run_analysis
    data_dictionary = generate_analysis(result, number_of_runs, num_cores=int(sys.argv[2]), file_writing=False, savefile_path=filepath)
  File "/home/gahan/may24/240524_allparametersopen/birch_dellon/family_1/Generation_41/Run_3/Code/function_library.py", line 342, in generate_analysis
    lignin_libraries = pool.starmap(generate_analysis_parallel, [(cur_adjs[i], monolist[i], file_writing, savefile_path) for i, result in enumerate(results)])
  File "/home/gahan/anaconda3/envs/ligninsims/lib/python3.10/multiprocessing/pool.py", line 375, in starmap
    return self._map_async(func, iterable, starmapstar, chunksize).get()
  File "/home/gahan/anaconda3/envs/ligninsims/lib/python3.10/multiprocessing/pool.py", line 774, in get
    raise self._value
KeyError: 19
multiprocessing.pool.RemoteTraceback: 
"""
Traceback (most recent call last):
  File "/home/gahan/anaconda3/envs/ligninsims/lib/python3.10/multiprocessing/pool.py", line 125, in worker
    result = (True, func(*args, **kwds))
  File "/home/gahan/anaconda3/envs/ligninsims/lib/python3.10/multiprocessing/pool.py", line 51, in starmapstar
    return list(itertools.starmap(args[0], args[1]))
  File "/home/gahan/may24/240524_allparametersopen/birch_dellon/family_1/Generation_41/Run_4/Code/function_library.py", line 201, in generate_analysis_parallel
    smiles = partial_dict_B[smiles_dictionary_id]["smilestring"]
KeyError: 18
"""

The above exception was the direct cause of the following exception:

Traceback (most recent call last):
  File "/home/gahan/may24/240524_allparametersopen/birch_dellon/family_1/Generation_41/Run_4/Code/simulation_main.py", line 80, in <module>
    simulation_run_analysis(SG_ratio, simulation_time, monomer_addition_rate, minimum_num_monomers, maximum_num_monomers, rxn_rates, number_of_runs, filewriting, filepath)
  File "/home/gahan/may24/240524_allparametersopen/birch_dellon/family_1/Generation_41/Run_4/Code/simulation_main.py", line 22, in simulation_run_analysis
    data_dictionary = generate_analysis(result, number_of_runs, num_cores=int(sys.argv[2]), file_writing=False, savefile_path=filepath)
  File "/home/gahan/may24/240524_allparametersopen/birch_dellon/family_1/Generation_41/Run_4/Code/function_library.py", line 342, in generate_analysis
    lignin_libraries = pool.starmap(generate_analysis_parallel, [(cur_adjs[i], monolist[i], file_writing, savefile_path) for i, result in enumerate(results)])
  File "/home/gahan/anaconda3/envs/ligninsims/lib/python3.10/multiprocessing/pool.py", line 375, in starmap
    return self._map_async(func, iterable, starmapstar, chunksize).get()
  File "/home/gahan/anaconda3/envs/ligninsims/lib/python3.10/multiprocessing/pool.py", line 774, in get
    raise self._value
KeyError: 18
multiprocessing.pool.RemoteTraceback: 
"""
Traceback (most recent call last):
  File "/home/gahan/anaconda3/envs/ligninsims/lib/python3.10/multiprocessing/pool.py", line 125, in worker
    result = (True, func(*args, **kwds))
  File "/home/gahan/anaconda3/envs/ligninsims/lib/python3.10/multiprocessing/pool.py", line 51, in starmapstar
    return list(itertools.starmap(args[0], args[1]))
  File "/home/gahan/may24/240524_allparametersopen/birch_dellon/family_1/Generation_42/Run_1/Code/function_library.py", line 201, in generate_analysis_parallel
    smiles = partial_dict_B[smiles_dictionary_id]["smilestring"]
KeyError: 14
"""

The above exception was the direct cause of the following exception:

Traceback (most recent call last):
  File "/home/gahan/may24/240524_allparametersopen/birch_dellon/family_1/Generation_42/Run_1/Code/simulation_main.py", line 80, in <module>
    simulation_run_analysis(SG_ratio, simulation_time, monomer_addition_rate, minimum_num_monomers, maximum_num_monomers, rxn_rates, number_of_runs, filewriting, filepath)
  File "/home/gahan/may24/240524_allparametersopen/birch_dellon/family_1/Generation_42/Run_1/Code/simulation_main.py", line 22, in simulation_run_analysis
    data_dictionary = generate_analysis(result, number_of_runs, num_cores=int(sys.argv[2]), file_writing=False, savefile_path=filepath)
  File "/home/gahan/may24/240524_allparametersopen/birch_dellon/family_1/Generation_42/Run_1/Code/function_library.py", line 342, in generate_analysis
    lignin_libraries = pool.starmap(generate_analysis_parallel, [(cur_adjs[i], monolist[i], file_writing, savefile_path) for i, result in enumerate(results)])
  File "/home/gahan/anaconda3/envs/ligninsims/lib/python3.10/multiprocessing/pool.py", line 375, in starmap
    return self._map_async(func, iterable, starmapstar, chunksize).get()
  File "/home/gahan/anaconda3/envs/ligninsims/lib/python3.10/multiprocessing/pool.py", line 774, in get
    raise self._value
KeyError: 14
multiprocessing.pool.RemoteTraceback: 
"""
Traceback (most recent call last):
  File "/home/gahan/anaconda3/envs/ligninsims/lib/python3.10/multiprocessing/pool.py", line 125, in worker
    result = (True, func(*args, **kwds))
  File "/home/gahan/anaconda3/envs/ligninsims/lib/python3.10/multiprocessing/pool.py", line 51, in starmapstar
    return list(itertools.starmap(args[0], args[1]))
  File "/home/gahan/may24/240524_allparametersopen/birch_dellon/family_1/Generation_43/Run_3/Code/function_library.py", line 201, in generate_analysis_parallel
    smiles = partial_dict_B[smiles_dictionary_id]["smilestring"]
KeyError: 59
"""

The above exception was the direct cause of the following exception:

Traceback (most recent call last):
  File "/home/gahan/may24/240524_allparametersopen/birch_dellon/family_1/Generation_43/Run_3/Code/simulation_main.py", line 80, in <module>
    simulation_run_analysis(SG_ratio, simulation_time, monomer_addition_rate, minimum_num_monomers, maximum_num_monomers, rxn_rates, number_of_runs, filewriting, filepath)
  File "/home/gahan/may24/240524_allparametersopen/birch_dellon/family_1/Generation_43/Run_3/Code/simulation_main.py", line 22, in simulation_run_analysis
    data_dictionary = generate_analysis(result, number_of_runs, num_cores=int(sys.argv[2]), file_writing=False, savefile_path=filepath)
  File "/home/gahan/may24/240524_allparametersopen/birch_dellon/family_1/Generation_43/Run_3/Code/function_library.py", line 342, in generate_analysis
    lignin_libraries = pool.starmap(generate_analysis_parallel, [(cur_adjs[i], monolist[i], file_writing, savefile_path) for i, result in enumerate(results)])
  File "/home/gahan/anaconda3/envs/ligninsims/lib/python3.10/multiprocessing/pool.py", line 375, in starmap
    return self._map_async(func, iterable, starmapstar, chunksize).get()
  File "/home/gahan/anaconda3/envs/ligninsims/lib/python3.10/multiprocessing/pool.py", line 774, in get
    raise self._value
KeyError: 59
multiprocessing.pool.RemoteTraceback: 
"""
Traceback (most recent call last):
  File "/home/gahan/anaconda3/envs/ligninsims/lib/python3.10/multiprocessing/pool.py", line 125, in worker
    result = (True, func(*args, **kwds))
  File "/home/gahan/anaconda3/envs/ligninsims/lib/python3.10/multiprocessing/pool.py", line 51, in starmapstar
    return list(itertools.starmap(args[0], args[1]))
  File "/home/gahan/may24/240524_allparametersopen/birch_dellon/family_1/Generation_44/Run_3/Code/function_library.py", line 185, in generate_analysis_parallel
    nrings = np.sum([partial_dict_B[smiles_dictionary_id + k]["rings"] for k in range(partial_dict_A[bond_dictionary_id]['Bonds']["b1"]+1)])
  File "/home/gahan/may24/240524_allparametersopen/birch_dellon/family_1/Generation_44/Run_3/Code/function_library.py", line 185, in <listcomp>
    nrings = np.sum([partial_dict_B[smiles_dictionary_id + k]["rings"] for k in range(partial_dict_A[bond_dictionary_id]['Bonds']["b1"]+1)])
KeyError: 47
"""

The above exception was the direct cause of the following exception:

Traceback (most recent call last):
  File "/home/gahan/may24/240524_allparametersopen/birch_dellon/family_1/Generation_44/Run_3/Code/simulation_main.py", line 80, in <module>
    simulation_run_analysis(SG_ratio, simulation_time, monomer_addition_rate, minimum_num_monomers, maximum_num_monomers, rxn_rates, number_of_runs, filewriting, filepath)
  File "/home/gahan/may24/240524_allparametersopen/birch_dellon/family_1/Generation_44/Run_3/Code/simulation_main.py", line 22, in simulation_run_analysis
    data_dictionary = generate_analysis(result, number_of_runs, num_cores=int(sys.argv[2]), file_writing=False, savefile_path=filepath)
  File "/home/gahan/may24/240524_allparametersopen/birch_dellon/family_1/Generation_44/Run_3/Code/function_library.py", line 342, in generate_analysis
    lignin_libraries = pool.starmap(generate_analysis_parallel, [(cur_adjs[i], monolist[i], file_writing, savefile_path) for i, result in enumerate(results)])
  File "/home/gahan/anaconda3/envs/ligninsims/lib/python3.10/multiprocessing/pool.py", line 375, in starmap
    return self._map_async(func, iterable, starmapstar, chunksize).get()
  File "/home/gahan/anaconda3/envs/ligninsims/lib/python3.10/multiprocessing/pool.py", line 774, in get
    raise self._value
KeyError: 47
multiprocessing.pool.RemoteTraceback: 
"""
Traceback (most recent call last):
  File "/home/gahan/anaconda3/envs/ligninsims/lib/python3.10/multiprocessing/pool.py", line 125, in worker
    result = (True, func(*args, **kwds))
  File "/home/gahan/anaconda3/envs/ligninsims/lib/python3.10/multiprocessing/pool.py", line 51, in starmapstar
    return list(itertools.starmap(args[0], args[1]))
  File "/home/gahan/may24/240524_allparametersopen/birch_dellon/family_1/Generation_45/Run_1/Code/function_library.py", line 185, in generate_analysis_parallel
    nrings = np.sum([partial_dict_B[smiles_dictionary_id + k]["rings"] for k in range(partial_dict_A[bond_dictionary_id]['Bonds']["b1"]+1)])
  File "/home/gahan/may24/240524_allparametersopen/birch_dellon/family_1/Generation_45/Run_1/Code/function_library.py", line 185, in <listcomp>
    nrings = np.sum([partial_dict_B[smiles_dictionary_id + k]["rings"] for k in range(partial_dict_A[bond_dictionary_id]['Bonds']["b1"]+1)])
KeyError: 16
"""

The above exception was the direct cause of the following exception:

Traceback (most recent call last):
  File "/home/gahan/may24/240524_allparametersopen/birch_dellon/family_1/Generation_45/Run_1/Code/simulation_main.py", line 80, in <module>
    simulation_run_analysis(SG_ratio, simulation_time, monomer_addition_rate, minimum_num_monomers, maximum_num_monomers, rxn_rates, number_of_runs, filewriting, filepath)
  File "/home/gahan/may24/240524_allparametersopen/birch_dellon/family_1/Generation_45/Run_1/Code/simulation_main.py", line 22, in simulation_run_analysis
    data_dictionary = generate_analysis(result, number_of_runs, num_cores=int(sys.argv[2]), file_writing=False, savefile_path=filepath)
  File "/home/gahan/may24/240524_allparametersopen/birch_dellon/family_1/Generation_45/Run_1/Code/function_library.py", line 342, in generate_analysis
    lignin_libraries = pool.starmap(generate_analysis_parallel, [(cur_adjs[i], monolist[i], file_writing, savefile_path) for i, result in enumerate(results)])
  File "/home/gahan/anaconda3/envs/ligninsims/lib/python3.10/multiprocessing/pool.py", line 375, in starmap
    return self._map_async(func, iterable, starmapstar, chunksize).get()
  File "/home/gahan/anaconda3/envs/ligninsims/lib/python3.10/multiprocessing/pool.py", line 774, in get
    raise self._value
KeyError: 16
multiprocessing.pool.RemoteTraceback: 
"""
Traceback (most recent call last):
  File "/home/gahan/anaconda3/envs/ligninsims/lib/python3.10/multiprocessing/pool.py", line 125, in worker
    result = (True, func(*args, **kwds))
  File "/home/gahan/anaconda3/envs/ligninsims/lib/python3.10/multiprocessing/pool.py", line 51, in starmapstar
    return list(itertools.starmap(args[0], args[1]))
  File "/home/gahan/may24/240524_allparametersopen/birch_dellon/family_1/Generation_45/Run_2/Code/function_library.py", line 201, in generate_analysis_parallel
    smiles = partial_dict_B[smiles_dictionary_id]["smilestring"]
KeyError: 24
"""

The above exception was the direct cause of the following exception:

Traceback (most recent call last):
  File "/home/gahan/may24/240524_allparametersopen/birch_dellon/family_1/Generation_45/Run_2/Code/simulation_main.py", line 80, in <module>
    simulation_run_analysis(SG_ratio, simulation_time, monomer_addition_rate, minimum_num_monomers, maximum_num_monomers, rxn_rates, number_of_runs, filewriting, filepath)
  File "/home/gahan/may24/240524_allparametersopen/birch_dellon/family_1/Generation_45/Run_2/Code/simulation_main.py", line 22, in simulation_run_analysis
    data_dictionary = generate_analysis(result, number_of_runs, num_cores=int(sys.argv[2]), file_writing=False, savefile_path=filepath)
  File "/home/gahan/may24/240524_allparametersopen/birch_dellon/family_1/Generation_45/Run_2/Code/function_library.py", line 342, in generate_analysis
    lignin_libraries = pool.starmap(generate_analysis_parallel, [(cur_adjs[i], monolist[i], file_writing, savefile_path) for i, result in enumerate(results)])
  File "/home/gahan/anaconda3/envs/ligninsims/lib/python3.10/multiprocessing/pool.py", line 375, in starmap
    return self._map_async(func, iterable, starmapstar, chunksize).get()
  File "/home/gahan/anaconda3/envs/ligninsims/lib/python3.10/multiprocessing/pool.py", line 774, in get
    raise self._value
KeyError: 24
multiprocessing.pool.RemoteTraceback: 
"""
Traceback (most recent call last):
  File "/home/gahan/anaconda3/envs/ligninsims/lib/python3.10/multiprocessing/pool.py", line 125, in worker
    result = (True, func(*args, **kwds))
  File "/home/gahan/anaconda3/envs/ligninsims/lib/python3.10/multiprocessing/pool.py", line 51, in starmapstar
    return list(itertools.starmap(args[0], args[1]))
  File "/home/gahan/may24/240524_allparametersopen/birch_dellon/family_1/Generation_45/Run_3/Code/function_library.py", line 201, in generate_analysis_parallel
    smiles = partial_dict_B[smiles_dictionary_id]["smilestring"]
KeyError: 38
"""

The above exception was the direct cause of the following exception:

Traceback (most recent call last):
  File "/home/gahan/may24/240524_allparametersopen/birch_dellon/family_1/Generation_45/Run_3/Code/simulation_main.py", line 80, in <module>
    simulation_run_analysis(SG_ratio, simulation_time, monomer_addition_rate, minimum_num_monomers, maximum_num_monomers, rxn_rates, number_of_runs, filewriting, filepath)
  File "/home/gahan/may24/240524_allparametersopen/birch_dellon/family_1/Generation_45/Run_3/Code/simulation_main.py", line 22, in simulation_run_analysis
    data_dictionary = generate_analysis(result, number_of_runs, num_cores=int(sys.argv[2]), file_writing=False, savefile_path=filepath)
  File "/home/gahan/may24/240524_allparametersopen/birch_dellon/family_1/Generation_45/Run_3/Code/function_library.py", line 342, in generate_analysis
    lignin_libraries = pool.starmap(generate_analysis_parallel, [(cur_adjs[i], monolist[i], file_writing, savefile_path) for i, result in enumerate(results)])
  File "/home/gahan/anaconda3/envs/ligninsims/lib/python3.10/multiprocessing/pool.py", line 375, in starmap
    return self._map_async(func, iterable, starmapstar, chunksize).get()
  File "/home/gahan/anaconda3/envs/ligninsims/lib/python3.10/multiprocessing/pool.py", line 774, in get
    raise self._value
KeyError: 38
multiprocessing.pool.RemoteTraceback: 
"""
Traceback (most recent call last):
  File "/home/gahan/anaconda3/envs/ligninsims/lib/python3.10/multiprocessing/pool.py", line 125, in worker
    result = (True, func(*args, **kwds))
  File "/home/gahan/anaconda3/envs/ligninsims/lib/python3.10/multiprocessing/pool.py", line 51, in starmapstar
    return list(itertools.starmap(args[0], args[1]))
  File "/home/gahan/may24/240524_allparametersopen/birch_dellon/family_1/Generation_46/Run_1/Code/function_library.py", line 185, in generate_analysis_parallel
    nrings = np.sum([partial_dict_B[smiles_dictionary_id + k]["rings"] for k in range(partial_dict_A[bond_dictionary_id]['Bonds']["b1"]+1)])
  File "/home/gahan/may24/240524_allparametersopen/birch_dellon/family_1/Generation_46/Run_1/Code/function_library.py", line 185, in <listcomp>
    nrings = np.sum([partial_dict_B[smiles_dictionary_id + k]["rings"] for k in range(partial_dict_A[bond_dictionary_id]['Bonds']["b1"]+1)])
KeyError: 62
"""

The above exception was the direct cause of the following exception:

Traceback (most recent call last):
  File "/home/gahan/may24/240524_allparametersopen/birch_dellon/family_1/Generation_46/Run_1/Code/simulation_main.py", line 80, in <module>
    simulation_run_analysis(SG_ratio, simulation_time, monomer_addition_rate, minimum_num_monomers, maximum_num_monomers, rxn_rates, number_of_runs, filewriting, filepath)
  File "/home/gahan/may24/240524_allparametersopen/birch_dellon/family_1/Generation_46/Run_1/Code/simulation_main.py", line 22, in simulation_run_analysis
    data_dictionary = generate_analysis(result, number_of_runs, num_cores=int(sys.argv[2]), file_writing=False, savefile_path=filepath)
  File "/home/gahan/may24/240524_allparametersopen/birch_dellon/family_1/Generation_46/Run_1/Code/function_library.py", line 342, in generate_analysis
    lignin_libraries = pool.starmap(generate_analysis_parallel, [(cur_adjs[i], monolist[i], file_writing, savefile_path) for i, result in enumerate(results)])
  File "/home/gahan/anaconda3/envs/ligninsims/lib/python3.10/multiprocessing/pool.py", line 375, in starmap
    return self._map_async(func, iterable, starmapstar, chunksize).get()
  File "/home/gahan/anaconda3/envs/ligninsims/lib/python3.10/multiprocessing/pool.py", line 774, in get
    raise self._value
KeyError: 62
multiprocessing.pool.RemoteTraceback: 
"""
Traceback (most recent call last):
  File "/home/gahan/anaconda3/envs/ligninsims/lib/python3.10/multiprocessing/pool.py", line 125, in worker
    result = (True, func(*args, **kwds))
  File "/home/gahan/anaconda3/envs/ligninsims/lib/python3.10/multiprocessing/pool.py", line 51, in starmapstar
    return list(itertools.starmap(args[0], args[1]))
  File "/home/gahan/may24/240524_allparametersopen/birch_dellon/family_1/Generation_46/Run_3/Code/function_library.py", line 201, in generate_analysis_parallel
    smiles = partial_dict_B[smiles_dictionary_id]["smilestring"]
KeyError: 44
"""

The above exception was the direct cause of the following exception:

Traceback (most recent call last):
  File "/home/gahan/may24/240524_allparametersopen/birch_dellon/family_1/Generation_46/Run_3/Code/simulation_main.py", line 80, in <module>
    simulation_run_analysis(SG_ratio, simulation_time, monomer_addition_rate, minimum_num_monomers, maximum_num_monomers, rxn_rates, number_of_runs, filewriting, filepath)
  File "/home/gahan/may24/240524_allparametersopen/birch_dellon/family_1/Generation_46/Run_3/Code/simulation_main.py", line 22, in simulation_run_analysis
    data_dictionary = generate_analysis(result, number_of_runs, num_cores=int(sys.argv[2]), file_writing=False, savefile_path=filepath)
  File "/home/gahan/may24/240524_allparametersopen/birch_dellon/family_1/Generation_46/Run_3/Code/function_library.py", line 342, in generate_analysis
    lignin_libraries = pool.starmap(generate_analysis_parallel, [(cur_adjs[i], monolist[i], file_writing, savefile_path) for i, result in enumerate(results)])
  File "/home/gahan/anaconda3/envs/ligninsims/lib/python3.10/multiprocessing/pool.py", line 375, in starmap
    return self._map_async(func, iterable, starmapstar, chunksize).get()
  File "/home/gahan/anaconda3/envs/ligninsims/lib/python3.10/multiprocessing/pool.py", line 774, in get
    raise self._value
KeyError: 44
multiprocessing.pool.RemoteTraceback: 
"""
Traceback (most recent call last):
  File "/home/gahan/anaconda3/envs/ligninsims/lib/python3.10/multiprocessing/pool.py", line 125, in worker
    result = (True, func(*args, **kwds))
  File "/home/gahan/anaconda3/envs/ligninsims/lib/python3.10/multiprocessing/pool.py", line 51, in starmapstar
    return list(itertools.starmap(args[0], args[1]))
  File "/home/gahan/may24/240524_allparametersopen/birch_dellon/family_1/Generation_46/Run_4/Code/function_library.py", line 201, in generate_analysis_parallel
    smiles = partial_dict_B[smiles_dictionary_id]["smilestring"]
KeyError: 38
"""

The above exception was the direct cause of the following exception:

Traceback (most recent call last):
  File "/home/gahan/may24/240524_allparametersopen/birch_dellon/family_1/Generation_46/Run_4/Code/simulation_main.py", line 80, in <module>
    simulation_run_analysis(SG_ratio, simulation_time, monomer_addition_rate, minimum_num_monomers, maximum_num_monomers, rxn_rates, number_of_runs, filewriting, filepath)
  File "/home/gahan/may24/240524_allparametersopen/birch_dellon/family_1/Generation_46/Run_4/Code/simulation_main.py", line 22, in simulation_run_analysis
    data_dictionary = generate_analysis(result, number_of_runs, num_cores=int(sys.argv[2]), file_writing=False, savefile_path=filepath)
  File "/home/gahan/may24/240524_allparametersopen/birch_dellon/family_1/Generation_46/Run_4/Code/function_library.py", line 342, in generate_analysis
    lignin_libraries = pool.starmap(generate_analysis_parallel, [(cur_adjs[i], monolist[i], file_writing, savefile_path) for i, result in enumerate(results)])
  File "/home/gahan/anaconda3/envs/ligninsims/lib/python3.10/multiprocessing/pool.py", line 375, in starmap
    return self._map_async(func, iterable, starmapstar, chunksize).get()
  File "/home/gahan/anaconda3/envs/ligninsims/lib/python3.10/multiprocessing/pool.py", line 774, in get
    raise self._value
KeyError: 38
multiprocessing.pool.RemoteTraceback: 
"""
Traceback (most recent call last):
  File "/home/gahan/anaconda3/envs/ligninsims/lib/python3.10/multiprocessing/pool.py", line 125, in worker
    result = (True, func(*args, **kwds))
  File "/home/gahan/anaconda3/envs/ligninsims/lib/python3.10/multiprocessing/pool.py", line 51, in starmapstar
    return list(itertools.starmap(args[0], args[1]))
  File "/home/gahan/may24/240524_allparametersopen/birch_dellon/family_1/Generation_48/Run_1/Code/function_library.py", line 201, in generate_analysis_parallel
    smiles = partial_dict_B[smiles_dictionary_id]["smilestring"]
KeyError: 40
"""

The above exception was the direct cause of the following exception:

Traceback (most recent call last):
  File "/home/gahan/may24/240524_allparametersopen/birch_dellon/family_1/Generation_48/Run_1/Code/simulation_main.py", line 80, in <module>
    simulation_run_analysis(SG_ratio, simulation_time, monomer_addition_rate, minimum_num_monomers, maximum_num_monomers, rxn_rates, number_of_runs, filewriting, filepath)
  File "/home/gahan/may24/240524_allparametersopen/birch_dellon/family_1/Generation_48/Run_1/Code/simulation_main.py", line 22, in simulation_run_analysis
    data_dictionary = generate_analysis(result, number_of_runs, num_cores=int(sys.argv[2]), file_writing=False, savefile_path=filepath)
  File "/home/gahan/may24/240524_allparametersopen/birch_dellon/family_1/Generation_48/Run_1/Code/function_library.py", line 342, in generate_analysis
    lignin_libraries = pool.starmap(generate_analysis_parallel, [(cur_adjs[i], monolist[i], file_writing, savefile_path) for i, result in enumerate(results)])
  File "/home/gahan/anaconda3/envs/ligninsims/lib/python3.10/multiprocessing/pool.py", line 375, in starmap
    return self._map_async(func, iterable, starmapstar, chunksize).get()
  File "/home/gahan/anaconda3/envs/ligninsims/lib/python3.10/multiprocessing/pool.py", line 774, in get
    raise self._value
KeyError: 40
multiprocessing.pool.RemoteTraceback: 
"""
Traceback (most recent call last):
  File "/home/gahan/anaconda3/envs/ligninsims/lib/python3.10/multiprocessing/pool.py", line 125, in worker
    result = (True, func(*args, **kwds))
  File "/home/gahan/anaconda3/envs/ligninsims/lib/python3.10/multiprocessing/pool.py", line 51, in starmapstar
    return list(itertools.starmap(args[0], args[1]))
  File "/home/gahan/may24/240524_allparametersopen/birch_dellon/family_1/Generation_48/Run_4/Code/function_library.py", line 201, in generate_analysis_parallel
    smiles = partial_dict_B[smiles_dictionary_id]["smilestring"]
KeyError: 33
"""

The above exception was the direct cause of the following exception:

Traceback (most recent call last):
  File "/home/gahan/may24/240524_allparametersopen/birch_dellon/family_1/Generation_48/Run_4/Code/simulation_main.py", line 80, in <module>
    simulation_run_analysis(SG_ratio, simulation_time, monomer_addition_rate, minimum_num_monomers, maximum_num_monomers, rxn_rates, number_of_runs, filewriting, filepath)
  File "/home/gahan/may24/240524_allparametersopen/birch_dellon/family_1/Generation_48/Run_4/Code/simulation_main.py", line 22, in simulation_run_analysis
    data_dictionary = generate_analysis(result, number_of_runs, num_cores=int(sys.argv[2]), file_writing=False, savefile_path=filepath)
  File "/home/gahan/may24/240524_allparametersopen/birch_dellon/family_1/Generation_48/Run_4/Code/function_library.py", line 342, in generate_analysis
    lignin_libraries = pool.starmap(generate_analysis_parallel, [(cur_adjs[i], monolist[i], file_writing, savefile_path) for i, result in enumerate(results)])
  File "/home/gahan/anaconda3/envs/ligninsims/lib/python3.10/multiprocessing/pool.py", line 375, in starmap
    return self._map_async(func, iterable, starmapstar, chunksize).get()
  File "/home/gahan/anaconda3/envs/ligninsims/lib/python3.10/multiprocessing/pool.py", line 774, in get
    raise self._value
KeyError: 33
multiprocessing.pool.RemoteTraceback: 
"""
Traceback (most recent call last):
  File "/home/gahan/anaconda3/envs/ligninsims/lib/python3.10/multiprocessing/pool.py", line 125, in worker
    result = (True, func(*args, **kwds))
  File "/home/gahan/anaconda3/envs/ligninsims/lib/python3.10/multiprocessing/pool.py", line 51, in starmapstar
    return list(itertools.starmap(args[0], args[1]))
  File "/home/gahan/may24/240524_allparametersopen/birch_dellon/family_1/Generation_49/Run_4/Code/function_library.py", line 201, in generate_analysis_parallel
    smiles = partial_dict_B[smiles_dictionary_id]["smilestring"]
KeyError: 36
"""

The above exception was the direct cause of the following exception:

Traceback (most recent call last):
  File "/home/gahan/may24/240524_allparametersopen/birch_dellon/family_1/Generation_49/Run_4/Code/simulation_main.py", line 80, in <module>
    simulation_run_analysis(SG_ratio, simulation_time, monomer_addition_rate, minimum_num_monomers, maximum_num_monomers, rxn_rates, number_of_runs, filewriting, filepath)
  File "/home/gahan/may24/240524_allparametersopen/birch_dellon/family_1/Generation_49/Run_4/Code/simulation_main.py", line 22, in simulation_run_analysis
    data_dictionary = generate_analysis(result, number_of_runs, num_cores=int(sys.argv[2]), file_writing=False, savefile_path=filepath)
  File "/home/gahan/may24/240524_allparametersopen/birch_dellon/family_1/Generation_49/Run_4/Code/function_library.py", line 342, in generate_analysis
    lignin_libraries = pool.starmap(generate_analysis_parallel, [(cur_adjs[i], monolist[i], file_writing, savefile_path) for i, result in enumerate(results)])
  File "/home/gahan/anaconda3/envs/ligninsims/lib/python3.10/multiprocessing/pool.py", line 375, in starmap
    return self._map_async(func, iterable, starmapstar, chunksize).get()
  File "/home/gahan/anaconda3/envs/ligninsims/lib/python3.10/multiprocessing/pool.py", line 774, in get
    raise self._value
KeyError: 36
multiprocessing.pool.RemoteTraceback: 
"""
Traceback (most recent call last):
  File "/home/gahan/anaconda3/envs/ligninsims/lib/python3.10/multiprocessing/pool.py", line 125, in worker
    result = (True, func(*args, **kwds))
  File "/home/gahan/anaconda3/envs/ligninsims/lib/python3.10/multiprocessing/pool.py", line 51, in starmapstar
    return list(itertools.starmap(args[0], args[1]))
  File "/home/gahan/may24/240524_allparametersopen/birch_dellon/family_1/Generation_50/Run_2/Code/function_library.py", line 201, in generate_analysis_parallel
    smiles = partial_dict_B[smiles_dictionary_id]["smilestring"]
KeyError: 27
"""

The above exception was the direct cause of the following exception:

Traceback (most recent call last):
  File "/home/gahan/may24/240524_allparametersopen/birch_dellon/family_1/Generation_50/Run_2/Code/simulation_main.py", line 80, in <module>
    simulation_run_analysis(SG_ratio, simulation_time, monomer_addition_rate, minimum_num_monomers, maximum_num_monomers, rxn_rates, number_of_runs, filewriting, filepath)
  File "/home/gahan/may24/240524_allparametersopen/birch_dellon/family_1/Generation_50/Run_2/Code/simulation_main.py", line 22, in simulation_run_analysis
    data_dictionary = generate_analysis(result, number_of_runs, num_cores=int(sys.argv[2]), file_writing=False, savefile_path=filepath)
  File "/home/gahan/may24/240524_allparametersopen/birch_dellon/family_1/Generation_50/Run_2/Code/function_library.py", line 342, in generate_analysis
    lignin_libraries = pool.starmap(generate_analysis_parallel, [(cur_adjs[i], monolist[i], file_writing, savefile_path) for i, result in enumerate(results)])
  File "/home/gahan/anaconda3/envs/ligninsims/lib/python3.10/multiprocessing/pool.py", line 375, in starmap
    return self._map_async(func, iterable, starmapstar, chunksize).get()
  File "/home/gahan/anaconda3/envs/ligninsims/lib/python3.10/multiprocessing/pool.py", line 774, in get
    raise self._value
KeyError: 27
multiprocessing.pool.RemoteTraceback: 
"""
Traceback (most recent call last):
  File "/home/gahan/anaconda3/envs/ligninsims/lib/python3.10/multiprocessing/pool.py", line 125, in worker
    result = (True, func(*args, **kwds))
  File "/home/gahan/anaconda3/envs/ligninsims/lib/python3.10/multiprocessing/pool.py", line 51, in starmapstar
    return list(itertools.starmap(args[0], args[1]))
  File "/home/gahan/may24/240524_allparametersopen/birch_dellon/family_1/Generation_50/Run_3/Code/function_library.py", line 201, in generate_analysis_parallel
    smiles = partial_dict_B[smiles_dictionary_id]["smilestring"]
KeyError: 55
"""

The above exception was the direct cause of the following exception:

Traceback (most recent call last):
  File "/home/gahan/may24/240524_allparametersopen/birch_dellon/family_1/Generation_50/Run_3/Code/simulation_main.py", line 80, in <module>
    simulation_run_analysis(SG_ratio, simulation_time, monomer_addition_rate, minimum_num_monomers, maximum_num_monomers, rxn_rates, number_of_runs, filewriting, filepath)
  File "/home/gahan/may24/240524_allparametersopen/birch_dellon/family_1/Generation_50/Run_3/Code/simulation_main.py", line 22, in simulation_run_analysis
    data_dictionary = generate_analysis(result, number_of_runs, num_cores=int(sys.argv[2]), file_writing=False, savefile_path=filepath)
  File "/home/gahan/may24/240524_allparametersopen/birch_dellon/family_1/Generation_50/Run_3/Code/function_library.py", line 342, in generate_analysis
    lignin_libraries = pool.starmap(generate_analysis_parallel, [(cur_adjs[i], monolist[i], file_writing, savefile_path) for i, result in enumerate(results)])
  File "/home/gahan/anaconda3/envs/ligninsims/lib/python3.10/multiprocessing/pool.py", line 375, in starmap
    return self._map_async(func, iterable, starmapstar, chunksize).get()
  File "/home/gahan/anaconda3/envs/ligninsims/lib/python3.10/multiprocessing/pool.py", line 774, in get
    raise self._value
KeyError: 55
rm: das Entfernen von 'Gridsearch/Run*' ist nicht möglich: Datei oder Verzeichnis nicht gefunden
multiprocessing.pool.RemoteTraceback: 
"""
Traceback (most recent call last):
  File "/home/gahan/anaconda3/envs/ligninsims/lib/python3.10/multiprocessing/pool.py", line 125, in worker
    result = (True, func(*args, **kwds))
  File "/home/gahan/anaconda3/envs/ligninsims/lib/python3.10/multiprocessing/pool.py", line 51, in starmapstar
    return list(itertools.starmap(args[0], args[1]))
  File "/home/gahan/may24/240524_allparametersopen/birch_dellon/BEST_FIT/best_Run/Code/function_library.py", line 201, in generate_analysis_parallel
    smiles = partial_dict_B[smiles_dictionary_id]["smilestring"]
KeyError: 35
"""

The above exception was the direct cause of the following exception:

Traceback (most recent call last):
  File "/home/gahan/may24/240524_allparametersopen/birch_dellon/BEST_FIT/best_Run/Code/simulation_main.py", line 80, in <module>
    simulation_run_analysis(SG_ratio, simulation_time, monomer_addition_rate, minimum_num_monomers, maximum_num_monomers, rxn_rates, number_of_runs, filewriting, filepath)
  File "/home/gahan/may24/240524_allparametersopen/birch_dellon/BEST_FIT/best_Run/Code/simulation_main.py", line 22, in simulation_run_analysis
    data_dictionary = generate_analysis(result, number_of_runs, num_cores=int(sys.argv[2]), file_writing=False, savefile_path=filepath)
  File "/home/gahan/may24/240524_allparametersopen/birch_dellon/BEST_FIT/best_Run/Code/function_library.py", line 342, in generate_analysis
    lignin_libraries = pool.starmap(generate_analysis_parallel, [(cur_adjs[i], monolist[i], file_writing, savefile_path) for i, result in enumerate(results)])
  File "/home/gahan/anaconda3/envs/ligninsims/lib/python3.10/multiprocessing/pool.py", line 375, in starmap
    return self._map_async(func, iterable, starmapstar, chunksize).get()
  File "/home/gahan/anaconda3/envs/ligninsims/lib/python3.10/multiprocessing/pool.py", line 774, in get
    raise self._value
KeyError: 35
