rm: das Entfernen von 'family_1/Generation_*' ist nicht möglich: Datei oder Verzeichnis nicht gefunden
rm: das Entfernen von 'family_1/vars_*.txt' ist nicht möglich: Datei oder Verzeichnis nicht gefunden
rm: das Entfernen von 'Gridsearch/Run*' ist nicht möglich: Datei oder Verzeichnis nicht gefunden
multiprocessing.pool.RemoteTraceback: 
"""
Traceback (most recent call last):
  File "/home/gahan/anaconda3/envs/ligninsims/lib/python3.10/multiprocessing/pool.py", line 125, in worker
    result = (True, func(*args, **kwds))
  File "/home/gahan/anaconda3/envs/ligninsims/lib/python3.10/multiprocessing/pool.py", line 51, in starmapstar
    return list(itertools.starmap(args[0], args[1]))
  File "/home/gahan/may24/240524_allparametersopen/wheatstraw_terrell/family_1/Generation_9/Run_3/Code/function_library.py", line 201, in generate_analysis_parallel
    smiles = partial_dict_B[smiles_dictionary_id]["smilestring"]
KeyError: 25
"""

The above exception was the direct cause of the following exception:

Traceback (most recent call last):
  File "/home/gahan/may24/240524_allparametersopen/wheatstraw_terrell/family_1/Generation_9/Run_3/Code/simulation_main.py", line 80, in <module>
    simulation_run_analysis(SG_ratio, simulation_time, monomer_addition_rate, minimum_num_monomers, maximum_num_monomers, rxn_rates, number_of_runs, filewriting, filepath)
  File "/home/gahan/may24/240524_allparametersopen/wheatstraw_terrell/family_1/Generation_9/Run_3/Code/simulation_main.py", line 22, in simulation_run_analysis
    data_dictionary = generate_analysis(result, number_of_runs, num_cores=int(sys.argv[2]), file_writing=False, savefile_path=filepath)
  File "/home/gahan/may24/240524_allparametersopen/wheatstraw_terrell/family_1/Generation_9/Run_3/Code/function_library.py", line 342, in generate_analysis
    lignin_libraries = pool.starmap(generate_analysis_parallel, [(cur_adjs[i], monolist[i], file_writing, savefile_path) for i, result in enumerate(results)])
  File "/home/gahan/anaconda3/envs/ligninsims/lib/python3.10/multiprocessing/pool.py", line 375, in starmap
    return self._map_async(func, iterable, starmapstar, chunksize).get()
  File "/home/gahan/anaconda3/envs/ligninsims/lib/python3.10/multiprocessing/pool.py", line 774, in get
    raise self._value
KeyError: 25
multiprocessing.pool.RemoteTraceback: 
"""
Traceback (most recent call last):
  File "/home/gahan/anaconda3/envs/ligninsims/lib/python3.10/multiprocessing/pool.py", line 125, in worker
    result = (True, func(*args, **kwds))
  File "/home/gahan/anaconda3/envs/ligninsims/lib/python3.10/multiprocessing/pool.py", line 51, in starmapstar
    return list(itertools.starmap(args[0], args[1]))
  File "/home/gahan/may24/240524_allparametersopen/wheatstraw_terrell/family_1/Generation_11/Run_1/Code/function_library.py", line 185, in generate_analysis_parallel
    nrings = np.sum([partial_dict_B[smiles_dictionary_id + k]["rings"] for k in range(partial_dict_A[bond_dictionary_id]['Bonds']["b1"]+1)])
  File "/home/gahan/may24/240524_allparametersopen/wheatstraw_terrell/family_1/Generation_11/Run_1/Code/function_library.py", line 185, in <listcomp>
    nrings = np.sum([partial_dict_B[smiles_dictionary_id + k]["rings"] for k in range(partial_dict_A[bond_dictionary_id]['Bonds']["b1"]+1)])
KeyError: 41
"""

The above exception was the direct cause of the following exception:

Traceback (most recent call last):
  File "/home/gahan/may24/240524_allparametersopen/wheatstraw_terrell/family_1/Generation_11/Run_1/Code/simulation_main.py", line 80, in <module>
    simulation_run_analysis(SG_ratio, simulation_time, monomer_addition_rate, minimum_num_monomers, maximum_num_monomers, rxn_rates, number_of_runs, filewriting, filepath)
  File "/home/gahan/may24/240524_allparametersopen/wheatstraw_terrell/family_1/Generation_11/Run_1/Code/simulation_main.py", line 22, in simulation_run_analysis
    data_dictionary = generate_analysis(result, number_of_runs, num_cores=int(sys.argv[2]), file_writing=False, savefile_path=filepath)
  File "/home/gahan/may24/240524_allparametersopen/wheatstraw_terrell/family_1/Generation_11/Run_1/Code/function_library.py", line 342, in generate_analysis
    lignin_libraries = pool.starmap(generate_analysis_parallel, [(cur_adjs[i], monolist[i], file_writing, savefile_path) for i, result in enumerate(results)])
  File "/home/gahan/anaconda3/envs/ligninsims/lib/python3.10/multiprocessing/pool.py", line 375, in starmap
    return self._map_async(func, iterable, starmapstar, chunksize).get()
  File "/home/gahan/anaconda3/envs/ligninsims/lib/python3.10/multiprocessing/pool.py", line 774, in get
    raise self._value
KeyError: 41
multiprocessing.pool.RemoteTraceback: 
"""
Traceback (most recent call last):
  File "/home/gahan/anaconda3/envs/ligninsims/lib/python3.10/multiprocessing/pool.py", line 125, in worker
    result = (True, func(*args, **kwds))
  File "/home/gahan/anaconda3/envs/ligninsims/lib/python3.10/multiprocessing/pool.py", line 51, in starmapstar
    return list(itertools.starmap(args[0], args[1]))
  File "/home/gahan/may24/240524_allparametersopen/wheatstraw_terrell/family_1/Generation_12/Run_1/Code/function_library.py", line 201, in generate_analysis_parallel
    smiles = partial_dict_B[smiles_dictionary_id]["smilestring"]
KeyError: 59
"""

The above exception was the direct cause of the following exception:

Traceback (most recent call last):
  File "/home/gahan/may24/240524_allparametersopen/wheatstraw_terrell/family_1/Generation_12/Run_1/Code/simulation_main.py", line 80, in <module>
    simulation_run_analysis(SG_ratio, simulation_time, monomer_addition_rate, minimum_num_monomers, maximum_num_monomers, rxn_rates, number_of_runs, filewriting, filepath)
  File "/home/gahan/may24/240524_allparametersopen/wheatstraw_terrell/family_1/Generation_12/Run_1/Code/simulation_main.py", line 22, in simulation_run_analysis
    data_dictionary = generate_analysis(result, number_of_runs, num_cores=int(sys.argv[2]), file_writing=False, savefile_path=filepath)
  File "/home/gahan/may24/240524_allparametersopen/wheatstraw_terrell/family_1/Generation_12/Run_1/Code/function_library.py", line 342, in generate_analysis
    lignin_libraries = pool.starmap(generate_analysis_parallel, [(cur_adjs[i], monolist[i], file_writing, savefile_path) for i, result in enumerate(results)])
  File "/home/gahan/anaconda3/envs/ligninsims/lib/python3.10/multiprocessing/pool.py", line 375, in starmap
    return self._map_async(func, iterable, starmapstar, chunksize).get()
  File "/home/gahan/anaconda3/envs/ligninsims/lib/python3.10/multiprocessing/pool.py", line 774, in get
    raise self._value
KeyError: 59
multiprocessing.pool.RemoteTraceback: 
"""
Traceback (most recent call last):
  File "/home/gahan/anaconda3/envs/ligninsims/lib/python3.10/multiprocessing/pool.py", line 125, in worker
    result = (True, func(*args, **kwds))
  File "/home/gahan/anaconda3/envs/ligninsims/lib/python3.10/multiprocessing/pool.py", line 51, in starmapstar
    return list(itertools.starmap(args[0], args[1]))
  File "/home/gahan/may24/240524_allparametersopen/wheatstraw_terrell/family_1/Generation_13/Run_4/Code/function_library.py", line 185, in generate_analysis_parallel
    nrings = np.sum([partial_dict_B[smiles_dictionary_id + k]["rings"] for k in range(partial_dict_A[bond_dictionary_id]['Bonds']["b1"]+1)])
  File "/home/gahan/may24/240524_allparametersopen/wheatstraw_terrell/family_1/Generation_13/Run_4/Code/function_library.py", line 185, in <listcomp>
    nrings = np.sum([partial_dict_B[smiles_dictionary_id + k]["rings"] for k in range(partial_dict_A[bond_dictionary_id]['Bonds']["b1"]+1)])
KeyError: 48
"""

The above exception was the direct cause of the following exception:

Traceback (most recent call last):
  File "/home/gahan/may24/240524_allparametersopen/wheatstraw_terrell/family_1/Generation_13/Run_4/Code/simulation_main.py", line 80, in <module>
    simulation_run_analysis(SG_ratio, simulation_time, monomer_addition_rate, minimum_num_monomers, maximum_num_monomers, rxn_rates, number_of_runs, filewriting, filepath)
  File "/home/gahan/may24/240524_allparametersopen/wheatstraw_terrell/family_1/Generation_13/Run_4/Code/simulation_main.py", line 22, in simulation_run_analysis
    data_dictionary = generate_analysis(result, number_of_runs, num_cores=int(sys.argv[2]), file_writing=False, savefile_path=filepath)
  File "/home/gahan/may24/240524_allparametersopen/wheatstraw_terrell/family_1/Generation_13/Run_4/Code/function_library.py", line 342, in generate_analysis
    lignin_libraries = pool.starmap(generate_analysis_parallel, [(cur_adjs[i], monolist[i], file_writing, savefile_path) for i, result in enumerate(results)])
  File "/home/gahan/anaconda3/envs/ligninsims/lib/python3.10/multiprocessing/pool.py", line 375, in starmap
    return self._map_async(func, iterable, starmapstar, chunksize).get()
  File "/home/gahan/anaconda3/envs/ligninsims/lib/python3.10/multiprocessing/pool.py", line 774, in get
    raise self._value
KeyError: 48
multiprocessing.pool.RemoteTraceback: 
"""
Traceback (most recent call last):
  File "/home/gahan/anaconda3/envs/ligninsims/lib/python3.10/multiprocessing/pool.py", line 125, in worker
    result = (True, func(*args, **kwds))
  File "/home/gahan/anaconda3/envs/ligninsims/lib/python3.10/multiprocessing/pool.py", line 51, in starmapstar
    return list(itertools.starmap(args[0], args[1]))
  File "/home/gahan/may24/240524_allparametersopen/wheatstraw_terrell/family_1/Generation_15/Run_4/Code/function_library.py", line 185, in generate_analysis_parallel
    nrings = np.sum([partial_dict_B[smiles_dictionary_id + k]["rings"] for k in range(partial_dict_A[bond_dictionary_id]['Bonds']["b1"]+1)])
  File "/home/gahan/may24/240524_allparametersopen/wheatstraw_terrell/family_1/Generation_15/Run_4/Code/function_library.py", line 185, in <listcomp>
    nrings = np.sum([partial_dict_B[smiles_dictionary_id + k]["rings"] for k in range(partial_dict_A[bond_dictionary_id]['Bonds']["b1"]+1)])
KeyError: 49
"""

The above exception was the direct cause of the following exception:

Traceback (most recent call last):
  File "/home/gahan/may24/240524_allparametersopen/wheatstraw_terrell/family_1/Generation_15/Run_4/Code/simulation_main.py", line 80, in <module>
    simulation_run_analysis(SG_ratio, simulation_time, monomer_addition_rate, minimum_num_monomers, maximum_num_monomers, rxn_rates, number_of_runs, filewriting, filepath)
  File "/home/gahan/may24/240524_allparametersopen/wheatstraw_terrell/family_1/Generation_15/Run_4/Code/simulation_main.py", line 22, in simulation_run_analysis
    data_dictionary = generate_analysis(result, number_of_runs, num_cores=int(sys.argv[2]), file_writing=False, savefile_path=filepath)
  File "/home/gahan/may24/240524_allparametersopen/wheatstraw_terrell/family_1/Generation_15/Run_4/Code/function_library.py", line 342, in generate_analysis
    lignin_libraries = pool.starmap(generate_analysis_parallel, [(cur_adjs[i], monolist[i], file_writing, savefile_path) for i, result in enumerate(results)])
  File "/home/gahan/anaconda3/envs/ligninsims/lib/python3.10/multiprocessing/pool.py", line 375, in starmap
    return self._map_async(func, iterable, starmapstar, chunksize).get()
  File "/home/gahan/anaconda3/envs/ligninsims/lib/python3.10/multiprocessing/pool.py", line 774, in get
    raise self._value
KeyError: 49
multiprocessing.pool.RemoteTraceback: 
"""
Traceback (most recent call last):
  File "/home/gahan/anaconda3/envs/ligninsims/lib/python3.10/multiprocessing/pool.py", line 125, in worker
    result = (True, func(*args, **kwds))
  File "/home/gahan/anaconda3/envs/ligninsims/lib/python3.10/multiprocessing/pool.py", line 51, in starmapstar
    return list(itertools.starmap(args[0], args[1]))
  File "/home/gahan/may24/240524_allparametersopen/wheatstraw_terrell/family_1/Generation_17/Run_1/Code/function_library.py", line 201, in generate_analysis_parallel
    smiles = partial_dict_B[smiles_dictionary_id]["smilestring"]
KeyError: 36
"""

The above exception was the direct cause of the following exception:

Traceback (most recent call last):
  File "/home/gahan/may24/240524_allparametersopen/wheatstraw_terrell/family_1/Generation_17/Run_1/Code/simulation_main.py", line 80, in <module>
    simulation_run_analysis(SG_ratio, simulation_time, monomer_addition_rate, minimum_num_monomers, maximum_num_monomers, rxn_rates, number_of_runs, filewriting, filepath)
  File "/home/gahan/may24/240524_allparametersopen/wheatstraw_terrell/family_1/Generation_17/Run_1/Code/simulation_main.py", line 22, in simulation_run_analysis
    data_dictionary = generate_analysis(result, number_of_runs, num_cores=int(sys.argv[2]), file_writing=False, savefile_path=filepath)
  File "/home/gahan/may24/240524_allparametersopen/wheatstraw_terrell/family_1/Generation_17/Run_1/Code/function_library.py", line 342, in generate_analysis
    lignin_libraries = pool.starmap(generate_analysis_parallel, [(cur_adjs[i], monolist[i], file_writing, savefile_path) for i, result in enumerate(results)])
  File "/home/gahan/anaconda3/envs/ligninsims/lib/python3.10/multiprocessing/pool.py", line 375, in starmap
    return self._map_async(func, iterable, starmapstar, chunksize).get()
  File "/home/gahan/anaconda3/envs/ligninsims/lib/python3.10/multiprocessing/pool.py", line 774, in get
    raise self._value
KeyError: 36
multiprocessing.pool.RemoteTraceback: 
"""
Traceback (most recent call last):
  File "/home/gahan/anaconda3/envs/ligninsims/lib/python3.10/multiprocessing/pool.py", line 125, in worker
    result = (True, func(*args, **kwds))
  File "/home/gahan/anaconda3/envs/ligninsims/lib/python3.10/multiprocessing/pool.py", line 51, in starmapstar
    return list(itertools.starmap(args[0], args[1]))
  File "/home/gahan/may24/240524_allparametersopen/wheatstraw_terrell/family_1/Generation_22/Run_4/Code/function_library.py", line 201, in generate_analysis_parallel
    smiles = partial_dict_B[smiles_dictionary_id]["smilestring"]
KeyError: 37
"""

The above exception was the direct cause of the following exception:

Traceback (most recent call last):
  File "/home/gahan/may24/240524_allparametersopen/wheatstraw_terrell/family_1/Generation_22/Run_4/Code/simulation_main.py", line 80, in <module>
    simulation_run_analysis(SG_ratio, simulation_time, monomer_addition_rate, minimum_num_monomers, maximum_num_monomers, rxn_rates, number_of_runs, filewriting, filepath)
  File "/home/gahan/may24/240524_allparametersopen/wheatstraw_terrell/family_1/Generation_22/Run_4/Code/simulation_main.py", line 22, in simulation_run_analysis
    data_dictionary = generate_analysis(result, number_of_runs, num_cores=int(sys.argv[2]), file_writing=False, savefile_path=filepath)
  File "/home/gahan/may24/240524_allparametersopen/wheatstraw_terrell/family_1/Generation_22/Run_4/Code/function_library.py", line 342, in generate_analysis
    lignin_libraries = pool.starmap(generate_analysis_parallel, [(cur_adjs[i], monolist[i], file_writing, savefile_path) for i, result in enumerate(results)])
  File "/home/gahan/anaconda3/envs/ligninsims/lib/python3.10/multiprocessing/pool.py", line 375, in starmap
    return self._map_async(func, iterable, starmapstar, chunksize).get()
  File "/home/gahan/anaconda3/envs/ligninsims/lib/python3.10/multiprocessing/pool.py", line 774, in get
    raise self._value
KeyError: 37
multiprocessing.pool.RemoteTraceback: 
"""
Traceback (most recent call last):
  File "/home/gahan/anaconda3/envs/ligninsims/lib/python3.10/multiprocessing/pool.py", line 125, in worker
    result = (True, func(*args, **kwds))
  File "/home/gahan/anaconda3/envs/ligninsims/lib/python3.10/multiprocessing/pool.py", line 51, in starmapstar
    return list(itertools.starmap(args[0], args[1]))
  File "/home/gahan/may24/240524_allparametersopen/wheatstraw_terrell/family_1/Generation_25/Run_2/Code/function_library.py", line 201, in generate_analysis_parallel
    smiles = partial_dict_B[smiles_dictionary_id]["smilestring"]
KeyError: 25
"""

The above exception was the direct cause of the following exception:

Traceback (most recent call last):
  File "/home/gahan/may24/240524_allparametersopen/wheatstraw_terrell/family_1/Generation_25/Run_2/Code/simulation_main.py", line 80, in <module>
    simulation_run_analysis(SG_ratio, simulation_time, monomer_addition_rate, minimum_num_monomers, maximum_num_monomers, rxn_rates, number_of_runs, filewriting, filepath)
  File "/home/gahan/may24/240524_allparametersopen/wheatstraw_terrell/family_1/Generation_25/Run_2/Code/simulation_main.py", line 22, in simulation_run_analysis
    data_dictionary = generate_analysis(result, number_of_runs, num_cores=int(sys.argv[2]), file_writing=False, savefile_path=filepath)
  File "/home/gahan/may24/240524_allparametersopen/wheatstraw_terrell/family_1/Generation_25/Run_2/Code/function_library.py", line 342, in generate_analysis
    lignin_libraries = pool.starmap(generate_analysis_parallel, [(cur_adjs[i], monolist[i], file_writing, savefile_path) for i, result in enumerate(results)])
  File "/home/gahan/anaconda3/envs/ligninsims/lib/python3.10/multiprocessing/pool.py", line 375, in starmap
    return self._map_async(func, iterable, starmapstar, chunksize).get()
  File "/home/gahan/anaconda3/envs/ligninsims/lib/python3.10/multiprocessing/pool.py", line 774, in get
    raise self._value
KeyError: 25
multiprocessing.pool.RemoteTraceback: 
"""
Traceback (most recent call last):
  File "/home/gahan/anaconda3/envs/ligninsims/lib/python3.10/multiprocessing/pool.py", line 125, in worker
    result = (True, func(*args, **kwds))
  File "/home/gahan/anaconda3/envs/ligninsims/lib/python3.10/multiprocessing/pool.py", line 51, in starmapstar
    return list(itertools.starmap(args[0], args[1]))
  File "/home/gahan/may24/240524_allparametersopen/wheatstraw_terrell/family_1/Generation_25/Run_4/Code/function_library.py", line 201, in generate_analysis_parallel
    smiles = partial_dict_B[smiles_dictionary_id]["smilestring"]
KeyError: 54
"""

The above exception was the direct cause of the following exception:

Traceback (most recent call last):
  File "/home/gahan/may24/240524_allparametersopen/wheatstraw_terrell/family_1/Generation_25/Run_4/Code/simulation_main.py", line 80, in <module>
    simulation_run_analysis(SG_ratio, simulation_time, monomer_addition_rate, minimum_num_monomers, maximum_num_monomers, rxn_rates, number_of_runs, filewriting, filepath)
  File "/home/gahan/may24/240524_allparametersopen/wheatstraw_terrell/family_1/Generation_25/Run_4/Code/simulation_main.py", line 22, in simulation_run_analysis
    data_dictionary = generate_analysis(result, number_of_runs, num_cores=int(sys.argv[2]), file_writing=False, savefile_path=filepath)
  File "/home/gahan/may24/240524_allparametersopen/wheatstraw_terrell/family_1/Generation_25/Run_4/Code/function_library.py", line 342, in generate_analysis
    lignin_libraries = pool.starmap(generate_analysis_parallel, [(cur_adjs[i], monolist[i], file_writing, savefile_path) for i, result in enumerate(results)])
  File "/home/gahan/anaconda3/envs/ligninsims/lib/python3.10/multiprocessing/pool.py", line 375, in starmap
    return self._map_async(func, iterable, starmapstar, chunksize).get()
  File "/home/gahan/anaconda3/envs/ligninsims/lib/python3.10/multiprocessing/pool.py", line 774, in get
    raise self._value
KeyError: 54
multiprocessing.pool.RemoteTraceback: 
"""
Traceback (most recent call last):
  File "/home/gahan/anaconda3/envs/ligninsims/lib/python3.10/multiprocessing/pool.py", line 125, in worker
    result = (True, func(*args, **kwds))
  File "/home/gahan/anaconda3/envs/ligninsims/lib/python3.10/multiprocessing/pool.py", line 51, in starmapstar
    return list(itertools.starmap(args[0], args[1]))
  File "/home/gahan/may24/240524_allparametersopen/wheatstraw_terrell/family_1/Generation_28/Run_4/Code/function_library.py", line 201, in generate_analysis_parallel
    smiles = partial_dict_B[smiles_dictionary_id]["smilestring"]
KeyError: 34
"""

The above exception was the direct cause of the following exception:

Traceback (most recent call last):
  File "/home/gahan/may24/240524_allparametersopen/wheatstraw_terrell/family_1/Generation_28/Run_4/Code/simulation_main.py", line 80, in <module>
    simulation_run_analysis(SG_ratio, simulation_time, monomer_addition_rate, minimum_num_monomers, maximum_num_monomers, rxn_rates, number_of_runs, filewriting, filepath)
  File "/home/gahan/may24/240524_allparametersopen/wheatstraw_terrell/family_1/Generation_28/Run_4/Code/simulation_main.py", line 22, in simulation_run_analysis
    data_dictionary = generate_analysis(result, number_of_runs, num_cores=int(sys.argv[2]), file_writing=False, savefile_path=filepath)
  File "/home/gahan/may24/240524_allparametersopen/wheatstraw_terrell/family_1/Generation_28/Run_4/Code/function_library.py", line 342, in generate_analysis
    lignin_libraries = pool.starmap(generate_analysis_parallel, [(cur_adjs[i], monolist[i], file_writing, savefile_path) for i, result in enumerate(results)])
  File "/home/gahan/anaconda3/envs/ligninsims/lib/python3.10/multiprocessing/pool.py", line 375, in starmap
    return self._map_async(func, iterable, starmapstar, chunksize).get()
  File "/home/gahan/anaconda3/envs/ligninsims/lib/python3.10/multiprocessing/pool.py", line 774, in get
    raise self._value
KeyError: 34
multiprocessing.pool.RemoteTraceback: 
"""
Traceback (most recent call last):
  File "/home/gahan/anaconda3/envs/ligninsims/lib/python3.10/multiprocessing/pool.py", line 125, in worker
    result = (True, func(*args, **kwds))
  File "/home/gahan/anaconda3/envs/ligninsims/lib/python3.10/multiprocessing/pool.py", line 51, in starmapstar
    return list(itertools.starmap(args[0], args[1]))
  File "/home/gahan/may24/240524_allparametersopen/wheatstraw_terrell/family_1/Generation_29/Run_2/Code/function_library.py", line 201, in generate_analysis_parallel
    smiles = partial_dict_B[smiles_dictionary_id]["smilestring"]
KeyError: 53
"""

The above exception was the direct cause of the following exception:

Traceback (most recent call last):
  File "/home/gahan/may24/240524_allparametersopen/wheatstraw_terrell/family_1/Generation_29/Run_2/Code/simulation_main.py", line 80, in <module>
    simulation_run_analysis(SG_ratio, simulation_time, monomer_addition_rate, minimum_num_monomers, maximum_num_monomers, rxn_rates, number_of_runs, filewriting, filepath)
  File "/home/gahan/may24/240524_allparametersopen/wheatstraw_terrell/family_1/Generation_29/Run_2/Code/simulation_main.py", line 22, in simulation_run_analysis
    data_dictionary = generate_analysis(result, number_of_runs, num_cores=int(sys.argv[2]), file_writing=False, savefile_path=filepath)
  File "/home/gahan/may24/240524_allparametersopen/wheatstraw_terrell/family_1/Generation_29/Run_2/Code/function_library.py", line 342, in generate_analysis
    lignin_libraries = pool.starmap(generate_analysis_parallel, [(cur_adjs[i], monolist[i], file_writing, savefile_path) for i, result in enumerate(results)])
  File "/home/gahan/anaconda3/envs/ligninsims/lib/python3.10/multiprocessing/pool.py", line 375, in starmap
    return self._map_async(func, iterable, starmapstar, chunksize).get()
  File "/home/gahan/anaconda3/envs/ligninsims/lib/python3.10/multiprocessing/pool.py", line 774, in get
    raise self._value
KeyError: 53
multiprocessing.pool.RemoteTraceback: 
"""
Traceback (most recent call last):
  File "/home/gahan/anaconda3/envs/ligninsims/lib/python3.10/multiprocessing/pool.py", line 125, in worker
    result = (True, func(*args, **kwds))
  File "/home/gahan/anaconda3/envs/ligninsims/lib/python3.10/multiprocessing/pool.py", line 51, in starmapstar
    return list(itertools.starmap(args[0], args[1]))
  File "/home/gahan/may24/240524_allparametersopen/wheatstraw_terrell/family_1/Generation_31/Run_1/Code/function_library.py", line 201, in generate_analysis_parallel
    smiles = partial_dict_B[smiles_dictionary_id]["smilestring"]
KeyError: 61
"""

The above exception was the direct cause of the following exception:

Traceback (most recent call last):
  File "/home/gahan/may24/240524_allparametersopen/wheatstraw_terrell/family_1/Generation_31/Run_1/Code/simulation_main.py", line 80, in <module>
    simulation_run_analysis(SG_ratio, simulation_time, monomer_addition_rate, minimum_num_monomers, maximum_num_monomers, rxn_rates, number_of_runs, filewriting, filepath)
  File "/home/gahan/may24/240524_allparametersopen/wheatstraw_terrell/family_1/Generation_31/Run_1/Code/simulation_main.py", line 22, in simulation_run_analysis
    data_dictionary = generate_analysis(result, number_of_runs, num_cores=int(sys.argv[2]), file_writing=False, savefile_path=filepath)
  File "/home/gahan/may24/240524_allparametersopen/wheatstraw_terrell/family_1/Generation_31/Run_1/Code/function_library.py", line 342, in generate_analysis
    lignin_libraries = pool.starmap(generate_analysis_parallel, [(cur_adjs[i], monolist[i], file_writing, savefile_path) for i, result in enumerate(results)])
  File "/home/gahan/anaconda3/envs/ligninsims/lib/python3.10/multiprocessing/pool.py", line 375, in starmap
    return self._map_async(func, iterable, starmapstar, chunksize).get()
  File "/home/gahan/anaconda3/envs/ligninsims/lib/python3.10/multiprocessing/pool.py", line 774, in get
    raise self._value
KeyError: 61
multiprocessing.pool.RemoteTraceback: 
"""
Traceback (most recent call last):
  File "/home/gahan/anaconda3/envs/ligninsims/lib/python3.10/multiprocessing/pool.py", line 125, in worker
    result = (True, func(*args, **kwds))
  File "/home/gahan/anaconda3/envs/ligninsims/lib/python3.10/multiprocessing/pool.py", line 51, in starmapstar
    return list(itertools.starmap(args[0], args[1]))
  File "/home/gahan/may24/240524_allparametersopen/wheatstraw_terrell/family_1/Generation_32/Run_4/Code/function_library.py", line 201, in generate_analysis_parallel
    smiles = partial_dict_B[smiles_dictionary_id]["smilestring"]
KeyError: 20
"""

The above exception was the direct cause of the following exception:

Traceback (most recent call last):
  File "/home/gahan/may24/240524_allparametersopen/wheatstraw_terrell/family_1/Generation_32/Run_4/Code/simulation_main.py", line 80, in <module>
    simulation_run_analysis(SG_ratio, simulation_time, monomer_addition_rate, minimum_num_monomers, maximum_num_monomers, rxn_rates, number_of_runs, filewriting, filepath)
  File "/home/gahan/may24/240524_allparametersopen/wheatstraw_terrell/family_1/Generation_32/Run_4/Code/simulation_main.py", line 22, in simulation_run_analysis
    data_dictionary = generate_analysis(result, number_of_runs, num_cores=int(sys.argv[2]), file_writing=False, savefile_path=filepath)
  File "/home/gahan/may24/240524_allparametersopen/wheatstraw_terrell/family_1/Generation_32/Run_4/Code/function_library.py", line 342, in generate_analysis
    lignin_libraries = pool.starmap(generate_analysis_parallel, [(cur_adjs[i], monolist[i], file_writing, savefile_path) for i, result in enumerate(results)])
  File "/home/gahan/anaconda3/envs/ligninsims/lib/python3.10/multiprocessing/pool.py", line 375, in starmap
    return self._map_async(func, iterable, starmapstar, chunksize).get()
  File "/home/gahan/anaconda3/envs/ligninsims/lib/python3.10/multiprocessing/pool.py", line 774, in get
    raise self._value
KeyError: 20
multiprocessing.pool.RemoteTraceback: 
"""
Traceback (most recent call last):
  File "/home/gahan/anaconda3/envs/ligninsims/lib/python3.10/multiprocessing/pool.py", line 125, in worker
    result = (True, func(*args, **kwds))
  File "/home/gahan/anaconda3/envs/ligninsims/lib/python3.10/multiprocessing/pool.py", line 51, in starmapstar
    return list(itertools.starmap(args[0], args[1]))
  File "/home/gahan/may24/240524_allparametersopen/wheatstraw_terrell/family_1/Generation_33/Run_4/Code/function_library.py", line 185, in generate_analysis_parallel
    nrings = np.sum([partial_dict_B[smiles_dictionary_id + k]["rings"] for k in range(partial_dict_A[bond_dictionary_id]['Bonds']["b1"]+1)])
  File "/home/gahan/may24/240524_allparametersopen/wheatstraw_terrell/family_1/Generation_33/Run_4/Code/function_library.py", line 185, in <listcomp>
    nrings = np.sum([partial_dict_B[smiles_dictionary_id + k]["rings"] for k in range(partial_dict_A[bond_dictionary_id]['Bonds']["b1"]+1)])
KeyError: 59
"""

The above exception was the direct cause of the following exception:

Traceback (most recent call last):
  File "/home/gahan/may24/240524_allparametersopen/wheatstraw_terrell/family_1/Generation_33/Run_4/Code/simulation_main.py", line 80, in <module>
    simulation_run_analysis(SG_ratio, simulation_time, monomer_addition_rate, minimum_num_monomers, maximum_num_monomers, rxn_rates, number_of_runs, filewriting, filepath)
  File "/home/gahan/may24/240524_allparametersopen/wheatstraw_terrell/family_1/Generation_33/Run_4/Code/simulation_main.py", line 22, in simulation_run_analysis
    data_dictionary = generate_analysis(result, number_of_runs, num_cores=int(sys.argv[2]), file_writing=False, savefile_path=filepath)
  File "/home/gahan/may24/240524_allparametersopen/wheatstraw_terrell/family_1/Generation_33/Run_4/Code/function_library.py", line 342, in generate_analysis
    lignin_libraries = pool.starmap(generate_analysis_parallel, [(cur_adjs[i], monolist[i], file_writing, savefile_path) for i, result in enumerate(results)])
  File "/home/gahan/anaconda3/envs/ligninsims/lib/python3.10/multiprocessing/pool.py", line 375, in starmap
    return self._map_async(func, iterable, starmapstar, chunksize).get()
  File "/home/gahan/anaconda3/envs/ligninsims/lib/python3.10/multiprocessing/pool.py", line 774, in get
    raise self._value
KeyError: 59
multiprocessing.pool.RemoteTraceback: 
"""
Traceback (most recent call last):
  File "/home/gahan/anaconda3/envs/ligninsims/lib/python3.10/multiprocessing/pool.py", line 125, in worker
    result = (True, func(*args, **kwds))
  File "/home/gahan/anaconda3/envs/ligninsims/lib/python3.10/multiprocessing/pool.py", line 51, in starmapstar
    return list(itertools.starmap(args[0], args[1]))
  File "/home/gahan/may24/240524_allparametersopen/wheatstraw_terrell/family_1/Generation_34/Run_4/Code/function_library.py", line 185, in generate_analysis_parallel
    nrings = np.sum([partial_dict_B[smiles_dictionary_id + k]["rings"] for k in range(partial_dict_A[bond_dictionary_id]['Bonds']["b1"]+1)])
  File "/home/gahan/may24/240524_allparametersopen/wheatstraw_terrell/family_1/Generation_34/Run_4/Code/function_library.py", line 185, in <listcomp>
    nrings = np.sum([partial_dict_B[smiles_dictionary_id + k]["rings"] for k in range(partial_dict_A[bond_dictionary_id]['Bonds']["b1"]+1)])
KeyError: 98
"""

The above exception was the direct cause of the following exception:

Traceback (most recent call last):
  File "/home/gahan/may24/240524_allparametersopen/wheatstraw_terrell/family_1/Generation_34/Run_4/Code/simulation_main.py", line 80, in <module>
    simulation_run_analysis(SG_ratio, simulation_time, monomer_addition_rate, minimum_num_monomers, maximum_num_monomers, rxn_rates, number_of_runs, filewriting, filepath)
  File "/home/gahan/may24/240524_allparametersopen/wheatstraw_terrell/family_1/Generation_34/Run_4/Code/simulation_main.py", line 22, in simulation_run_analysis
    data_dictionary = generate_analysis(result, number_of_runs, num_cores=int(sys.argv[2]), file_writing=False, savefile_path=filepath)
  File "/home/gahan/may24/240524_allparametersopen/wheatstraw_terrell/family_1/Generation_34/Run_4/Code/function_library.py", line 342, in generate_analysis
    lignin_libraries = pool.starmap(generate_analysis_parallel, [(cur_adjs[i], monolist[i], file_writing, savefile_path) for i, result in enumerate(results)])
  File "/home/gahan/anaconda3/envs/ligninsims/lib/python3.10/multiprocessing/pool.py", line 375, in starmap
    return self._map_async(func, iterable, starmapstar, chunksize).get()
  File "/home/gahan/anaconda3/envs/ligninsims/lib/python3.10/multiprocessing/pool.py", line 774, in get
    raise self._value
KeyError: 98
multiprocessing.pool.RemoteTraceback: 
"""
Traceback (most recent call last):
  File "/home/gahan/anaconda3/envs/ligninsims/lib/python3.10/multiprocessing/pool.py", line 125, in worker
    result = (True, func(*args, **kwds))
  File "/home/gahan/anaconda3/envs/ligninsims/lib/python3.10/multiprocessing/pool.py", line 51, in starmapstar
    return list(itertools.starmap(args[0], args[1]))
  File "/home/gahan/may24/240524_allparametersopen/wheatstraw_terrell/family_1/Generation_38/Run_4/Code/function_library.py", line 201, in generate_analysis_parallel
    smiles = partial_dict_B[smiles_dictionary_id]["smilestring"]
KeyError: 43
"""

The above exception was the direct cause of the following exception:

Traceback (most recent call last):
  File "/home/gahan/may24/240524_allparametersopen/wheatstraw_terrell/family_1/Generation_38/Run_4/Code/simulation_main.py", line 80, in <module>
    simulation_run_analysis(SG_ratio, simulation_time, monomer_addition_rate, minimum_num_monomers, maximum_num_monomers, rxn_rates, number_of_runs, filewriting, filepath)
  File "/home/gahan/may24/240524_allparametersopen/wheatstraw_terrell/family_1/Generation_38/Run_4/Code/simulation_main.py", line 22, in simulation_run_analysis
    data_dictionary = generate_analysis(result, number_of_runs, num_cores=int(sys.argv[2]), file_writing=False, savefile_path=filepath)
  File "/home/gahan/may24/240524_allparametersopen/wheatstraw_terrell/family_1/Generation_38/Run_4/Code/function_library.py", line 342, in generate_analysis
    lignin_libraries = pool.starmap(generate_analysis_parallel, [(cur_adjs[i], monolist[i], file_writing, savefile_path) for i, result in enumerate(results)])
  File "/home/gahan/anaconda3/envs/ligninsims/lib/python3.10/multiprocessing/pool.py", line 375, in starmap
    return self._map_async(func, iterable, starmapstar, chunksize).get()
  File "/home/gahan/anaconda3/envs/ligninsims/lib/python3.10/multiprocessing/pool.py", line 774, in get
    raise self._value
KeyError: 43
multiprocessing.pool.RemoteTraceback: 
"""
Traceback (most recent call last):
  File "/home/gahan/anaconda3/envs/ligninsims/lib/python3.10/multiprocessing/pool.py", line 125, in worker
    result = (True, func(*args, **kwds))
  File "/home/gahan/anaconda3/envs/ligninsims/lib/python3.10/multiprocessing/pool.py", line 51, in starmapstar
    return list(itertools.starmap(args[0], args[1]))
  File "/home/gahan/may24/240524_allparametersopen/wheatstraw_terrell/family_1/Generation_39/Run_3/Code/function_library.py", line 201, in generate_analysis_parallel
    smiles = partial_dict_B[smiles_dictionary_id]["smilestring"]
KeyError: 50
"""

The above exception was the direct cause of the following exception:

Traceback (most recent call last):
  File "/home/gahan/may24/240524_allparametersopen/wheatstraw_terrell/family_1/Generation_39/Run_3/Code/simulation_main.py", line 80, in <module>
    simulation_run_analysis(SG_ratio, simulation_time, monomer_addition_rate, minimum_num_monomers, maximum_num_monomers, rxn_rates, number_of_runs, filewriting, filepath)
  File "/home/gahan/may24/240524_allparametersopen/wheatstraw_terrell/family_1/Generation_39/Run_3/Code/simulation_main.py", line 22, in simulation_run_analysis
    data_dictionary = generate_analysis(result, number_of_runs, num_cores=int(sys.argv[2]), file_writing=False, savefile_path=filepath)
  File "/home/gahan/may24/240524_allparametersopen/wheatstraw_terrell/family_1/Generation_39/Run_3/Code/function_library.py", line 342, in generate_analysis
    lignin_libraries = pool.starmap(generate_analysis_parallel, [(cur_adjs[i], monolist[i], file_writing, savefile_path) for i, result in enumerate(results)])
  File "/home/gahan/anaconda3/envs/ligninsims/lib/python3.10/multiprocessing/pool.py", line 375, in starmap
    return self._map_async(func, iterable, starmapstar, chunksize).get()
  File "/home/gahan/anaconda3/envs/ligninsims/lib/python3.10/multiprocessing/pool.py", line 774, in get
    raise self._value
KeyError: 50
multiprocessing.pool.RemoteTraceback: 
"""
Traceback (most recent call last):
  File "/home/gahan/anaconda3/envs/ligninsims/lib/python3.10/multiprocessing/pool.py", line 125, in worker
    result = (True, func(*args, **kwds))
  File "/home/gahan/anaconda3/envs/ligninsims/lib/python3.10/multiprocessing/pool.py", line 51, in starmapstar
    return list(itertools.starmap(args[0], args[1]))
  File "/home/gahan/may24/240524_allparametersopen/wheatstraw_terrell/family_1/Generation_39/Run_4/Code/function_library.py", line 201, in generate_analysis_parallel
    smiles = partial_dict_B[smiles_dictionary_id]["smilestring"]
KeyError: 92
"""

The above exception was the direct cause of the following exception:

Traceback (most recent call last):
  File "/home/gahan/may24/240524_allparametersopen/wheatstraw_terrell/family_1/Generation_39/Run_4/Code/simulation_main.py", line 80, in <module>
    simulation_run_analysis(SG_ratio, simulation_time, monomer_addition_rate, minimum_num_monomers, maximum_num_monomers, rxn_rates, number_of_runs, filewriting, filepath)
  File "/home/gahan/may24/240524_allparametersopen/wheatstraw_terrell/family_1/Generation_39/Run_4/Code/simulation_main.py", line 22, in simulation_run_analysis
    data_dictionary = generate_analysis(result, number_of_runs, num_cores=int(sys.argv[2]), file_writing=False, savefile_path=filepath)
  File "/home/gahan/may24/240524_allparametersopen/wheatstraw_terrell/family_1/Generation_39/Run_4/Code/function_library.py", line 342, in generate_analysis
    lignin_libraries = pool.starmap(generate_analysis_parallel, [(cur_adjs[i], monolist[i], file_writing, savefile_path) for i, result in enumerate(results)])
  File "/home/gahan/anaconda3/envs/ligninsims/lib/python3.10/multiprocessing/pool.py", line 375, in starmap
    return self._map_async(func, iterable, starmapstar, chunksize).get()
  File "/home/gahan/anaconda3/envs/ligninsims/lib/python3.10/multiprocessing/pool.py", line 774, in get
    raise self._value
KeyError: 92
multiprocessing.pool.RemoteTraceback: 
"""
Traceback (most recent call last):
  File "/home/gahan/anaconda3/envs/ligninsims/lib/python3.10/multiprocessing/pool.py", line 125, in worker
    result = (True, func(*args, **kwds))
  File "/home/gahan/anaconda3/envs/ligninsims/lib/python3.10/multiprocessing/pool.py", line 51, in starmapstar
    return list(itertools.starmap(args[0], args[1]))
  File "/home/gahan/may24/240524_allparametersopen/wheatstraw_terrell/family_1/Generation_40/Run_4/Code/function_library.py", line 185, in generate_analysis_parallel
    nrings = np.sum([partial_dict_B[smiles_dictionary_id + k]["rings"] for k in range(partial_dict_A[bond_dictionary_id]['Bonds']["b1"]+1)])
  File "/home/gahan/may24/240524_allparametersopen/wheatstraw_terrell/family_1/Generation_40/Run_4/Code/function_library.py", line 185, in <listcomp>
    nrings = np.sum([partial_dict_B[smiles_dictionary_id + k]["rings"] for k in range(partial_dict_A[bond_dictionary_id]['Bonds']["b1"]+1)])
KeyError: 59
"""

The above exception was the direct cause of the following exception:

Traceback (most recent call last):
  File "/home/gahan/may24/240524_allparametersopen/wheatstraw_terrell/family_1/Generation_40/Run_4/Code/simulation_main.py", line 80, in <module>
    simulation_run_analysis(SG_ratio, simulation_time, monomer_addition_rate, minimum_num_monomers, maximum_num_monomers, rxn_rates, number_of_runs, filewriting, filepath)
  File "/home/gahan/may24/240524_allparametersopen/wheatstraw_terrell/family_1/Generation_40/Run_4/Code/simulation_main.py", line 22, in simulation_run_analysis
    data_dictionary = generate_analysis(result, number_of_runs, num_cores=int(sys.argv[2]), file_writing=False, savefile_path=filepath)
  File "/home/gahan/may24/240524_allparametersopen/wheatstraw_terrell/family_1/Generation_40/Run_4/Code/function_library.py", line 342, in generate_analysis
    lignin_libraries = pool.starmap(generate_analysis_parallel, [(cur_adjs[i], monolist[i], file_writing, savefile_path) for i, result in enumerate(results)])
  File "/home/gahan/anaconda3/envs/ligninsims/lib/python3.10/multiprocessing/pool.py", line 375, in starmap
    return self._map_async(func, iterable, starmapstar, chunksize).get()
  File "/home/gahan/anaconda3/envs/ligninsims/lib/python3.10/multiprocessing/pool.py", line 774, in get
    raise self._value
KeyError: 59
multiprocessing.pool.RemoteTraceback: 
"""
Traceback (most recent call last):
  File "/home/gahan/anaconda3/envs/ligninsims/lib/python3.10/multiprocessing/pool.py", line 125, in worker
    result = (True, func(*args, **kwds))
  File "/home/gahan/anaconda3/envs/ligninsims/lib/python3.10/multiprocessing/pool.py", line 51, in starmapstar
    return list(itertools.starmap(args[0], args[1]))
  File "/home/gahan/may24/240524_allparametersopen/wheatstraw_terrell/family_1/Generation_42/Run_2/Code/function_library.py", line 201, in generate_analysis_parallel
    smiles = partial_dict_B[smiles_dictionary_id]["smilestring"]
KeyError: 46
"""

The above exception was the direct cause of the following exception:

Traceback (most recent call last):
  File "/home/gahan/may24/240524_allparametersopen/wheatstraw_terrell/family_1/Generation_42/Run_2/Code/simulation_main.py", line 80, in <module>
    simulation_run_analysis(SG_ratio, simulation_time, monomer_addition_rate, minimum_num_monomers, maximum_num_monomers, rxn_rates, number_of_runs, filewriting, filepath)
  File "/home/gahan/may24/240524_allparametersopen/wheatstraw_terrell/family_1/Generation_42/Run_2/Code/simulation_main.py", line 22, in simulation_run_analysis
    data_dictionary = generate_analysis(result, number_of_runs, num_cores=int(sys.argv[2]), file_writing=False, savefile_path=filepath)
  File "/home/gahan/may24/240524_allparametersopen/wheatstraw_terrell/family_1/Generation_42/Run_2/Code/function_library.py", line 342, in generate_analysis
    lignin_libraries = pool.starmap(generate_analysis_parallel, [(cur_adjs[i], monolist[i], file_writing, savefile_path) for i, result in enumerate(results)])
  File "/home/gahan/anaconda3/envs/ligninsims/lib/python3.10/multiprocessing/pool.py", line 375, in starmap
    return self._map_async(func, iterable, starmapstar, chunksize).get()
  File "/home/gahan/anaconda3/envs/ligninsims/lib/python3.10/multiprocessing/pool.py", line 774, in get
    raise self._value
KeyError: 46
multiprocessing.pool.RemoteTraceback: 
"""
Traceback (most recent call last):
  File "/home/gahan/anaconda3/envs/ligninsims/lib/python3.10/multiprocessing/pool.py", line 125, in worker
    result = (True, func(*args, **kwds))
  File "/home/gahan/anaconda3/envs/ligninsims/lib/python3.10/multiprocessing/pool.py", line 51, in starmapstar
    return list(itertools.starmap(args[0], args[1]))
  File "/home/gahan/may24/240524_allparametersopen/wheatstraw_terrell/family_1/Generation_43/Run_1/Code/function_library.py", line 201, in generate_analysis_parallel
    smiles = partial_dict_B[smiles_dictionary_id]["smilestring"]
KeyError: 59
"""

The above exception was the direct cause of the following exception:

Traceback (most recent call last):
  File "/home/gahan/may24/240524_allparametersopen/wheatstraw_terrell/family_1/Generation_43/Run_1/Code/simulation_main.py", line 80, in <module>
    simulation_run_analysis(SG_ratio, simulation_time, monomer_addition_rate, minimum_num_monomers, maximum_num_monomers, rxn_rates, number_of_runs, filewriting, filepath)
  File "/home/gahan/may24/240524_allparametersopen/wheatstraw_terrell/family_1/Generation_43/Run_1/Code/simulation_main.py", line 22, in simulation_run_analysis
    data_dictionary = generate_analysis(result, number_of_runs, num_cores=int(sys.argv[2]), file_writing=False, savefile_path=filepath)
  File "/home/gahan/may24/240524_allparametersopen/wheatstraw_terrell/family_1/Generation_43/Run_1/Code/function_library.py", line 342, in generate_analysis
    lignin_libraries = pool.starmap(generate_analysis_parallel, [(cur_adjs[i], monolist[i], file_writing, savefile_path) for i, result in enumerate(results)])
  File "/home/gahan/anaconda3/envs/ligninsims/lib/python3.10/multiprocessing/pool.py", line 375, in starmap
    return self._map_async(func, iterable, starmapstar, chunksize).get()
  File "/home/gahan/anaconda3/envs/ligninsims/lib/python3.10/multiprocessing/pool.py", line 774, in get
    raise self._value
KeyError: 59
multiprocessing.pool.RemoteTraceback: 
"""
Traceback (most recent call last):
  File "/home/gahan/anaconda3/envs/ligninsims/lib/python3.10/multiprocessing/pool.py", line 125, in worker
    result = (True, func(*args, **kwds))
  File "/home/gahan/anaconda3/envs/ligninsims/lib/python3.10/multiprocessing/pool.py", line 51, in starmapstar
    return list(itertools.starmap(args[0], args[1]))
  File "/home/gahan/may24/240524_allparametersopen/wheatstraw_terrell/family_1/Generation_43/Run_3/Code/function_library.py", line 201, in generate_analysis_parallel
    smiles = partial_dict_B[smiles_dictionary_id]["smilestring"]
KeyError: 19
"""

The above exception was the direct cause of the following exception:

Traceback (most recent call last):
  File "/home/gahan/may24/240524_allparametersopen/wheatstraw_terrell/family_1/Generation_43/Run_3/Code/simulation_main.py", line 80, in <module>
    simulation_run_analysis(SG_ratio, simulation_time, monomer_addition_rate, minimum_num_monomers, maximum_num_monomers, rxn_rates, number_of_runs, filewriting, filepath)
  File "/home/gahan/may24/240524_allparametersopen/wheatstraw_terrell/family_1/Generation_43/Run_3/Code/simulation_main.py", line 22, in simulation_run_analysis
    data_dictionary = generate_analysis(result, number_of_runs, num_cores=int(sys.argv[2]), file_writing=False, savefile_path=filepath)
  File "/home/gahan/may24/240524_allparametersopen/wheatstraw_terrell/family_1/Generation_43/Run_3/Code/function_library.py", line 342, in generate_analysis
    lignin_libraries = pool.starmap(generate_analysis_parallel, [(cur_adjs[i], monolist[i], file_writing, savefile_path) for i, result in enumerate(results)])
  File "/home/gahan/anaconda3/envs/ligninsims/lib/python3.10/multiprocessing/pool.py", line 375, in starmap
    return self._map_async(func, iterable, starmapstar, chunksize).get()
  File "/home/gahan/anaconda3/envs/ligninsims/lib/python3.10/multiprocessing/pool.py", line 774, in get
    raise self._value
KeyError: 19
multiprocessing.pool.RemoteTraceback: 
"""
Traceback (most recent call last):
  File "/home/gahan/anaconda3/envs/ligninsims/lib/python3.10/multiprocessing/pool.py", line 125, in worker
    result = (True, func(*args, **kwds))
  File "/home/gahan/anaconda3/envs/ligninsims/lib/python3.10/multiprocessing/pool.py", line 51, in starmapstar
    return list(itertools.starmap(args[0], args[1]))
  File "/home/gahan/may24/240524_allparametersopen/wheatstraw_terrell/family_1/Generation_43/Run_4/Code/function_library.py", line 201, in generate_analysis_parallel
    smiles = partial_dict_B[smiles_dictionary_id]["smilestring"]
KeyError: 31
"""

The above exception was the direct cause of the following exception:

Traceback (most recent call last):
  File "/home/gahan/may24/240524_allparametersopen/wheatstraw_terrell/family_1/Generation_43/Run_4/Code/simulation_main.py", line 80, in <module>
    simulation_run_analysis(SG_ratio, simulation_time, monomer_addition_rate, minimum_num_monomers, maximum_num_monomers, rxn_rates, number_of_runs, filewriting, filepath)
  File "/home/gahan/may24/240524_allparametersopen/wheatstraw_terrell/family_1/Generation_43/Run_4/Code/simulation_main.py", line 22, in simulation_run_analysis
    data_dictionary = generate_analysis(result, number_of_runs, num_cores=int(sys.argv[2]), file_writing=False, savefile_path=filepath)
  File "/home/gahan/may24/240524_allparametersopen/wheatstraw_terrell/family_1/Generation_43/Run_4/Code/function_library.py", line 342, in generate_analysis
    lignin_libraries = pool.starmap(generate_analysis_parallel, [(cur_adjs[i], monolist[i], file_writing, savefile_path) for i, result in enumerate(results)])
  File "/home/gahan/anaconda3/envs/ligninsims/lib/python3.10/multiprocessing/pool.py", line 375, in starmap
    return self._map_async(func, iterable, starmapstar, chunksize).get()
  File "/home/gahan/anaconda3/envs/ligninsims/lib/python3.10/multiprocessing/pool.py", line 774, in get
    raise self._value
KeyError: 31
multiprocessing.pool.RemoteTraceback: 
"""
Traceback (most recent call last):
  File "/home/gahan/anaconda3/envs/ligninsims/lib/python3.10/multiprocessing/pool.py", line 125, in worker
    result = (True, func(*args, **kwds))
  File "/home/gahan/anaconda3/envs/ligninsims/lib/python3.10/multiprocessing/pool.py", line 51, in starmapstar
    return list(itertools.starmap(args[0], args[1]))
  File "/home/gahan/may24/240524_allparametersopen/wheatstraw_terrell/family_1/Generation_44/Run_1/Code/function_library.py", line 185, in generate_analysis_parallel
    nrings = np.sum([partial_dict_B[smiles_dictionary_id + k]["rings"] for k in range(partial_dict_A[bond_dictionary_id]['Bonds']["b1"]+1)])
  File "/home/gahan/may24/240524_allparametersopen/wheatstraw_terrell/family_1/Generation_44/Run_1/Code/function_library.py", line 185, in <listcomp>
    nrings = np.sum([partial_dict_B[smiles_dictionary_id + k]["rings"] for k in range(partial_dict_A[bond_dictionary_id]['Bonds']["b1"]+1)])
KeyError: 67
"""

The above exception was the direct cause of the following exception:

Traceback (most recent call last):
  File "/home/gahan/may24/240524_allparametersopen/wheatstraw_terrell/family_1/Generation_44/Run_1/Code/simulation_main.py", line 80, in <module>
    simulation_run_analysis(SG_ratio, simulation_time, monomer_addition_rate, minimum_num_monomers, maximum_num_monomers, rxn_rates, number_of_runs, filewriting, filepath)
  File "/home/gahan/may24/240524_allparametersopen/wheatstraw_terrell/family_1/Generation_44/Run_1/Code/simulation_main.py", line 22, in simulation_run_analysis
    data_dictionary = generate_analysis(result, number_of_runs, num_cores=int(sys.argv[2]), file_writing=False, savefile_path=filepath)
  File "/home/gahan/may24/240524_allparametersopen/wheatstraw_terrell/family_1/Generation_44/Run_1/Code/function_library.py", line 342, in generate_analysis
    lignin_libraries = pool.starmap(generate_analysis_parallel, [(cur_adjs[i], monolist[i], file_writing, savefile_path) for i, result in enumerate(results)])
  File "/home/gahan/anaconda3/envs/ligninsims/lib/python3.10/multiprocessing/pool.py", line 375, in starmap
    return self._map_async(func, iterable, starmapstar, chunksize).get()
  File "/home/gahan/anaconda3/envs/ligninsims/lib/python3.10/multiprocessing/pool.py", line 774, in get
    raise self._value
KeyError: 67
multiprocessing.pool.RemoteTraceback: 
"""
Traceback (most recent call last):
  File "/home/gahan/anaconda3/envs/ligninsims/lib/python3.10/multiprocessing/pool.py", line 125, in worker
    result = (True, func(*args, **kwds))
  File "/home/gahan/anaconda3/envs/ligninsims/lib/python3.10/multiprocessing/pool.py", line 51, in starmapstar
    return list(itertools.starmap(args[0], args[1]))
  File "/home/gahan/may24/240524_allparametersopen/wheatstraw_terrell/family_1/Generation_44/Run_2/Code/function_library.py", line 185, in generate_analysis_parallel
    nrings = np.sum([partial_dict_B[smiles_dictionary_id + k]["rings"] for k in range(partial_dict_A[bond_dictionary_id]['Bonds']["b1"]+1)])
  File "/home/gahan/may24/240524_allparametersopen/wheatstraw_terrell/family_1/Generation_44/Run_2/Code/function_library.py", line 185, in <listcomp>
    nrings = np.sum([partial_dict_B[smiles_dictionary_id + k]["rings"] for k in range(partial_dict_A[bond_dictionary_id]['Bonds']["b1"]+1)])
KeyError: 42
"""

The above exception was the direct cause of the following exception:

Traceback (most recent call last):
  File "/home/gahan/may24/240524_allparametersopen/wheatstraw_terrell/family_1/Generation_44/Run_2/Code/simulation_main.py", line 80, in <module>
    simulation_run_analysis(SG_ratio, simulation_time, monomer_addition_rate, minimum_num_monomers, maximum_num_monomers, rxn_rates, number_of_runs, filewriting, filepath)
  File "/home/gahan/may24/240524_allparametersopen/wheatstraw_terrell/family_1/Generation_44/Run_2/Code/simulation_main.py", line 22, in simulation_run_analysis
    data_dictionary = generate_analysis(result, number_of_runs, num_cores=int(sys.argv[2]), file_writing=False, savefile_path=filepath)
  File "/home/gahan/may24/240524_allparametersopen/wheatstraw_terrell/family_1/Generation_44/Run_2/Code/function_library.py", line 342, in generate_analysis
    lignin_libraries = pool.starmap(generate_analysis_parallel, [(cur_adjs[i], monolist[i], file_writing, savefile_path) for i, result in enumerate(results)])
  File "/home/gahan/anaconda3/envs/ligninsims/lib/python3.10/multiprocessing/pool.py", line 375, in starmap
    return self._map_async(func, iterable, starmapstar, chunksize).get()
  File "/home/gahan/anaconda3/envs/ligninsims/lib/python3.10/multiprocessing/pool.py", line 774, in get
    raise self._value
KeyError: 42
multiprocessing.pool.RemoteTraceback: 
"""
Traceback (most recent call last):
  File "/home/gahan/anaconda3/envs/ligninsims/lib/python3.10/multiprocessing/pool.py", line 125, in worker
    result = (True, func(*args, **kwds))
  File "/home/gahan/anaconda3/envs/ligninsims/lib/python3.10/multiprocessing/pool.py", line 51, in starmapstar
    return list(itertools.starmap(args[0], args[1]))
  File "/home/gahan/may24/240524_allparametersopen/wheatstraw_terrell/family_1/Generation_46/Run_4/Code/function_library.py", line 201, in generate_analysis_parallel
    smiles = partial_dict_B[smiles_dictionary_id]["smilestring"]
KeyError: 37
"""

The above exception was the direct cause of the following exception:

Traceback (most recent call last):
  File "/home/gahan/may24/240524_allparametersopen/wheatstraw_terrell/family_1/Generation_46/Run_4/Code/simulation_main.py", line 80, in <module>
    simulation_run_analysis(SG_ratio, simulation_time, monomer_addition_rate, minimum_num_monomers, maximum_num_monomers, rxn_rates, number_of_runs, filewriting, filepath)
  File "/home/gahan/may24/240524_allparametersopen/wheatstraw_terrell/family_1/Generation_46/Run_4/Code/simulation_main.py", line 22, in simulation_run_analysis
    data_dictionary = generate_analysis(result, number_of_runs, num_cores=int(sys.argv[2]), file_writing=False, savefile_path=filepath)
  File "/home/gahan/may24/240524_allparametersopen/wheatstraw_terrell/family_1/Generation_46/Run_4/Code/function_library.py", line 342, in generate_analysis
    lignin_libraries = pool.starmap(generate_analysis_parallel, [(cur_adjs[i], monolist[i], file_writing, savefile_path) for i, result in enumerate(results)])
  File "/home/gahan/anaconda3/envs/ligninsims/lib/python3.10/multiprocessing/pool.py", line 375, in starmap
    return self._map_async(func, iterable, starmapstar, chunksize).get()
  File "/home/gahan/anaconda3/envs/ligninsims/lib/python3.10/multiprocessing/pool.py", line 774, in get
    raise self._value
KeyError: 37
multiprocessing.pool.RemoteTraceback: 
"""
Traceback (most recent call last):
  File "/home/gahan/anaconda3/envs/ligninsims/lib/python3.10/multiprocessing/pool.py", line 125, in worker
    result = (True, func(*args, **kwds))
  File "/home/gahan/anaconda3/envs/ligninsims/lib/python3.10/multiprocessing/pool.py", line 51, in starmapstar
    return list(itertools.starmap(args[0], args[1]))
  File "/home/gahan/may24/240524_allparametersopen/wheatstraw_terrell/family_1/Generation_47/Run_3/Code/function_library.py", line 201, in generate_analysis_parallel
    smiles = partial_dict_B[smiles_dictionary_id]["smilestring"]
KeyError: 36
"""

The above exception was the direct cause of the following exception:

Traceback (most recent call last):
  File "/home/gahan/may24/240524_allparametersopen/wheatstraw_terrell/family_1/Generation_47/Run_3/Code/simulation_main.py", line 80, in <module>
    simulation_run_analysis(SG_ratio, simulation_time, monomer_addition_rate, minimum_num_monomers, maximum_num_monomers, rxn_rates, number_of_runs, filewriting, filepath)
  File "/home/gahan/may24/240524_allparametersopen/wheatstraw_terrell/family_1/Generation_47/Run_3/Code/simulation_main.py", line 22, in simulation_run_analysis
    data_dictionary = generate_analysis(result, number_of_runs, num_cores=int(sys.argv[2]), file_writing=False, savefile_path=filepath)
  File "/home/gahan/may24/240524_allparametersopen/wheatstraw_terrell/family_1/Generation_47/Run_3/Code/function_library.py", line 342, in generate_analysis
    lignin_libraries = pool.starmap(generate_analysis_parallel, [(cur_adjs[i], monolist[i], file_writing, savefile_path) for i, result in enumerate(results)])
  File "/home/gahan/anaconda3/envs/ligninsims/lib/python3.10/multiprocessing/pool.py", line 375, in starmap
    return self._map_async(func, iterable, starmapstar, chunksize).get()
  File "/home/gahan/anaconda3/envs/ligninsims/lib/python3.10/multiprocessing/pool.py", line 774, in get
    raise self._value
KeyError: 36
multiprocessing.pool.RemoteTraceback: 
"""
Traceback (most recent call last):
  File "/home/gahan/anaconda3/envs/ligninsims/lib/python3.10/multiprocessing/pool.py", line 125, in worker
    result = (True, func(*args, **kwds))
  File "/home/gahan/anaconda3/envs/ligninsims/lib/python3.10/multiprocessing/pool.py", line 51, in starmapstar
    return list(itertools.starmap(args[0], args[1]))
  File "/home/gahan/may24/240524_allparametersopen/wheatstraw_terrell/family_1/Generation_48/Run_1/Code/function_library.py", line 201, in generate_analysis_parallel
    smiles = partial_dict_B[smiles_dictionary_id]["smilestring"]
KeyError: 71
"""

The above exception was the direct cause of the following exception:

Traceback (most recent call last):
  File "/home/gahan/may24/240524_allparametersopen/wheatstraw_terrell/family_1/Generation_48/Run_1/Code/simulation_main.py", line 80, in <module>
    simulation_run_analysis(SG_ratio, simulation_time, monomer_addition_rate, minimum_num_monomers, maximum_num_monomers, rxn_rates, number_of_runs, filewriting, filepath)
  File "/home/gahan/may24/240524_allparametersopen/wheatstraw_terrell/family_1/Generation_48/Run_1/Code/simulation_main.py", line 22, in simulation_run_analysis
    data_dictionary = generate_analysis(result, number_of_runs, num_cores=int(sys.argv[2]), file_writing=False, savefile_path=filepath)
  File "/home/gahan/may24/240524_allparametersopen/wheatstraw_terrell/family_1/Generation_48/Run_1/Code/function_library.py", line 342, in generate_analysis
    lignin_libraries = pool.starmap(generate_analysis_parallel, [(cur_adjs[i], monolist[i], file_writing, savefile_path) for i, result in enumerate(results)])
  File "/home/gahan/anaconda3/envs/ligninsims/lib/python3.10/multiprocessing/pool.py", line 375, in starmap
    return self._map_async(func, iterable, starmapstar, chunksize).get()
  File "/home/gahan/anaconda3/envs/ligninsims/lib/python3.10/multiprocessing/pool.py", line 774, in get
    raise self._value
KeyError: 71
multiprocessing.pool.RemoteTraceback: 
"""
Traceback (most recent call last):
  File "/home/gahan/anaconda3/envs/ligninsims/lib/python3.10/multiprocessing/pool.py", line 125, in worker
    result = (True, func(*args, **kwds))
  File "/home/gahan/anaconda3/envs/ligninsims/lib/python3.10/multiprocessing/pool.py", line 51, in starmapstar
    return list(itertools.starmap(args[0], args[1]))
  File "/home/gahan/may24/240524_allparametersopen/wheatstraw_terrell/family_1/Generation_48/Run_4/Code/function_library.py", line 201, in generate_analysis_parallel
    smiles = partial_dict_B[smiles_dictionary_id]["smilestring"]
KeyError: 20
"""

The above exception was the direct cause of the following exception:

Traceback (most recent call last):
  File "/home/gahan/may24/240524_allparametersopen/wheatstraw_terrell/family_1/Generation_48/Run_4/Code/simulation_main.py", line 80, in <module>
    simulation_run_analysis(SG_ratio, simulation_time, monomer_addition_rate, minimum_num_monomers, maximum_num_monomers, rxn_rates, number_of_runs, filewriting, filepath)
  File "/home/gahan/may24/240524_allparametersopen/wheatstraw_terrell/family_1/Generation_48/Run_4/Code/simulation_main.py", line 22, in simulation_run_analysis
    data_dictionary = generate_analysis(result, number_of_runs, num_cores=int(sys.argv[2]), file_writing=False, savefile_path=filepath)
  File "/home/gahan/may24/240524_allparametersopen/wheatstraw_terrell/family_1/Generation_48/Run_4/Code/function_library.py", line 342, in generate_analysis
    lignin_libraries = pool.starmap(generate_analysis_parallel, [(cur_adjs[i], monolist[i], file_writing, savefile_path) for i, result in enumerate(results)])
  File "/home/gahan/anaconda3/envs/ligninsims/lib/python3.10/multiprocessing/pool.py", line 375, in starmap
    return self._map_async(func, iterable, starmapstar, chunksize).get()
  File "/home/gahan/anaconda3/envs/ligninsims/lib/python3.10/multiprocessing/pool.py", line 774, in get
    raise self._value
KeyError: 20
multiprocessing.pool.RemoteTraceback: 
"""
Traceback (most recent call last):
  File "/home/gahan/anaconda3/envs/ligninsims/lib/python3.10/multiprocessing/pool.py", line 125, in worker
    result = (True, func(*args, **kwds))
  File "/home/gahan/anaconda3/envs/ligninsims/lib/python3.10/multiprocessing/pool.py", line 51, in starmapstar
    return list(itertools.starmap(args[0], args[1]))
  File "/home/gahan/may24/240524_allparametersopen/wheatstraw_terrell/family_1/Generation_50/Run_2/Code/function_library.py", line 201, in generate_analysis_parallel
    smiles = partial_dict_B[smiles_dictionary_id]["smilestring"]
KeyError: 46
"""

The above exception was the direct cause of the following exception:

Traceback (most recent call last):
  File "/home/gahan/may24/240524_allparametersopen/wheatstraw_terrell/family_1/Generation_50/Run_2/Code/simulation_main.py", line 80, in <module>
    simulation_run_analysis(SG_ratio, simulation_time, monomer_addition_rate, minimum_num_monomers, maximum_num_monomers, rxn_rates, number_of_runs, filewriting, filepath)
  File "/home/gahan/may24/240524_allparametersopen/wheatstraw_terrell/family_1/Generation_50/Run_2/Code/simulation_main.py", line 22, in simulation_run_analysis
    data_dictionary = generate_analysis(result, number_of_runs, num_cores=int(sys.argv[2]), file_writing=False, savefile_path=filepath)
  File "/home/gahan/may24/240524_allparametersopen/wheatstraw_terrell/family_1/Generation_50/Run_2/Code/function_library.py", line 342, in generate_analysis
    lignin_libraries = pool.starmap(generate_analysis_parallel, [(cur_adjs[i], monolist[i], file_writing, savefile_path) for i, result in enumerate(results)])
  File "/home/gahan/anaconda3/envs/ligninsims/lib/python3.10/multiprocessing/pool.py", line 375, in starmap
    return self._map_async(func, iterable, starmapstar, chunksize).get()
  File "/home/gahan/anaconda3/envs/ligninsims/lib/python3.10/multiprocessing/pool.py", line 774, in get
    raise self._value
KeyError: 46
multiprocessing.pool.RemoteTraceback: 
"""
Traceback (most recent call last):
  File "/home/gahan/anaconda3/envs/ligninsims/lib/python3.10/multiprocessing/pool.py", line 125, in worker
    result = (True, func(*args, **kwds))
  File "/home/gahan/anaconda3/envs/ligninsims/lib/python3.10/multiprocessing/pool.py", line 51, in starmapstar
    return list(itertools.starmap(args[0], args[1]))
  File "/home/gahan/may24/240524_allparametersopen/wheatstraw_terrell/family_1/Generation_50/Run_3/Code/function_library.py", line 201, in generate_analysis_parallel
    smiles = partial_dict_B[smiles_dictionary_id]["smilestring"]
KeyError: 105
"""

The above exception was the direct cause of the following exception:

Traceback (most recent call last):
  File "/home/gahan/may24/240524_allparametersopen/wheatstraw_terrell/family_1/Generation_50/Run_3/Code/simulation_main.py", line 80, in <module>
    simulation_run_analysis(SG_ratio, simulation_time, monomer_addition_rate, minimum_num_monomers, maximum_num_monomers, rxn_rates, number_of_runs, filewriting, filepath)
  File "/home/gahan/may24/240524_allparametersopen/wheatstraw_terrell/family_1/Generation_50/Run_3/Code/simulation_main.py", line 22, in simulation_run_analysis
    data_dictionary = generate_analysis(result, number_of_runs, num_cores=int(sys.argv[2]), file_writing=False, savefile_path=filepath)
  File "/home/gahan/may24/240524_allparametersopen/wheatstraw_terrell/family_1/Generation_50/Run_3/Code/function_library.py", line 342, in generate_analysis
    lignin_libraries = pool.starmap(generate_analysis_parallel, [(cur_adjs[i], monolist[i], file_writing, savefile_path) for i, result in enumerate(results)])
  File "/home/gahan/anaconda3/envs/ligninsims/lib/python3.10/multiprocessing/pool.py", line 375, in starmap
    return self._map_async(func, iterable, starmapstar, chunksize).get()
  File "/home/gahan/anaconda3/envs/ligninsims/lib/python3.10/multiprocessing/pool.py", line 774, in get
    raise self._value
KeyError: 105
rm: das Entfernen von 'Gridsearch/Run*' ist nicht möglich: Datei oder Verzeichnis nicht gefunden
